Internal Server Error: /api/news/fetch-news/
Traceback (most recent call last):
  File "C:\Users\subhi\AppData\Roaming\Python\Python312\site-packages\django\core\handlers\exception.py", line 56, in inner
    response = get_response(request)
               ^^^^^^^^^^^^^^^^^^^^^
  File "C:\Users\subhi\AppData\Roaming\Python\Python312\site-packages\django\core\handlers\base.py", line 197, in _get_response
    response = wrapped_callback(request, *callback_args, **callback_kwargs)
               ^^^^^^^^^^^^^^^^^^^^^^^^^^^^^^^^^^^^^^^^^^^^^^^^^^^^^^^^^^^^
  File "C:\Users\subhi\AppData\Roaming\Python\Python312\site-packages\django\views\decorators\csrf.py", line 55, in wrapped_view
    return view_func(*args, **kwargs)
           ^^^^^^^^^^^^^^^^^^^^^^^^^^
  File "C:\Users\subhi\AppData\Roaming\Python\Python312\site-packages\django\views\generic\base.py", line 103, in view
    return self.dispatch(request, *args, **kwargs)
           ^^^^^^^^^^^^^^^^^^^^^^^^^^^^^^^^^^^^^^^
  File "C:\Users\subhi\AppData\Roaming\Python\Python312\site-packages\rest_framework\views.py", line 509, in dispatch
    response = self.handle_exception(exc)
               ^^^^^^^^^^^^^^^^^^^^^^^^^^
  File "C:\Users\subhi\AppData\Roaming\Python\Python312\site-packages\rest_framework\views.py", line 469, in handle_exception
    self.raise_uncaught_exception(exc)
  File "C:\Users\subhi\AppData\Roaming\Python\Python312\site-packages\rest_framework\views.py", line 480, in raise_uncaught_exception
    raise exc
  File "C:\Users\subhi\AppData\Roaming\Python\Python312\site-packages\rest_framework\views.py", line 506, in dispatch
    response = handler(request, *args, **kwargs)
               ^^^^^^^^^^^^^^^^^^^^^^^^^^^^^^^^^
  File "C:\Users\subhi\AppData\Roaming\Python\Python312\site-packages\rest_framework\decorators.py", line 50, in handler
    return func(*args, **kwargs)
           ^^^^^^^^^^^^^^^^^^^^^
  File "C:\cit\6th sem\cloudcat\news_backend\newsapp\views.py", line 55, in fetch_news
    return JsonResponse({"news": NewsArticleSerializer.data})
           ^^^^^^^^^^^^^^^^^^^^^^^^^^^^^^^^^^^^^^^^^^^^^^^^^^
  File "C:\Users\subhi\AppData\Roaming\Python\Python312\site-packages\django\http\response.py", line 691, in __init__
    data = json.dumps(data, cls=encoder, **json_dumps_params)
           ^^^^^^^^^^^^^^^^^^^^^^^^^^^^^^^^^^^^^^^^^^^^^^^^^^
  File "C:\Program Files\Python312\Lib\json\__init__.py", line 238, in dumps
    **kw).encode(obj)
          ^^^^^^^^^^^
  File "C:\Program Files\Python312\Lib\json\encoder.py", line 200, in encode
    chunks = self.iterencode(o, _one_shot=True)
             ^^^^^^^^^^^^^^^^^^^^^^^^^^^^^^^^^^
  File "C:\Program Files\Python312\Lib\json\encoder.py", line 258, in iterencode
    return _iterencode(o, 0)
           ^^^^^^^^^^^^^^^^^
  File "C:\Users\subhi\AppData\Roaming\Python\Python312\site-packages\django\core\serializers\json.py", line 106, in default
    return super().default(o)
           ^^^^^^^^^^^^^^^^^^
  File "C:\Program Files\Python312\Lib\json\encoder.py", line 180, in default
    raise TypeError(f'Object of type {o.__class__.__name__} '
TypeError: Object of type property is not JSON serializable
"GET /api/news/fetch-news/ HTTP/1.1" 500 139546
Internal Server Error: /api/news/fetch-news/
Traceback (most recent call last):
  File "C:\Users\subhi\AppData\Roaming\Python\Python312\site-packages\django\core\handlers\exception.py", line 56, in inner
    response = get_response(request)
               ^^^^^^^^^^^^^^^^^^^^^
  File "C:\Users\subhi\AppData\Roaming\Python\Python312\site-packages\django\core\handlers\base.py", line 197, in _get_response
    response = wrapped_callback(request, *callback_args, **callback_kwargs)
               ^^^^^^^^^^^^^^^^^^^^^^^^^^^^^^^^^^^^^^^^^^^^^^^^^^^^^^^^^^^^
  File "C:\Users\subhi\AppData\Roaming\Python\Python312\site-packages\django\views\decorators\csrf.py", line 55, in wrapped_view
    return view_func(*args, **kwargs)
           ^^^^^^^^^^^^^^^^^^^^^^^^^^
  File "C:\Users\subhi\AppData\Roaming\Python\Python312\site-packages\django\views\generic\base.py", line 103, in view
    return self.dispatch(request, *args, **kwargs)
           ^^^^^^^^^^^^^^^^^^^^^^^^^^^^^^^^^^^^^^^
  File "C:\Users\subhi\AppData\Roaming\Python\Python312\site-packages\rest_framework\views.py", line 509, in dispatch
    response = self.handle_exception(exc)
               ^^^^^^^^^^^^^^^^^^^^^^^^^^
  File "C:\Users\subhi\AppData\Roaming\Python\Python312\site-packages\rest_framework\views.py", line 469, in handle_exception
    self.raise_uncaught_exception(exc)
  File "C:\Users\subhi\AppData\Roaming\Python\Python312\site-packages\rest_framework\views.py", line 480, in raise_uncaught_exception
    raise exc
  File "C:\Users\subhi\AppData\Roaming\Python\Python312\site-packages\rest_framework\views.py", line 506, in dispatch
    response = handler(request, *args, **kwargs)
               ^^^^^^^^^^^^^^^^^^^^^^^^^^^^^^^^^
  File "C:\Users\subhi\AppData\Roaming\Python\Python312\site-packages\rest_framework\decorators.py", line 50, in handler
    return func(*args, **kwargs)
           ^^^^^^^^^^^^^^^^^^^^^
  File "C:\cit\6th sem\cloudcat\news_backend\newsapp\views.py", line 55, in fetch_news
    return JsonResponse({"news": serializer.data})
                                 ^^^^^^^^^^
NameError: name 'serializer' is not defined
"GET /api/news/fetch-news/ HTTP/1.1" 500 114155
Internal Server Error: /api/news/fetch-news/
Traceback (most recent call last):
  File "C:\Users\subhi\AppData\Roaming\Python\Python312\site-packages\django\core\handlers\exception.py", line 56, in inner
    response = get_response(request)
               ^^^^^^^^^^^^^^^^^^^^^
  File "C:\Users\subhi\AppData\Roaming\Python\Python312\site-packages\django\core\handlers\base.py", line 197, in _get_response
    response = wrapped_callback(request, *callback_args, **callback_kwargs)
               ^^^^^^^^^^^^^^^^^^^^^^^^^^^^^^^^^^^^^^^^^^^^^^^^^^^^^^^^^^^^
  File "C:\Users\subhi\AppData\Roaming\Python\Python312\site-packages\django\views\decorators\csrf.py", line 55, in wrapped_view
    return view_func(*args, **kwargs)
           ^^^^^^^^^^^^^^^^^^^^^^^^^^
  File "C:\Users\subhi\AppData\Roaming\Python\Python312\site-packages\django\views\generic\base.py", line 103, in view
    return self.dispatch(request, *args, **kwargs)
           ^^^^^^^^^^^^^^^^^^^^^^^^^^^^^^^^^^^^^^^
  File "C:\Users\subhi\AppData\Roaming\Python\Python312\site-packages\rest_framework\views.py", line 509, in dispatch
    response = self.handle_exception(exc)
               ^^^^^^^^^^^^^^^^^^^^^^^^^^
  File "C:\Users\subhi\AppData\Roaming\Python\Python312\site-packages\rest_framework\views.py", line 469, in handle_exception
    self.raise_uncaught_exception(exc)
  File "C:\Users\subhi\AppData\Roaming\Python\Python312\site-packages\rest_framework\views.py", line 480, in raise_uncaught_exception
    raise exc
  File "C:\Users\subhi\AppData\Roaming\Python\Python312\site-packages\rest_framework\views.py", line 506, in dispatch
    response = handler(request, *args, **kwargs)
               ^^^^^^^^^^^^^^^^^^^^^^^^^^^^^^^^^
  File "C:\Users\subhi\AppData\Roaming\Python\Python312\site-packages\rest_framework\decorators.py", line 50, in handler
    return func(*args, **kwargs)
           ^^^^^^^^^^^^^^^^^^^^^
  File "C:\cit\6th sem\cloudcat\news_backend\newsapp\views.py", line 55, in fetch_news
    return JsonResponse({"message": "News articles updated successfully!", "news": NewsArticleSerializer.data})
           ^^^^^^^^^^^^^^^^^^^^^^^^^^^^^^^^^^^^^^^^^^^^^^^^^^^^^^^^^^^^^^^^^^^^^^^^^^^^^^^^^^^^^^^^^^^^^^^^^^^^
  File "C:\Users\subhi\AppData\Roaming\Python\Python312\site-packages\django\http\response.py", line 691, in __init__
    data = json.dumps(data, cls=encoder, **json_dumps_params)
           ^^^^^^^^^^^^^^^^^^^^^^^^^^^^^^^^^^^^^^^^^^^^^^^^^^
  File "C:\Program Files\Python312\Lib\json\__init__.py", line 238, in dumps
    **kw).encode(obj)
          ^^^^^^^^^^^
  File "C:\Program Files\Python312\Lib\json\encoder.py", line 200, in encode
    chunks = self.iterencode(o, _one_shot=True)
             ^^^^^^^^^^^^^^^^^^^^^^^^^^^^^^^^^^
  File "C:\Program Files\Python312\Lib\json\encoder.py", line 258, in iterencode
    return _iterencode(o, 0)
           ^^^^^^^^^^^^^^^^^
  File "C:\Users\subhi\AppData\Roaming\Python\Python312\site-packages\django\core\serializers\json.py", line 106, in default
    return super().default(o)
           ^^^^^^^^^^^^^^^^^^
  File "C:\Program Files\Python312\Lib\json\encoder.py", line 180, in default
    raise TypeError(f'Object of type {o.__class__.__name__} '
TypeError: Object of type property is not JSON serializable
"GET /api/news/fetch-news/ HTTP/1.1" 500 139893
Internal Server Error: /api/news/get-news/
Traceback (most recent call last):
  File "C:\Users\subhi\AppData\Roaming\Python\Python312\site-packages\django\core\handlers\exception.py", line 56, in inner
    response = get_response(request)
               ^^^^^^^^^^^^^^^^^^^^^
  File "C:\Users\subhi\AppData\Roaming\Python\Python312\site-packages\django\core\handlers\base.py", line 197, in _get_response
    response = wrapped_callback(request, *callback_args, **callback_kwargs)
               ^^^^^^^^^^^^^^^^^^^^^^^^^^^^^^^^^^^^^^^^^^^^^^^^^^^^^^^^^^^^
  File "C:\Users\subhi\AppData\Roaming\Python\Python312\site-packages\django\views\decorators\csrf.py", line 55, in wrapped_view
    return view_func(*args, **kwargs)
           ^^^^^^^^^^^^^^^^^^^^^^^^^^
  File "C:\Users\subhi\AppData\Roaming\Python\Python312\site-packages\django\views\generic\base.py", line 103, in view
    return self.dispatch(request, *args, **kwargs)
           ^^^^^^^^^^^^^^^^^^^^^^^^^^^^^^^^^^^^^^^
  File "C:\Users\subhi\AppData\Roaming\Python\Python312\site-packages\rest_framework\views.py", line 509, in dispatch
    response = self.handle_exception(exc)
               ^^^^^^^^^^^^^^^^^^^^^^^^^^
  File "C:\Users\subhi\AppData\Roaming\Python\Python312\site-packages\rest_framework\views.py", line 469, in handle_exception
    self.raise_uncaught_exception(exc)
  File "C:\Users\subhi\AppData\Roaming\Python\Python312\site-packages\rest_framework\views.py", line 480, in raise_uncaught_exception
    raise exc
  File "C:\Users\subhi\AppData\Roaming\Python\Python312\site-packages\rest_framework\views.py", line 506, in dispatch
    response = handler(request, *args, **kwargs)
               ^^^^^^^^^^^^^^^^^^^^^^^^^^^^^^^^^
  File "C:\Users\subhi\AppData\Roaming\Python\Python312\site-packages\rest_framework\decorators.py", line 50, in handler
    return func(*args, **kwargs)
           ^^^^^^^^^^^^^^^^^^^^^
  File "C:\cit\6th sem\cloudcat\news_backend\newsapp\views.py", line 75, in get_news
    "pubDate": article.pubDate.strftime("%Y-%m-%d %H:%M:%S") if article.pubDate else None,
               ^^^^^^^^^^^^^^^^^^^^^^^^
AttributeError: 'str' object has no attribute 'strftime'
"GET /api/news/get-news/ HTTP/1.1" 500 102253
Internal Server Error: /api/news/login/
Traceback (most recent call last):
  File "C:\Users\subhi\AppData\Roaming\Python\Python312\site-packages\django\core\handlers\exception.py", line 56, in inner
    response = get_response(request)
               ^^^^^^^^^^^^^^^^^^^^^
  File "C:\Users\subhi\AppData\Roaming\Python\Python312\site-packages\django\core\handlers\base.py", line 197, in _get_response
    response = wrapped_callback(request, *callback_args, **callback_kwargs)
               ^^^^^^^^^^^^^^^^^^^^^^^^^^^^^^^^^^^^^^^^^^^^^^^^^^^^^^^^^^^^
  File "C:\Users\subhi\AppData\Roaming\Python\Python312\site-packages\django\views\decorators\csrf.py", line 55, in wrapped_view
    return view_func(*args, **kwargs)
           ^^^^^^^^^^^^^^^^^^^^^^^^^^
  File "C:\Users\subhi\AppData\Roaming\Python\Python312\site-packages\django\views\generic\base.py", line 103, in view
    return self.dispatch(request, *args, **kwargs)
           ^^^^^^^^^^^^^^^^^^^^^^^^^^^^^^^^^^^^^^^
  File "C:\Users\subhi\AppData\Roaming\Python\Python312\site-packages\rest_framework\views.py", line 509, in dispatch
    response = self.handle_exception(exc)
               ^^^^^^^^^^^^^^^^^^^^^^^^^^
  File "C:\Users\subhi\AppData\Roaming\Python\Python312\site-packages\rest_framework\views.py", line 469, in handle_exception
    self.raise_uncaught_exception(exc)
  File "C:\Users\subhi\AppData\Roaming\Python\Python312\site-packages\rest_framework\views.py", line 480, in raise_uncaught_exception
    raise exc
  File "C:\Users\subhi\AppData\Roaming\Python\Python312\site-packages\rest_framework\views.py", line 506, in dispatch
    response = handler(request, *args, **kwargs)
               ^^^^^^^^^^^^^^^^^^^^^^^^^^^^^^^^^
  File "C:\Users\subhi\AppData\Roaming\Python\Python312\site-packages\rest_framework\decorators.py", line 50, in handler
    return func(*args, **kwargs)
           ^^^^^^^^^^^^^^^^^^^^^
  File "C:\cit\6th sem\cloudcat\news_backend\newsapp\views.py", line 102, in login_user
    user = User.objects.filter(email=data['email']).first()
                                     ~~~~^^^^^^^^^
KeyError: 'email'
"GET /api/news/login/ HTTP/1.1" 500 99076
Internal Server Error: /api/news/login/
Traceback (most recent call last):
  File "C:\Users\subhi\AppData\Roaming\Python\Python312\site-packages\django\core\handlers\exception.py", line 56, in inner
    response = get_response(request)
               ^^^^^^^^^^^^^^^^^^^^^
  File "C:\Users\subhi\AppData\Roaming\Python\Python312\site-packages\django\core\handlers\base.py", line 197, in _get_response
    response = wrapped_callback(request, *callback_args, **callback_kwargs)
               ^^^^^^^^^^^^^^^^^^^^^^^^^^^^^^^^^^^^^^^^^^^^^^^^^^^^^^^^^^^^
  File "C:\Users\subhi\AppData\Roaming\Python\Python312\site-packages\django\views\decorators\csrf.py", line 55, in wrapped_view
    return view_func(*args, **kwargs)
           ^^^^^^^^^^^^^^^^^^^^^^^^^^
  File "C:\Users\subhi\AppData\Roaming\Python\Python312\site-packages\django\views\generic\base.py", line 103, in view
    return self.dispatch(request, *args, **kwargs)
           ^^^^^^^^^^^^^^^^^^^^^^^^^^^^^^^^^^^^^^^
  File "C:\Users\subhi\AppData\Roaming\Python\Python312\site-packages\rest_framework\views.py", line 509, in dispatch
    response = self.handle_exception(exc)
               ^^^^^^^^^^^^^^^^^^^^^^^^^^
  File "C:\Users\subhi\AppData\Roaming\Python\Python312\site-packages\rest_framework\views.py", line 469, in handle_exception
    self.raise_uncaught_exception(exc)
  File "C:\Users\subhi\AppData\Roaming\Python\Python312\site-packages\rest_framework\views.py", line 480, in raise_uncaught_exception
    raise exc
  File "C:\Users\subhi\AppData\Roaming\Python\Python312\site-packages\rest_framework\views.py", line 506, in dispatch
    response = handler(request, *args, **kwargs)
               ^^^^^^^^^^^^^^^^^^^^^^^^^^^^^^^^^
  File "C:\Users\subhi\AppData\Roaming\Python\Python312\site-packages\rest_framework\decorators.py", line 50, in handler
    return func(*args, **kwargs)
           ^^^^^^^^^^^^^^^^^^^^^
  File "C:\cit\6th sem\cloudcat\news_backend\newsapp\views.py", line 102, in login_user
    user = User.objects.filter(email=data['email']).first()
                                     ~~~~^^^^^^^^^
KeyError: 'email'
"GET /api/news/login/ HTTP/1.1" 500 99213
Internal Server Error: /api/news/signup/
Traceback (most recent call last):
  File "C:\Users\subhi\AppData\Roaming\Python\Python312\site-packages\django\core\handlers\exception.py", line 56, in inner
    response = get_response(request)
               ^^^^^^^^^^^^^^^^^^^^^
  File "C:\Users\subhi\AppData\Roaming\Python\Python312\site-packages\django\core\handlers\base.py", line 197, in _get_response
    response = wrapped_callback(request, *callback_args, **callback_kwargs)
               ^^^^^^^^^^^^^^^^^^^^^^^^^^^^^^^^^^^^^^^^^^^^^^^^^^^^^^^^^^^^
  File "C:\Users\subhi\AppData\Roaming\Python\Python312\site-packages\django\views\decorators\csrf.py", line 55, in wrapped_view
    return view_func(*args, **kwargs)
           ^^^^^^^^^^^^^^^^^^^^^^^^^^
  File "C:\Users\subhi\AppData\Roaming\Python\Python312\site-packages\django\views\generic\base.py", line 103, in view
    return self.dispatch(request, *args, **kwargs)
           ^^^^^^^^^^^^^^^^^^^^^^^^^^^^^^^^^^^^^^^
  File "C:\Users\subhi\AppData\Roaming\Python\Python312\site-packages\rest_framework\views.py", line 509, in dispatch
    response = self.handle_exception(exc)
               ^^^^^^^^^^^^^^^^^^^^^^^^^^
  File "C:\Users\subhi\AppData\Roaming\Python\Python312\site-packages\rest_framework\views.py", line 469, in handle_exception
    self.raise_uncaught_exception(exc)
  File "C:\Users\subhi\AppData\Roaming\Python\Python312\site-packages\rest_framework\views.py", line 480, in raise_uncaught_exception
    raise exc
  File "C:\Users\subhi\AppData\Roaming\Python\Python312\site-packages\rest_framework\views.py", line 506, in dispatch
    response = handler(request, *args, **kwargs)
               ^^^^^^^^^^^^^^^^^^^^^^^^^^^^^^^^^
  File "C:\Users\subhi\AppData\Roaming\Python\Python312\site-packages\rest_framework\decorators.py", line 50, in handler
    return func(*args, **kwargs)
           ^^^^^^^^^^^^^^^^^^^^^
  File "C:\cit\6th sem\cloudcat\news_backend\newsapp\views.py", line 87, in register_user
    if User.objects.filter(email=data['email']).exists():
                                 ~~~~^^^^^^^^^
KeyError: 'email'
"GET /api/news/signup/ HTTP/1.1" 500 99280
Internal Server Error: /api/news/signup/
Traceback (most recent call last):
  File "C:\Users\subhi\AppData\Roaming\Python\Python312\site-packages\django\core\handlers\exception.py", line 56, in inner
    response = get_response(request)
               ^^^^^^^^^^^^^^^^^^^^^
  File "C:\Users\subhi\AppData\Roaming\Python\Python312\site-packages\django\core\handlers\base.py", line 197, in _get_response
    response = wrapped_callback(request, *callback_args, **callback_kwargs)
               ^^^^^^^^^^^^^^^^^^^^^^^^^^^^^^^^^^^^^^^^^^^^^^^^^^^^^^^^^^^^
  File "C:\Users\subhi\AppData\Roaming\Python\Python312\site-packages\django\views\decorators\csrf.py", line 55, in wrapped_view
    return view_func(*args, **kwargs)
           ^^^^^^^^^^^^^^^^^^^^^^^^^^
  File "C:\Users\subhi\AppData\Roaming\Python\Python312\site-packages\django\views\generic\base.py", line 103, in view
    return self.dispatch(request, *args, **kwargs)
           ^^^^^^^^^^^^^^^^^^^^^^^^^^^^^^^^^^^^^^^
  File "C:\Users\subhi\AppData\Roaming\Python\Python312\site-packages\rest_framework\views.py", line 509, in dispatch
    response = self.handle_exception(exc)
               ^^^^^^^^^^^^^^^^^^^^^^^^^^
  File "C:\Users\subhi\AppData\Roaming\Python\Python312\site-packages\rest_framework\views.py", line 469, in handle_exception
    self.raise_uncaught_exception(exc)
  File "C:\Users\subhi\AppData\Roaming\Python\Python312\site-packages\rest_framework\views.py", line 480, in raise_uncaught_exception
    raise exc
  File "C:\Users\subhi\AppData\Roaming\Python\Python312\site-packages\rest_framework\views.py", line 506, in dispatch
    response = handler(request, *args, **kwargs)
               ^^^^^^^^^^^^^^^^^^^^^^^^^^^^^^^^^
  File "C:\Users\subhi\AppData\Roaming\Python\Python312\site-packages\rest_framework\decorators.py", line 50, in handler
    return func(*args, **kwargs)
           ^^^^^^^^^^^^^^^^^^^^^
  File "C:\cit\6th sem\cloudcat\news_backend\newsapp\views.py", line 87, in register_user
    if User.objects.filter(email=data['email']).exists():
                                 ~~~~^^^^^^^^^
KeyError: 'email'
"GET /api/news/signup/ HTTP/1.1" 500 99006
Internal Server Error: /api/news/signup/
Traceback (most recent call last):
  File "C:\Users\subhi\AppData\Roaming\Python\Python312\site-packages\djongo\sql2mongo\query.py", line 808, in __iter__
    yield from iter(self._query)
  File "C:\Users\subhi\AppData\Roaming\Python\Python312\site-packages\djongo\sql2mongo\query.py", line 167, in __iter__
    yield self._align_results(doc)
          ^^^^^^^^^^^^^^^^^^^^^^^^
  File "C:\Users\subhi\AppData\Roaming\Python\Python312\site-packages\djongo\sql2mongo\query.py", line 269, in _align_results
    if selected.table == self.left_table:
       ^^^^^^^^^^^^^^
  File "C:\Users\subhi\AppData\Roaming\Python\Python312\site-packages\djongo\sql2mongo\sql_tokens.py", line 133, in table
    return alias2token[name].table
           ^^^^^^^^^^^^^^^^^^^^^^^
  File "C:\Users\subhi\AppData\Roaming\Python\Python312\site-packages\djongo\sql2mongo\sql_tokens.py", line 133, in table
    return alias2token[name].table
           ^^^^^^^^^^^^^^^^^^^^^^^
  File "C:\Users\subhi\AppData\Roaming\Python\Python312\site-packages\djongo\sql2mongo\sql_tokens.py", line 133, in table
    return alias2token[name].table
           ^^^^^^^^^^^^^^^^^^^^^^^
  [Previous line repeated 941 more times]
  File "C:\Users\subhi\AppData\Roaming\Python\Python312\site-packages\djongo\sql2mongo\sql_tokens.py", line 130, in table
    name = self.given_table
           ^^^^^^^^^^^^^^^^
  File "C:\Users\subhi\AppData\Roaming\Python\Python312\site-packages\djongo\sql2mongo\sql_tokens.py", line 141, in given_table
    name = self._token.get_real_name()
           ^^^^^^^^^^^^^^^^^^^^^^^^^^^
  File "C:\Users\subhi\AppData\Roaming\Python\Python312\site-packages\sqlparse\sql.py", line 361, in get_real_name
    return self._get_first_name(dot_idx)
           ^^^^^^^^^^^^^^^^^^^^^^^^^^^^^
  File "C:\Users\subhi\AppData\Roaming\Python\Python312\site-packages\sqlparse\sql.py", line 386, in _get_first_name
    return token.get_name()
           ^^^^^^^^^^^^^^^^
  File "C:\Users\subhi\AppData\Roaming\Python\Python312\site-packages\sqlparse\sql.py", line 355, in get_name
    return self.get_alias() or self.get_real_name()
           ^^^^^^^^^^^^^^^^
  File "C:\Users\subhi\AppData\Roaming\Python\Python312\site-packages\sqlparse\sql.py", line 339, in get_alias
    kw_idx, kw = self.token_next_by(m=(T.Keyword, 'AS'))
                 ^^^^^^^^^^^^^^^^^^^^^^^^^^^^^^^^^^^^^^^
  File "C:\Users\subhi\AppData\Roaming\Python\Python312\site-packages\sqlparse\sql.py", line 244, in token_next_by
    return self._token_matching(funcs, idx, end)
           ^^^^^^^^^^^^^^^^^^^^^^^^^^^^^^^^^^^^^
  File "C:\Users\subhi\AppData\Roaming\Python\Python312\site-packages\sqlparse\sql.py", line 223, in _token_matching
    if func(token):
       ^^^^^^^^^^^
  File "C:\Users\subhi\AppData\Roaming\Python\Python312\site-packages\sqlparse\sql.py", line 242, in <lambda>
    funcs = lambda tk: imt(tk, i, m, t)
                       ^^^^^^^^^^^^^^^^
  File "C:\Users\subhi\AppData\Roaming\Python\Python312\site-packages\sqlparse\utils.py", line 98, in imt
    elif mpatterns and any(token.match(*pattern) for pattern in mpatterns):
                       ^^^^^^^^^^^^^^^^^^^^^^^^^^^^^^^^^^^^^^^^^^^^^^^^^^^
  File "C:\Users\subhi\AppData\Roaming\Python\Python312\site-packages\sqlparse\utils.py", line 98, in <genexpr>
    elif mpatterns and any(token.match(*pattern) for pattern in mpatterns):
                           ^^^^^^^^^^^^^^^^^^^^^
RecursionError: maximum recursion depth exceeded

The above exception was the direct cause of the following exception:

Traceback (most recent call last):
  File "C:\Users\subhi\AppData\Roaming\Python\Python312\site-packages\djongo\cursor.py", line 76, in fetchone
    return self.result.next()
           ^^^^^^^^^^^^^^^^^^
  File "C:\Users\subhi\AppData\Roaming\Python\Python312\site-packages\djongo\sql2mongo\query.py", line 797, in __next__
    result = next(self._result_generator)
             ^^^^^^^^^^^^^^^^^^^^^^^^^^^^
  File "C:\Users\subhi\AppData\Roaming\Python\Python312\site-packages\djongo\sql2mongo\query.py", line 830, in __iter__
    raise exe from e
djongo.exceptions.SQLDecodeError: 

	Keyword: FAILED SQL: SELECT %(0)s AS "a" FROM "newsapp_user" WHERE "newsapp_user"."email" = %(1)s LIMIT 1
Params: (1, 'subhitcha.s@gmail.com')
Version: 1.3.6
	Sub SQL: None
	FAILED SQL: None
	Params: None
	Version: None

The above exception was the direct cause of the following exception:

Traceback (most recent call last):
  File "C:\Users\subhi\AppData\Roaming\Python\Python312\site-packages\django\db\utils.py", line 98, in inner
    return func(*args, **kwargs)
           ^^^^^^^^^^^^^^^^^^^^^
  File "C:\Users\subhi\AppData\Roaming\Python\Python312\site-packages\djongo\cursor.py", line 81, in fetchone
    raise db_exe from e
djongo.database.DatabaseError

The above exception was the direct cause of the following exception:

Traceback (most recent call last):
  File "C:\Users\subhi\AppData\Roaming\Python\Python312\site-packages\django\core\handlers\exception.py", line 56, in inner
    response = get_response(request)
               ^^^^^^^^^^^^^^^^^^^^^
  File "C:\Users\subhi\AppData\Roaming\Python\Python312\site-packages\django\core\handlers\base.py", line 197, in _get_response
    response = wrapped_callback(request, *callback_args, **callback_kwargs)
               ^^^^^^^^^^^^^^^^^^^^^^^^^^^^^^^^^^^^^^^^^^^^^^^^^^^^^^^^^^^^
  File "C:\Users\subhi\AppData\Roaming\Python\Python312\site-packages\django\views\decorators\csrf.py", line 55, in wrapped_view
    return view_func(*args, **kwargs)
           ^^^^^^^^^^^^^^^^^^^^^^^^^^
  File "C:\Users\subhi\AppData\Roaming\Python\Python312\site-packages\django\views\generic\base.py", line 103, in view
    return self.dispatch(request, *args, **kwargs)
           ^^^^^^^^^^^^^^^^^^^^^^^^^^^^^^^^^^^^^^^
  File "C:\Users\subhi\AppData\Roaming\Python\Python312\site-packages\rest_framework\views.py", line 509, in dispatch
    response = self.handle_exception(exc)
               ^^^^^^^^^^^^^^^^^^^^^^^^^^
  File "C:\Users\subhi\AppData\Roaming\Python\Python312\site-packages\rest_framework\views.py", line 469, in handle_exception
    self.raise_uncaught_exception(exc)
  File "C:\Users\subhi\AppData\Roaming\Python\Python312\site-packages\rest_framework\views.py", line 480, in raise_uncaught_exception
    raise exc
  File "C:\Users\subhi\AppData\Roaming\Python\Python312\site-packages\rest_framework\views.py", line 506, in dispatch
    response = handler(request, *args, **kwargs)
               ^^^^^^^^^^^^^^^^^^^^^^^^^^^^^^^^^
  File "C:\Users\subhi\AppData\Roaming\Python\Python312\site-packages\rest_framework\decorators.py", line 50, in handler
    return func(*args, **kwargs)
           ^^^^^^^^^^^^^^^^^^^^^
  File "C:\cit\6th sem\cloudcat\news_backend\newsapp\views.py", line 91, in register_user
    if User.objects.filter(email=data.get('email')).exists():
       ^^^^^^^^^^^^^^^^^^^^^^^^^^^^^^^^^^^^^^^^^^^^^^^^^^^^^
  File "C:\Users\subhi\AppData\Roaming\Python\Python312\site-packages\django\db\models\query.py", line 1226, in exists
    return self.query.has_results(using=self.db)
           ^^^^^^^^^^^^^^^^^^^^^^^^^^^^^^^^^^^^^
  File "C:\Users\subhi\AppData\Roaming\Python\Python312\site-packages\django\db\models\sql\query.py", line 592, in has_results
    return compiler.has_results()
           ^^^^^^^^^^^^^^^^^^^^^^
  File "C:\Users\subhi\AppData\Roaming\Python\Python312\site-packages\django\db\models\sql\compiler.py", line 1366, in has_results
    return bool(self.execute_sql(SINGLE))
                ^^^^^^^^^^^^^^^^^^^^^^^^
  File "C:\Users\subhi\AppData\Roaming\Python\Python312\site-packages\django\db\models\sql\compiler.py", line 1409, in execute_sql
    val = cursor.fetchone()
          ^^^^^^^^^^^^^^^^^
  File "C:\Users\subhi\AppData\Roaming\Python\Python312\site-packages\django\db\utils.py", line 97, in inner
    with self:
  File "C:\Users\subhi\AppData\Roaming\Python\Python312\site-packages\django\db\utils.py", line 91, in __exit__
    raise dj_exc_value.with_traceback(traceback) from exc_value
  File "C:\Users\subhi\AppData\Roaming\Python\Python312\site-packages\django\db\utils.py", line 98, in inner
    return func(*args, **kwargs)
           ^^^^^^^^^^^^^^^^^^^^^
  File "C:\Users\subhi\AppData\Roaming\Python\Python312\site-packages\djongo\cursor.py", line 81, in fetchone
    raise db_exe from e
django.db.utils.DatabaseError
"POST /api/news/signup/ HTTP/1.1" 500 3817207
Internal Server Error: /api/news/signup/
Traceback (most recent call last):
  File "C:\Users\subhi\AppData\Roaming\Python\Python312\site-packages\djongo\sql2mongo\query.py", line 808, in __iter__
    yield from iter(self._query)
  File "C:\Users\subhi\AppData\Roaming\Python\Python312\site-packages\djongo\sql2mongo\query.py", line 167, in __iter__
    yield self._align_results(doc)
          ^^^^^^^^^^^^^^^^^^^^^^^^
  File "C:\Users\subhi\AppData\Roaming\Python\Python312\site-packages\djongo\sql2mongo\query.py", line 269, in _align_results
    if selected.table == self.left_table:
       ^^^^^^^^^^^^^^
  File "C:\Users\subhi\AppData\Roaming\Python\Python312\site-packages\djongo\sql2mongo\sql_tokens.py", line 133, in table
    return alias2token[name].table
           ^^^^^^^^^^^^^^^^^^^^^^^
  File "C:\Users\subhi\AppData\Roaming\Python\Python312\site-packages\djongo\sql2mongo\sql_tokens.py", line 133, in table
    return alias2token[name].table
           ^^^^^^^^^^^^^^^^^^^^^^^
  File "C:\Users\subhi\AppData\Roaming\Python\Python312\site-packages\djongo\sql2mongo\sql_tokens.py", line 133, in table
    return alias2token[name].table
           ^^^^^^^^^^^^^^^^^^^^^^^
  [Previous line repeated 941 more times]
  File "C:\Users\subhi\AppData\Roaming\Python\Python312\site-packages\djongo\sql2mongo\sql_tokens.py", line 130, in table
    name = self.given_table
           ^^^^^^^^^^^^^^^^
  File "C:\Users\subhi\AppData\Roaming\Python\Python312\site-packages\djongo\sql2mongo\sql_tokens.py", line 141, in given_table
    name = self._token.get_real_name()
           ^^^^^^^^^^^^^^^^^^^^^^^^^^^
  File "C:\Users\subhi\AppData\Roaming\Python\Python312\site-packages\sqlparse\sql.py", line 361, in get_real_name
    return self._get_first_name(dot_idx)
           ^^^^^^^^^^^^^^^^^^^^^^^^^^^^^
  File "C:\Users\subhi\AppData\Roaming\Python\Python312\site-packages\sqlparse\sql.py", line 386, in _get_first_name
    return token.get_name()
           ^^^^^^^^^^^^^^^^
  File "C:\Users\subhi\AppData\Roaming\Python\Python312\site-packages\sqlparse\sql.py", line 355, in get_name
    return self.get_alias() or self.get_real_name()
           ^^^^^^^^^^^^^^^^
  File "C:\Users\subhi\AppData\Roaming\Python\Python312\site-packages\sqlparse\sql.py", line 339, in get_alias
    kw_idx, kw = self.token_next_by(m=(T.Keyword, 'AS'))
                 ^^^^^^^^^^^^^^^^^^^^^^^^^^^^^^^^^^^^^^^
  File "C:\Users\subhi\AppData\Roaming\Python\Python312\site-packages\sqlparse\sql.py", line 244, in token_next_by
    return self._token_matching(funcs, idx, end)
           ^^^^^^^^^^^^^^^^^^^^^^^^^^^^^^^^^^^^^
  File "C:\Users\subhi\AppData\Roaming\Python\Python312\site-packages\sqlparse\sql.py", line 223, in _token_matching
    if func(token):
       ^^^^^^^^^^^
  File "C:\Users\subhi\AppData\Roaming\Python\Python312\site-packages\sqlparse\sql.py", line 242, in <lambda>
    funcs = lambda tk: imt(tk, i, m, t)
                       ^^^^^^^^^^^^^^^^
  File "C:\Users\subhi\AppData\Roaming\Python\Python312\site-packages\sqlparse\utils.py", line 98, in imt
    elif mpatterns and any(token.match(*pattern) for pattern in mpatterns):
                       ^^^^^^^^^^^^^^^^^^^^^^^^^^^^^^^^^^^^^^^^^^^^^^^^^^^
  File "C:\Users\subhi\AppData\Roaming\Python\Python312\site-packages\sqlparse\utils.py", line 98, in <genexpr>
    elif mpatterns and any(token.match(*pattern) for pattern in mpatterns):
                           ^^^^^^^^^^^^^^^^^^^^^
RecursionError: maximum recursion depth exceeded

The above exception was the direct cause of the following exception:

Traceback (most recent call last):
  File "C:\Users\subhi\AppData\Roaming\Python\Python312\site-packages\djongo\cursor.py", line 76, in fetchone
    return self.result.next()
           ^^^^^^^^^^^^^^^^^^
  File "C:\Users\subhi\AppData\Roaming\Python\Python312\site-packages\djongo\sql2mongo\query.py", line 797, in __next__
    result = next(self._result_generator)
             ^^^^^^^^^^^^^^^^^^^^^^^^^^^^
  File "C:\Users\subhi\AppData\Roaming\Python\Python312\site-packages\djongo\sql2mongo\query.py", line 830, in __iter__
    raise exe from e
djongo.exceptions.SQLDecodeError: 

	Keyword: FAILED SQL: SELECT %(0)s AS "a" FROM "newsapp_user" WHERE "newsapp_user"."email" = %(1)s LIMIT 1
Params: (1, 'subhitcha.s@gmail.com')
Version: 1.3.6
	Sub SQL: None
	FAILED SQL: None
	Params: None
	Version: None

The above exception was the direct cause of the following exception:

Traceback (most recent call last):
  File "C:\Users\subhi\AppData\Roaming\Python\Python312\site-packages\django\db\utils.py", line 98, in inner
    return func(*args, **kwargs)
           ^^^^^^^^^^^^^^^^^^^^^
  File "C:\Users\subhi\AppData\Roaming\Python\Python312\site-packages\djongo\cursor.py", line 81, in fetchone
    raise db_exe from e
djongo.database.DatabaseError

The above exception was the direct cause of the following exception:

Traceback (most recent call last):
  File "C:\Users\subhi\AppData\Roaming\Python\Python312\site-packages\django\core\handlers\exception.py", line 56, in inner
    response = get_response(request)
               ^^^^^^^^^^^^^^^^^^^^^
  File "C:\Users\subhi\AppData\Roaming\Python\Python312\site-packages\django\core\handlers\base.py", line 197, in _get_response
    response = wrapped_callback(request, *callback_args, **callback_kwargs)
               ^^^^^^^^^^^^^^^^^^^^^^^^^^^^^^^^^^^^^^^^^^^^^^^^^^^^^^^^^^^^
  File "C:\Users\subhi\AppData\Roaming\Python\Python312\site-packages\django\views\decorators\csrf.py", line 55, in wrapped_view
    return view_func(*args, **kwargs)
           ^^^^^^^^^^^^^^^^^^^^^^^^^^
  File "C:\Users\subhi\AppData\Roaming\Python\Python312\site-packages\django\views\generic\base.py", line 103, in view
    return self.dispatch(request, *args, **kwargs)
           ^^^^^^^^^^^^^^^^^^^^^^^^^^^^^^^^^^^^^^^
  File "C:\Users\subhi\AppData\Roaming\Python\Python312\site-packages\rest_framework\views.py", line 509, in dispatch
    response = self.handle_exception(exc)
               ^^^^^^^^^^^^^^^^^^^^^^^^^^
  File "C:\Users\subhi\AppData\Roaming\Python\Python312\site-packages\rest_framework\views.py", line 469, in handle_exception
    self.raise_uncaught_exception(exc)
  File "C:\Users\subhi\AppData\Roaming\Python\Python312\site-packages\rest_framework\views.py", line 480, in raise_uncaught_exception
    raise exc
  File "C:\Users\subhi\AppData\Roaming\Python\Python312\site-packages\rest_framework\views.py", line 506, in dispatch
    response = handler(request, *args, **kwargs)
               ^^^^^^^^^^^^^^^^^^^^^^^^^^^^^^^^^
  File "C:\Users\subhi\AppData\Roaming\Python\Python312\site-packages\rest_framework\decorators.py", line 50, in handler
    return func(*args, **kwargs)
           ^^^^^^^^^^^^^^^^^^^^^
  File "C:\cit\6th sem\cloudcat\news_backend\newsapp\views.py", line 91, in register_user
    if User.objects.filter(email=data.get('email')).exists():
       ^^^^^^^^^^^^^^^^^^^^^^^^^^^^^^^^^^^^^^^^^^^^^^^^^^^^^
  File "C:\Users\subhi\AppData\Roaming\Python\Python312\site-packages\django\db\models\query.py", line 1226, in exists
    return self.query.has_results(using=self.db)
           ^^^^^^^^^^^^^^^^^^^^^^^^^^^^^^^^^^^^^
  File "C:\Users\subhi\AppData\Roaming\Python\Python312\site-packages\django\db\models\sql\query.py", line 592, in has_results
    return compiler.has_results()
           ^^^^^^^^^^^^^^^^^^^^^^
  File "C:\Users\subhi\AppData\Roaming\Python\Python312\site-packages\django\db\models\sql\compiler.py", line 1366, in has_results
    return bool(self.execute_sql(SINGLE))
                ^^^^^^^^^^^^^^^^^^^^^^^^
  File "C:\Users\subhi\AppData\Roaming\Python\Python312\site-packages\django\db\models\sql\compiler.py", line 1409, in execute_sql
    val = cursor.fetchone()
          ^^^^^^^^^^^^^^^^^
  File "C:\Users\subhi\AppData\Roaming\Python\Python312\site-packages\django\db\utils.py", line 97, in inner
    with self:
  File "C:\Users\subhi\AppData\Roaming\Python\Python312\site-packages\django\db\utils.py", line 91, in __exit__
    raise dj_exc_value.with_traceback(traceback) from exc_value
  File "C:\Users\subhi\AppData\Roaming\Python\Python312\site-packages\django\db\utils.py", line 98, in inner
    return func(*args, **kwargs)
           ^^^^^^^^^^^^^^^^^^^^^
  File "C:\Users\subhi\AppData\Roaming\Python\Python312\site-packages\djongo\cursor.py", line 81, in fetchone
    raise db_exe from e
django.db.utils.DatabaseError
"POST /api/news/signup/ HTTP/1.1" 500 3817207
Internal Server Error: /api/news/signup/
Traceback (most recent call last):
  File "C:\Users\subhi\AppData\Roaming\Python\Python312\site-packages\djongo\sql2mongo\query.py", line 808, in __iter__
    yield from iter(self._query)
  File "C:\Users\subhi\AppData\Roaming\Python\Python312\site-packages\djongo\sql2mongo\query.py", line 167, in __iter__
    yield self._align_results(doc)
          ^^^^^^^^^^^^^^^^^^^^^^^^
  File "C:\Users\subhi\AppData\Roaming\Python\Python312\site-packages\djongo\sql2mongo\query.py", line 269, in _align_results
    if selected.table == self.left_table:
       ^^^^^^^^^^^^^^
  File "C:\Users\subhi\AppData\Roaming\Python\Python312\site-packages\djongo\sql2mongo\sql_tokens.py", line 133, in table
    return alias2token[name].table
           ^^^^^^^^^^^^^^^^^^^^^^^
  File "C:\Users\subhi\AppData\Roaming\Python\Python312\site-packages\djongo\sql2mongo\sql_tokens.py", line 133, in table
    return alias2token[name].table
           ^^^^^^^^^^^^^^^^^^^^^^^
  File "C:\Users\subhi\AppData\Roaming\Python\Python312\site-packages\djongo\sql2mongo\sql_tokens.py", line 133, in table
    return alias2token[name].table
           ^^^^^^^^^^^^^^^^^^^^^^^
  [Previous line repeated 941 more times]
  File "C:\Users\subhi\AppData\Roaming\Python\Python312\site-packages\djongo\sql2mongo\sql_tokens.py", line 130, in table
    name = self.given_table
           ^^^^^^^^^^^^^^^^
  File "C:\Users\subhi\AppData\Roaming\Python\Python312\site-packages\djongo\sql2mongo\sql_tokens.py", line 141, in given_table
    name = self._token.get_real_name()
           ^^^^^^^^^^^^^^^^^^^^^^^^^^^
  File "C:\Users\subhi\AppData\Roaming\Python\Python312\site-packages\sqlparse\sql.py", line 361, in get_real_name
    return self._get_first_name(dot_idx)
           ^^^^^^^^^^^^^^^^^^^^^^^^^^^^^
  File "C:\Users\subhi\AppData\Roaming\Python\Python312\site-packages\sqlparse\sql.py", line 386, in _get_first_name
    return token.get_name()
           ^^^^^^^^^^^^^^^^
  File "C:\Users\subhi\AppData\Roaming\Python\Python312\site-packages\sqlparse\sql.py", line 355, in get_name
    return self.get_alias() or self.get_real_name()
           ^^^^^^^^^^^^^^^^
  File "C:\Users\subhi\AppData\Roaming\Python\Python312\site-packages\sqlparse\sql.py", line 339, in get_alias
    kw_idx, kw = self.token_next_by(m=(T.Keyword, 'AS'))
                 ^^^^^^^^^^^^^^^^^^^^^^^^^^^^^^^^^^^^^^^
  File "C:\Users\subhi\AppData\Roaming\Python\Python312\site-packages\sqlparse\sql.py", line 244, in token_next_by
    return self._token_matching(funcs, idx, end)
           ^^^^^^^^^^^^^^^^^^^^^^^^^^^^^^^^^^^^^
  File "C:\Users\subhi\AppData\Roaming\Python\Python312\site-packages\sqlparse\sql.py", line 223, in _token_matching
    if func(token):
       ^^^^^^^^^^^
  File "C:\Users\subhi\AppData\Roaming\Python\Python312\site-packages\sqlparse\sql.py", line 242, in <lambda>
    funcs = lambda tk: imt(tk, i, m, t)
                       ^^^^^^^^^^^^^^^^
  File "C:\Users\subhi\AppData\Roaming\Python\Python312\site-packages\sqlparse\utils.py", line 98, in imt
    elif mpatterns and any(token.match(*pattern) for pattern in mpatterns):
                       ^^^^^^^^^^^^^^^^^^^^^^^^^^^^^^^^^^^^^^^^^^^^^^^^^^^
  File "C:\Users\subhi\AppData\Roaming\Python\Python312\site-packages\sqlparse\utils.py", line 98, in <genexpr>
    elif mpatterns and any(token.match(*pattern) for pattern in mpatterns):
                           ^^^^^^^^^^^^^^^^^^^^^
RecursionError: maximum recursion depth exceeded

The above exception was the direct cause of the following exception:

Traceback (most recent call last):
  File "C:\Users\subhi\AppData\Roaming\Python\Python312\site-packages\djongo\cursor.py", line 76, in fetchone
    return self.result.next()
           ^^^^^^^^^^^^^^^^^^
  File "C:\Users\subhi\AppData\Roaming\Python\Python312\site-packages\djongo\sql2mongo\query.py", line 797, in __next__
    result = next(self._result_generator)
             ^^^^^^^^^^^^^^^^^^^^^^^^^^^^
  File "C:\Users\subhi\AppData\Roaming\Python\Python312\site-packages\djongo\sql2mongo\query.py", line 830, in __iter__
    raise exe from e
djongo.exceptions.SQLDecodeError: 

	Keyword: FAILED SQL: SELECT %(0)s AS "a" FROM "newsapp_user" WHERE "newsapp_user"."email" = %(1)s LIMIT 1
Params: (1, 'subhitcha.s@gmail.com')
Version: 1.3.6
	Sub SQL: None
	FAILED SQL: None
	Params: None
	Version: None

The above exception was the direct cause of the following exception:

Traceback (most recent call last):
  File "C:\Users\subhi\AppData\Roaming\Python\Python312\site-packages\django\db\utils.py", line 98, in inner
    return func(*args, **kwargs)
           ^^^^^^^^^^^^^^^^^^^^^
  File "C:\Users\subhi\AppData\Roaming\Python\Python312\site-packages\djongo\cursor.py", line 81, in fetchone
    raise db_exe from e
djongo.database.DatabaseError

The above exception was the direct cause of the following exception:

Traceback (most recent call last):
  File "C:\Users\subhi\AppData\Roaming\Python\Python312\site-packages\django\core\handlers\exception.py", line 56, in inner
    response = get_response(request)
               ^^^^^^^^^^^^^^^^^^^^^
  File "C:\Users\subhi\AppData\Roaming\Python\Python312\site-packages\django\core\handlers\base.py", line 197, in _get_response
    response = wrapped_callback(request, *callback_args, **callback_kwargs)
               ^^^^^^^^^^^^^^^^^^^^^^^^^^^^^^^^^^^^^^^^^^^^^^^^^^^^^^^^^^^^
  File "C:\Users\subhi\AppData\Roaming\Python\Python312\site-packages\django\views\decorators\csrf.py", line 55, in wrapped_view
    return view_func(*args, **kwargs)
           ^^^^^^^^^^^^^^^^^^^^^^^^^^
  File "C:\Users\subhi\AppData\Roaming\Python\Python312\site-packages\django\views\generic\base.py", line 103, in view
    return self.dispatch(request, *args, **kwargs)
           ^^^^^^^^^^^^^^^^^^^^^^^^^^^^^^^^^^^^^^^
  File "C:\Users\subhi\AppData\Roaming\Python\Python312\site-packages\rest_framework\views.py", line 509, in dispatch
    response = self.handle_exception(exc)
               ^^^^^^^^^^^^^^^^^^^^^^^^^^
  File "C:\Users\subhi\AppData\Roaming\Python\Python312\site-packages\rest_framework\views.py", line 469, in handle_exception
    self.raise_uncaught_exception(exc)
  File "C:\Users\subhi\AppData\Roaming\Python\Python312\site-packages\rest_framework\views.py", line 480, in raise_uncaught_exception
    raise exc
  File "C:\Users\subhi\AppData\Roaming\Python\Python312\site-packages\rest_framework\views.py", line 506, in dispatch
    response = handler(request, *args, **kwargs)
               ^^^^^^^^^^^^^^^^^^^^^^^^^^^^^^^^^
  File "C:\Users\subhi\AppData\Roaming\Python\Python312\site-packages\rest_framework\decorators.py", line 50, in handler
    return func(*args, **kwargs)
           ^^^^^^^^^^^^^^^^^^^^^
  File "C:\cit\6th sem\cloudcat\news_backend\newsapp\views.py", line 91, in register_user
    if User.objects.filter(email=data.get('email')).exists():
       ^^^^^^^^^^^^^^^^^^^^^^^^^^^^^^^^^^^^^^^^^^^^^^^^^^^^^
  File "C:\Users\subhi\AppData\Roaming\Python\Python312\site-packages\django\db\models\query.py", line 1226, in exists
    return self.query.has_results(using=self.db)
           ^^^^^^^^^^^^^^^^^^^^^^^^^^^^^^^^^^^^^
  File "C:\Users\subhi\AppData\Roaming\Python\Python312\site-packages\django\db\models\sql\query.py", line 592, in has_results
    return compiler.has_results()
           ^^^^^^^^^^^^^^^^^^^^^^
  File "C:\Users\subhi\AppData\Roaming\Python\Python312\site-packages\django\db\models\sql\compiler.py", line 1366, in has_results
    return bool(self.execute_sql(SINGLE))
                ^^^^^^^^^^^^^^^^^^^^^^^^
  File "C:\Users\subhi\AppData\Roaming\Python\Python312\site-packages\django\db\models\sql\compiler.py", line 1409, in execute_sql
    val = cursor.fetchone()
          ^^^^^^^^^^^^^^^^^
  File "C:\Users\subhi\AppData\Roaming\Python\Python312\site-packages\django\db\utils.py", line 97, in inner
    with self:
  File "C:\Users\subhi\AppData\Roaming\Python\Python312\site-packages\django\db\utils.py", line 91, in __exit__
    raise dj_exc_value.with_traceback(traceback) from exc_value
  File "C:\Users\subhi\AppData\Roaming\Python\Python312\site-packages\django\db\utils.py", line 98, in inner
    return func(*args, **kwargs)
           ^^^^^^^^^^^^^^^^^^^^^
  File "C:\Users\subhi\AppData\Roaming\Python\Python312\site-packages\djongo\cursor.py", line 81, in fetchone
    raise db_exe from e
django.db.utils.DatabaseError
"POST /api/news/signup/ HTTP/1.1" 500 3817207
Internal Server Error: /api/news/signup/
Traceback (most recent call last):
  File "C:\Users\subhi\AppData\Roaming\Python\Python312\site-packages\djongo\sql2mongo\query.py", line 808, in __iter__
    yield from iter(self._query)
  File "C:\Users\subhi\AppData\Roaming\Python\Python312\site-packages\djongo\sql2mongo\query.py", line 167, in __iter__
    yield self._align_results(doc)
          ^^^^^^^^^^^^^^^^^^^^^^^^
  File "C:\Users\subhi\AppData\Roaming\Python\Python312\site-packages\djongo\sql2mongo\query.py", line 269, in _align_results
    if selected.table == self.left_table:
       ^^^^^^^^^^^^^^
  File "C:\Users\subhi\AppData\Roaming\Python\Python312\site-packages\djongo\sql2mongo\sql_tokens.py", line 133, in table
    return alias2token[name].table
           ^^^^^^^^^^^^^^^^^^^^^^^
  File "C:\Users\subhi\AppData\Roaming\Python\Python312\site-packages\djongo\sql2mongo\sql_tokens.py", line 133, in table
    return alias2token[name].table
           ^^^^^^^^^^^^^^^^^^^^^^^
  File "C:\Users\subhi\AppData\Roaming\Python\Python312\site-packages\djongo\sql2mongo\sql_tokens.py", line 133, in table
    return alias2token[name].table
           ^^^^^^^^^^^^^^^^^^^^^^^
  [Previous line repeated 941 more times]
  File "C:\Users\subhi\AppData\Roaming\Python\Python312\site-packages\djongo\sql2mongo\sql_tokens.py", line 130, in table
    name = self.given_table
           ^^^^^^^^^^^^^^^^
  File "C:\Users\subhi\AppData\Roaming\Python\Python312\site-packages\djongo\sql2mongo\sql_tokens.py", line 141, in given_table
    name = self._token.get_real_name()
           ^^^^^^^^^^^^^^^^^^^^^^^^^^^
  File "C:\Users\subhi\AppData\Roaming\Python\Python312\site-packages\sqlparse\sql.py", line 361, in get_real_name
    return self._get_first_name(dot_idx)
           ^^^^^^^^^^^^^^^^^^^^^^^^^^^^^
  File "C:\Users\subhi\AppData\Roaming\Python\Python312\site-packages\sqlparse\sql.py", line 386, in _get_first_name
    return token.get_name()
           ^^^^^^^^^^^^^^^^
  File "C:\Users\subhi\AppData\Roaming\Python\Python312\site-packages\sqlparse\sql.py", line 355, in get_name
    return self.get_alias() or self.get_real_name()
           ^^^^^^^^^^^^^^^^
  File "C:\Users\subhi\AppData\Roaming\Python\Python312\site-packages\sqlparse\sql.py", line 339, in get_alias
    kw_idx, kw = self.token_next_by(m=(T.Keyword, 'AS'))
                 ^^^^^^^^^^^^^^^^^^^^^^^^^^^^^^^^^^^^^^^
  File "C:\Users\subhi\AppData\Roaming\Python\Python312\site-packages\sqlparse\sql.py", line 244, in token_next_by
    return self._token_matching(funcs, idx, end)
           ^^^^^^^^^^^^^^^^^^^^^^^^^^^^^^^^^^^^^
  File "C:\Users\subhi\AppData\Roaming\Python\Python312\site-packages\sqlparse\sql.py", line 223, in _token_matching
    if func(token):
       ^^^^^^^^^^^
  File "C:\Users\subhi\AppData\Roaming\Python\Python312\site-packages\sqlparse\sql.py", line 242, in <lambda>
    funcs = lambda tk: imt(tk, i, m, t)
                       ^^^^^^^^^^^^^^^^
  File "C:\Users\subhi\AppData\Roaming\Python\Python312\site-packages\sqlparse\utils.py", line 98, in imt
    elif mpatterns and any(token.match(*pattern) for pattern in mpatterns):
                       ^^^^^^^^^^^^^^^^^^^^^^^^^^^^^^^^^^^^^^^^^^^^^^^^^^^
  File "C:\Users\subhi\AppData\Roaming\Python\Python312\site-packages\sqlparse\utils.py", line 98, in <genexpr>
    elif mpatterns and any(token.match(*pattern) for pattern in mpatterns):
                           ^^^^^^^^^^^^^^^^^^^^^
RecursionError: maximum recursion depth exceeded

The above exception was the direct cause of the following exception:

Traceback (most recent call last):
  File "C:\Users\subhi\AppData\Roaming\Python\Python312\site-packages\djongo\cursor.py", line 76, in fetchone
    return self.result.next()
           ^^^^^^^^^^^^^^^^^^
  File "C:\Users\subhi\AppData\Roaming\Python\Python312\site-packages\djongo\sql2mongo\query.py", line 797, in __next__
    result = next(self._result_generator)
             ^^^^^^^^^^^^^^^^^^^^^^^^^^^^
  File "C:\Users\subhi\AppData\Roaming\Python\Python312\site-packages\djongo\sql2mongo\query.py", line 830, in __iter__
    raise exe from e
djongo.exceptions.SQLDecodeError: 

	Keyword: FAILED SQL: SELECT %(0)s AS "a" FROM "newsapp_user" WHERE "newsapp_user"."email" = %(1)s LIMIT 1
Params: (1, 'subhitcha.s@gmail.com')
Version: 1.3.6
	Sub SQL: None
	FAILED SQL: None
	Params: None
	Version: None

The above exception was the direct cause of the following exception:

Traceback (most recent call last):
  File "C:\Users\subhi\AppData\Roaming\Python\Python312\site-packages\django\db\utils.py", line 98, in inner
    return func(*args, **kwargs)
           ^^^^^^^^^^^^^^^^^^^^^
  File "C:\Users\subhi\AppData\Roaming\Python\Python312\site-packages\djongo\cursor.py", line 81, in fetchone
    raise db_exe from e
djongo.database.DatabaseError

The above exception was the direct cause of the following exception:

Traceback (most recent call last):
  File "C:\Users\subhi\AppData\Roaming\Python\Python312\site-packages\django\core\handlers\exception.py", line 56, in inner
    response = get_response(request)
               ^^^^^^^^^^^^^^^^^^^^^
  File "C:\Users\subhi\AppData\Roaming\Python\Python312\site-packages\django\core\handlers\base.py", line 197, in _get_response
    response = wrapped_callback(request, *callback_args, **callback_kwargs)
               ^^^^^^^^^^^^^^^^^^^^^^^^^^^^^^^^^^^^^^^^^^^^^^^^^^^^^^^^^^^^
  File "C:\Users\subhi\AppData\Roaming\Python\Python312\site-packages\django\views\decorators\csrf.py", line 55, in wrapped_view
    return view_func(*args, **kwargs)
           ^^^^^^^^^^^^^^^^^^^^^^^^^^
  File "C:\Users\subhi\AppData\Roaming\Python\Python312\site-packages\django\views\generic\base.py", line 103, in view
    return self.dispatch(request, *args, **kwargs)
           ^^^^^^^^^^^^^^^^^^^^^^^^^^^^^^^^^^^^^^^
  File "C:\Users\subhi\AppData\Roaming\Python\Python312\site-packages\rest_framework\views.py", line 509, in dispatch
    response = self.handle_exception(exc)
               ^^^^^^^^^^^^^^^^^^^^^^^^^^
  File "C:\Users\subhi\AppData\Roaming\Python\Python312\site-packages\rest_framework\views.py", line 469, in handle_exception
    self.raise_uncaught_exception(exc)
  File "C:\Users\subhi\AppData\Roaming\Python\Python312\site-packages\rest_framework\views.py", line 480, in raise_uncaught_exception
    raise exc
  File "C:\Users\subhi\AppData\Roaming\Python\Python312\site-packages\rest_framework\views.py", line 506, in dispatch
    response = handler(request, *args, **kwargs)
               ^^^^^^^^^^^^^^^^^^^^^^^^^^^^^^^^^
  File "C:\Users\subhi\AppData\Roaming\Python\Python312\site-packages\rest_framework\decorators.py", line 50, in handler
    return func(*args, **kwargs)
           ^^^^^^^^^^^^^^^^^^^^^
  File "C:\cit\6th sem\cloudcat\news_backend\newsapp\views.py", line 91, in register_user
    if User.objects.filter(email=data.get('email')).exists():
       ^^^^^^^^^^^^^^^^^^^^^^^^^^^^^^^^^^^^^^^^^^^^^^^^^^^^^
  File "C:\Users\subhi\AppData\Roaming\Python\Python312\site-packages\django\db\models\query.py", line 1226, in exists
    return self.query.has_results(using=self.db)
           ^^^^^^^^^^^^^^^^^^^^^^^^^^^^^^^^^^^^^
  File "C:\Users\subhi\AppData\Roaming\Python\Python312\site-packages\django\db\models\sql\query.py", line 592, in has_results
    return compiler.has_results()
           ^^^^^^^^^^^^^^^^^^^^^^
  File "C:\Users\subhi\AppData\Roaming\Python\Python312\site-packages\django\db\models\sql\compiler.py", line 1366, in has_results
    return bool(self.execute_sql(SINGLE))
                ^^^^^^^^^^^^^^^^^^^^^^^^
  File "C:\Users\subhi\AppData\Roaming\Python\Python312\site-packages\django\db\models\sql\compiler.py", line 1409, in execute_sql
    val = cursor.fetchone()
          ^^^^^^^^^^^^^^^^^
  File "C:\Users\subhi\AppData\Roaming\Python\Python312\site-packages\django\db\utils.py", line 97, in inner
    with self:
  File "C:\Users\subhi\AppData\Roaming\Python\Python312\site-packages\django\db\utils.py", line 91, in __exit__
    raise dj_exc_value.with_traceback(traceback) from exc_value
  File "C:\Users\subhi\AppData\Roaming\Python\Python312\site-packages\django\db\utils.py", line 98, in inner
    return func(*args, **kwargs)
           ^^^^^^^^^^^^^^^^^^^^^
  File "C:\Users\subhi\AppData\Roaming\Python\Python312\site-packages\djongo\cursor.py", line 81, in fetchone
    raise db_exe from e
django.db.utils.DatabaseError
"POST /api/news/signup/ HTTP/1.1" 500 3816902
Internal Server Error: /api/news/signup/
Traceback (most recent call last):
  File "C:\Users\subhi\AppData\Roaming\Python\Python312\site-packages\djongo\sql2mongo\query.py", line 808, in __iter__
    yield from iter(self._query)
  File "C:\Users\subhi\AppData\Roaming\Python\Python312\site-packages\djongo\sql2mongo\query.py", line 167, in __iter__
    yield self._align_results(doc)
          ^^^^^^^^^^^^^^^^^^^^^^^^
  File "C:\Users\subhi\AppData\Roaming\Python\Python312\site-packages\djongo\sql2mongo\query.py", line 269, in _align_results
    if selected.table == self.left_table:
       ^^^^^^^^^^^^^^
  File "C:\Users\subhi\AppData\Roaming\Python\Python312\site-packages\djongo\sql2mongo\sql_tokens.py", line 133, in table
    return alias2token[name].table
           ^^^^^^^^^^^^^^^^^^^^^^^
  File "C:\Users\subhi\AppData\Roaming\Python\Python312\site-packages\djongo\sql2mongo\sql_tokens.py", line 133, in table
    return alias2token[name].table
           ^^^^^^^^^^^^^^^^^^^^^^^
  File "C:\Users\subhi\AppData\Roaming\Python\Python312\site-packages\djongo\sql2mongo\sql_tokens.py", line 133, in table
    return alias2token[name].table
           ^^^^^^^^^^^^^^^^^^^^^^^
  [Previous line repeated 941 more times]
  File "C:\Users\subhi\AppData\Roaming\Python\Python312\site-packages\djongo\sql2mongo\sql_tokens.py", line 130, in table
    name = self.given_table
           ^^^^^^^^^^^^^^^^
  File "C:\Users\subhi\AppData\Roaming\Python\Python312\site-packages\djongo\sql2mongo\sql_tokens.py", line 141, in given_table
    name = self._token.get_real_name()
           ^^^^^^^^^^^^^^^^^^^^^^^^^^^
  File "C:\Users\subhi\AppData\Roaming\Python\Python312\site-packages\sqlparse\sql.py", line 361, in get_real_name
    return self._get_first_name(dot_idx)
           ^^^^^^^^^^^^^^^^^^^^^^^^^^^^^
  File "C:\Users\subhi\AppData\Roaming\Python\Python312\site-packages\sqlparse\sql.py", line 386, in _get_first_name
    return token.get_name()
           ^^^^^^^^^^^^^^^^
  File "C:\Users\subhi\AppData\Roaming\Python\Python312\site-packages\sqlparse\sql.py", line 355, in get_name
    return self.get_alias() or self.get_real_name()
           ^^^^^^^^^^^^^^^^
  File "C:\Users\subhi\AppData\Roaming\Python\Python312\site-packages\sqlparse\sql.py", line 339, in get_alias
    kw_idx, kw = self.token_next_by(m=(T.Keyword, 'AS'))
                 ^^^^^^^^^^^^^^^^^^^^^^^^^^^^^^^^^^^^^^^
  File "C:\Users\subhi\AppData\Roaming\Python\Python312\site-packages\sqlparse\sql.py", line 244, in token_next_by
    return self._token_matching(funcs, idx, end)
           ^^^^^^^^^^^^^^^^^^^^^^^^^^^^^^^^^^^^^
  File "C:\Users\subhi\AppData\Roaming\Python\Python312\site-packages\sqlparse\sql.py", line 223, in _token_matching
    if func(token):
       ^^^^^^^^^^^
  File "C:\Users\subhi\AppData\Roaming\Python\Python312\site-packages\sqlparse\sql.py", line 242, in <lambda>
    funcs = lambda tk: imt(tk, i, m, t)
                       ^^^^^^^^^^^^^^^^
  File "C:\Users\subhi\AppData\Roaming\Python\Python312\site-packages\sqlparse\utils.py", line 98, in imt
    elif mpatterns and any(token.match(*pattern) for pattern in mpatterns):
                       ^^^^^^^^^^^^^^^^^^^^^^^^^^^^^^^^^^^^^^^^^^^^^^^^^^^
  File "C:\Users\subhi\AppData\Roaming\Python\Python312\site-packages\sqlparse\utils.py", line 98, in <genexpr>
    elif mpatterns and any(token.match(*pattern) for pattern in mpatterns):
                           ^^^^^^^^^^^^^^^^^^^^^
RecursionError: maximum recursion depth exceeded

The above exception was the direct cause of the following exception:

Traceback (most recent call last):
  File "C:\Users\subhi\AppData\Roaming\Python\Python312\site-packages\djongo\cursor.py", line 76, in fetchone
    return self.result.next()
           ^^^^^^^^^^^^^^^^^^
  File "C:\Users\subhi\AppData\Roaming\Python\Python312\site-packages\djongo\sql2mongo\query.py", line 797, in __next__
    result = next(self._result_generator)
             ^^^^^^^^^^^^^^^^^^^^^^^^^^^^
  File "C:\Users\subhi\AppData\Roaming\Python\Python312\site-packages\djongo\sql2mongo\query.py", line 830, in __iter__
    raise exe from e
djongo.exceptions.SQLDecodeError: 

	Keyword: FAILED SQL: SELECT %(0)s AS "a" FROM "newsapp_user" WHERE "newsapp_user"."email" = %(1)s LIMIT 1
Params: (1, 'subhitcha.s@gmail.com')
Version: 1.3.6
	Sub SQL: None
	FAILED SQL: None
	Params: None
	Version: None

The above exception was the direct cause of the following exception:

Traceback (most recent call last):
  File "C:\Users\subhi\AppData\Roaming\Python\Python312\site-packages\django\db\utils.py", line 98, in inner
    return func(*args, **kwargs)
           ^^^^^^^^^^^^^^^^^^^^^
  File "C:\Users\subhi\AppData\Roaming\Python\Python312\site-packages\djongo\cursor.py", line 81, in fetchone
    raise db_exe from e
djongo.database.DatabaseError

The above exception was the direct cause of the following exception:

Traceback (most recent call last):
  File "C:\Users\subhi\AppData\Roaming\Python\Python312\site-packages\django\core\handlers\exception.py", line 56, in inner
    response = get_response(request)
               ^^^^^^^^^^^^^^^^^^^^^
  File "C:\Users\subhi\AppData\Roaming\Python\Python312\site-packages\django\core\handlers\base.py", line 197, in _get_response
    response = wrapped_callback(request, *callback_args, **callback_kwargs)
               ^^^^^^^^^^^^^^^^^^^^^^^^^^^^^^^^^^^^^^^^^^^^^^^^^^^^^^^^^^^^
  File "C:\Users\subhi\AppData\Roaming\Python\Python312\site-packages\django\views\decorators\csrf.py", line 55, in wrapped_view
    return view_func(*args, **kwargs)
           ^^^^^^^^^^^^^^^^^^^^^^^^^^
  File "C:\Users\subhi\AppData\Roaming\Python\Python312\site-packages\django\views\generic\base.py", line 103, in view
    return self.dispatch(request, *args, **kwargs)
           ^^^^^^^^^^^^^^^^^^^^^^^^^^^^^^^^^^^^^^^
  File "C:\Users\subhi\AppData\Roaming\Python\Python312\site-packages\rest_framework\views.py", line 509, in dispatch
    response = self.handle_exception(exc)
               ^^^^^^^^^^^^^^^^^^^^^^^^^^
  File "C:\Users\subhi\AppData\Roaming\Python\Python312\site-packages\rest_framework\views.py", line 469, in handle_exception
    self.raise_uncaught_exception(exc)
  File "C:\Users\subhi\AppData\Roaming\Python\Python312\site-packages\rest_framework\views.py", line 480, in raise_uncaught_exception
    raise exc
  File "C:\Users\subhi\AppData\Roaming\Python\Python312\site-packages\rest_framework\views.py", line 506, in dispatch
    response = handler(request, *args, **kwargs)
               ^^^^^^^^^^^^^^^^^^^^^^^^^^^^^^^^^
  File "C:\Users\subhi\AppData\Roaming\Python\Python312\site-packages\rest_framework\decorators.py", line 50, in handler
    return func(*args, **kwargs)
           ^^^^^^^^^^^^^^^^^^^^^
  File "C:\cit\6th sem\cloudcat\news_backend\newsapp\views.py", line 91, in register_user
    if User.objects.filter(email=data.get('email')).exists():
       ^^^^^^^^^^^^^^^^^^^^^^^^^^^^^^^^^^^^^^^^^^^^^^^^^^^^^
  File "C:\Users\subhi\AppData\Roaming\Python\Python312\site-packages\django\db\models\query.py", line 1226, in exists
    return self.query.has_results(using=self.db)
           ^^^^^^^^^^^^^^^^^^^^^^^^^^^^^^^^^^^^^
  File "C:\Users\subhi\AppData\Roaming\Python\Python312\site-packages\django\db\models\sql\query.py", line 592, in has_results
    return compiler.has_results()
           ^^^^^^^^^^^^^^^^^^^^^^
  File "C:\Users\subhi\AppData\Roaming\Python\Python312\site-packages\django\db\models\sql\compiler.py", line 1366, in has_results
    return bool(self.execute_sql(SINGLE))
                ^^^^^^^^^^^^^^^^^^^^^^^^
  File "C:\Users\subhi\AppData\Roaming\Python\Python312\site-packages\django\db\models\sql\compiler.py", line 1409, in execute_sql
    val = cursor.fetchone()
          ^^^^^^^^^^^^^^^^^
  File "C:\Users\subhi\AppData\Roaming\Python\Python312\site-packages\django\db\utils.py", line 97, in inner
    with self:
  File "C:\Users\subhi\AppData\Roaming\Python\Python312\site-packages\django\db\utils.py", line 91, in __exit__
    raise dj_exc_value.with_traceback(traceback) from exc_value
  File "C:\Users\subhi\AppData\Roaming\Python\Python312\site-packages\django\db\utils.py", line 98, in inner
    return func(*args, **kwargs)
           ^^^^^^^^^^^^^^^^^^^^^
  File "C:\Users\subhi\AppData\Roaming\Python\Python312\site-packages\djongo\cursor.py", line 81, in fetchone
    raise db_exe from e
django.db.utils.DatabaseError
"POST /api/news/signup/ HTTP/1.1" 500 3816902
Internal Server Error: /api/news/signup/
Traceback (most recent call last):
  File "C:\Users\subhi\AppData\Roaming\Python\Python312\site-packages\djongo\sql2mongo\query.py", line 808, in __iter__
    yield from iter(self._query)
  File "C:\Users\subhi\AppData\Roaming\Python\Python312\site-packages\djongo\sql2mongo\query.py", line 167, in __iter__
    yield self._align_results(doc)
          ^^^^^^^^^^^^^^^^^^^^^^^^
  File "C:\Users\subhi\AppData\Roaming\Python\Python312\site-packages\djongo\sql2mongo\query.py", line 269, in _align_results
    if selected.table == self.left_table:
       ^^^^^^^^^^^^^^
  File "C:\Users\subhi\AppData\Roaming\Python\Python312\site-packages\djongo\sql2mongo\sql_tokens.py", line 133, in table
    return alias2token[name].table
           ^^^^^^^^^^^^^^^^^^^^^^^
  File "C:\Users\subhi\AppData\Roaming\Python\Python312\site-packages\djongo\sql2mongo\sql_tokens.py", line 133, in table
    return alias2token[name].table
           ^^^^^^^^^^^^^^^^^^^^^^^
  File "C:\Users\subhi\AppData\Roaming\Python\Python312\site-packages\djongo\sql2mongo\sql_tokens.py", line 133, in table
    return alias2token[name].table
           ^^^^^^^^^^^^^^^^^^^^^^^
  [Previous line repeated 941 more times]
  File "C:\Users\subhi\AppData\Roaming\Python\Python312\site-packages\djongo\sql2mongo\sql_tokens.py", line 130, in table
    name = self.given_table
           ^^^^^^^^^^^^^^^^
  File "C:\Users\subhi\AppData\Roaming\Python\Python312\site-packages\djongo\sql2mongo\sql_tokens.py", line 141, in given_table
    name = self._token.get_real_name()
           ^^^^^^^^^^^^^^^^^^^^^^^^^^^
  File "C:\Users\subhi\AppData\Roaming\Python\Python312\site-packages\sqlparse\sql.py", line 361, in get_real_name
    return self._get_first_name(dot_idx)
           ^^^^^^^^^^^^^^^^^^^^^^^^^^^^^
  File "C:\Users\subhi\AppData\Roaming\Python\Python312\site-packages\sqlparse\sql.py", line 386, in _get_first_name
    return token.get_name()
           ^^^^^^^^^^^^^^^^
  File "C:\Users\subhi\AppData\Roaming\Python\Python312\site-packages\sqlparse\sql.py", line 355, in get_name
    return self.get_alias() or self.get_real_name()
           ^^^^^^^^^^^^^^^^
  File "C:\Users\subhi\AppData\Roaming\Python\Python312\site-packages\sqlparse\sql.py", line 339, in get_alias
    kw_idx, kw = self.token_next_by(m=(T.Keyword, 'AS'))
                 ^^^^^^^^^^^^^^^^^^^^^^^^^^^^^^^^^^^^^^^
  File "C:\Users\subhi\AppData\Roaming\Python\Python312\site-packages\sqlparse\sql.py", line 244, in token_next_by
    return self._token_matching(funcs, idx, end)
           ^^^^^^^^^^^^^^^^^^^^^^^^^^^^^^^^^^^^^
  File "C:\Users\subhi\AppData\Roaming\Python\Python312\site-packages\sqlparse\sql.py", line 223, in _token_matching
    if func(token):
       ^^^^^^^^^^^
  File "C:\Users\subhi\AppData\Roaming\Python\Python312\site-packages\sqlparse\sql.py", line 242, in <lambda>
    funcs = lambda tk: imt(tk, i, m, t)
                       ^^^^^^^^^^^^^^^^
  File "C:\Users\subhi\AppData\Roaming\Python\Python312\site-packages\sqlparse\utils.py", line 98, in imt
    elif mpatterns and any(token.match(*pattern) for pattern in mpatterns):
                       ^^^^^^^^^^^^^^^^^^^^^^^^^^^^^^^^^^^^^^^^^^^^^^^^^^^
  File "C:\Users\subhi\AppData\Roaming\Python\Python312\site-packages\sqlparse\utils.py", line 98, in <genexpr>
    elif mpatterns and any(token.match(*pattern) for pattern in mpatterns):
                           ^^^^^^^^^^^^^^^^^^^^^
RecursionError: maximum recursion depth exceeded

The above exception was the direct cause of the following exception:

Traceback (most recent call last):
  File "C:\Users\subhi\AppData\Roaming\Python\Python312\site-packages\djongo\cursor.py", line 76, in fetchone
    return self.result.next()
           ^^^^^^^^^^^^^^^^^^
  File "C:\Users\subhi\AppData\Roaming\Python\Python312\site-packages\djongo\sql2mongo\query.py", line 797, in __next__
    result = next(self._result_generator)
             ^^^^^^^^^^^^^^^^^^^^^^^^^^^^
  File "C:\Users\subhi\AppData\Roaming\Python\Python312\site-packages\djongo\sql2mongo\query.py", line 830, in __iter__
    raise exe from e
djongo.exceptions.SQLDecodeError: 

	Keyword: FAILED SQL: SELECT %(0)s AS "a" FROM "newsapp_user" WHERE "newsapp_user"."email" = %(1)s LIMIT 1
Params: (1, 'subhitcha.s@gmail.com')
Version: 1.3.6
	Sub SQL: None
	FAILED SQL: None
	Params: None
	Version: None

The above exception was the direct cause of the following exception:

Traceback (most recent call last):
  File "C:\Users\subhi\AppData\Roaming\Python\Python312\site-packages\django\db\utils.py", line 98, in inner
    return func(*args, **kwargs)
           ^^^^^^^^^^^^^^^^^^^^^
  File "C:\Users\subhi\AppData\Roaming\Python\Python312\site-packages\djongo\cursor.py", line 81, in fetchone
    raise db_exe from e
djongo.database.DatabaseError

The above exception was the direct cause of the following exception:

Traceback (most recent call last):
  File "C:\Users\subhi\AppData\Roaming\Python\Python312\site-packages\django\core\handlers\exception.py", line 56, in inner
    response = get_response(request)
               ^^^^^^^^^^^^^^^^^^^^^
  File "C:\Users\subhi\AppData\Roaming\Python\Python312\site-packages\django\core\handlers\base.py", line 197, in _get_response
    response = wrapped_callback(request, *callback_args, **callback_kwargs)
               ^^^^^^^^^^^^^^^^^^^^^^^^^^^^^^^^^^^^^^^^^^^^^^^^^^^^^^^^^^^^
  File "C:\Users\subhi\AppData\Roaming\Python\Python312\site-packages\django\views\decorators\csrf.py", line 55, in wrapped_view
    return view_func(*args, **kwargs)
           ^^^^^^^^^^^^^^^^^^^^^^^^^^
  File "C:\Users\subhi\AppData\Roaming\Python\Python312\site-packages\django\views\generic\base.py", line 103, in view
    return self.dispatch(request, *args, **kwargs)
           ^^^^^^^^^^^^^^^^^^^^^^^^^^^^^^^^^^^^^^^
  File "C:\Users\subhi\AppData\Roaming\Python\Python312\site-packages\rest_framework\views.py", line 509, in dispatch
    response = self.handle_exception(exc)
               ^^^^^^^^^^^^^^^^^^^^^^^^^^
  File "C:\Users\subhi\AppData\Roaming\Python\Python312\site-packages\rest_framework\views.py", line 469, in handle_exception
    self.raise_uncaught_exception(exc)
  File "C:\Users\subhi\AppData\Roaming\Python\Python312\site-packages\rest_framework\views.py", line 480, in raise_uncaught_exception
    raise exc
  File "C:\Users\subhi\AppData\Roaming\Python\Python312\site-packages\rest_framework\views.py", line 506, in dispatch
    response = handler(request, *args, **kwargs)
               ^^^^^^^^^^^^^^^^^^^^^^^^^^^^^^^^^
  File "C:\Users\subhi\AppData\Roaming\Python\Python312\site-packages\rest_framework\decorators.py", line 50, in handler
    return func(*args, **kwargs)
           ^^^^^^^^^^^^^^^^^^^^^
  File "C:\cit\6th sem\cloudcat\news_backend\newsapp\views.py", line 91, in register_user
    if User.objects.filter(email=data.get('email')).exists():
       ^^^^^^^^^^^^^^^^^^^^^^^^^^^^^^^^^^^^^^^^^^^^^^^^^^^^^
  File "C:\Users\subhi\AppData\Roaming\Python\Python312\site-packages\django\db\models\query.py", line 1226, in exists
    return self.query.has_results(using=self.db)
           ^^^^^^^^^^^^^^^^^^^^^^^^^^^^^^^^^^^^^
  File "C:\Users\subhi\AppData\Roaming\Python\Python312\site-packages\django\db\models\sql\query.py", line 592, in has_results
    return compiler.has_results()
           ^^^^^^^^^^^^^^^^^^^^^^
  File "C:\Users\subhi\AppData\Roaming\Python\Python312\site-packages\django\db\models\sql\compiler.py", line 1366, in has_results
    return bool(self.execute_sql(SINGLE))
                ^^^^^^^^^^^^^^^^^^^^^^^^
  File "C:\Users\subhi\AppData\Roaming\Python\Python312\site-packages\django\db\models\sql\compiler.py", line 1409, in execute_sql
    val = cursor.fetchone()
          ^^^^^^^^^^^^^^^^^
  File "C:\Users\subhi\AppData\Roaming\Python\Python312\site-packages\django\db\utils.py", line 97, in inner
    with self:
  File "C:\Users\subhi\AppData\Roaming\Python\Python312\site-packages\django\db\utils.py", line 91, in __exit__
    raise dj_exc_value.with_traceback(traceback) from exc_value
  File "C:\Users\subhi\AppData\Roaming\Python\Python312\site-packages\django\db\utils.py", line 98, in inner
    return func(*args, **kwargs)
           ^^^^^^^^^^^^^^^^^^^^^
  File "C:\Users\subhi\AppData\Roaming\Python\Python312\site-packages\djongo\cursor.py", line 81, in fetchone
    raise db_exe from e
django.db.utils.DatabaseError
"POST /api/news/signup/ HTTP/1.1" 500 3816902
Internal Server Error: /api/news/signup/
Traceback (most recent call last):
  File "C:\Users\subhi\AppData\Roaming\Python\Python312\site-packages\djongo\sql2mongo\query.py", line 808, in __iter__
    yield from iter(self._query)
  File "C:\Users\subhi\AppData\Roaming\Python\Python312\site-packages\djongo\sql2mongo\query.py", line 167, in __iter__
    yield self._align_results(doc)
          ^^^^^^^^^^^^^^^^^^^^^^^^
  File "C:\Users\subhi\AppData\Roaming\Python\Python312\site-packages\djongo\sql2mongo\query.py", line 269, in _align_results
    if selected.table == self.left_table:
       ^^^^^^^^^^^^^^
  File "C:\Users\subhi\AppData\Roaming\Python\Python312\site-packages\djongo\sql2mongo\sql_tokens.py", line 133, in table
    return alias2token[name].table
           ^^^^^^^^^^^^^^^^^^^^^^^
  File "C:\Users\subhi\AppData\Roaming\Python\Python312\site-packages\djongo\sql2mongo\sql_tokens.py", line 133, in table
    return alias2token[name].table
           ^^^^^^^^^^^^^^^^^^^^^^^
  File "C:\Users\subhi\AppData\Roaming\Python\Python312\site-packages\djongo\sql2mongo\sql_tokens.py", line 133, in table
    return alias2token[name].table
           ^^^^^^^^^^^^^^^^^^^^^^^
  [Previous line repeated 941 more times]
  File "C:\Users\subhi\AppData\Roaming\Python\Python312\site-packages\djongo\sql2mongo\sql_tokens.py", line 130, in table
    name = self.given_table
           ^^^^^^^^^^^^^^^^
  File "C:\Users\subhi\AppData\Roaming\Python\Python312\site-packages\djongo\sql2mongo\sql_tokens.py", line 141, in given_table
    name = self._token.get_real_name()
           ^^^^^^^^^^^^^^^^^^^^^^^^^^^
  File "C:\Users\subhi\AppData\Roaming\Python\Python312\site-packages\sqlparse\sql.py", line 361, in get_real_name
    return self._get_first_name(dot_idx)
           ^^^^^^^^^^^^^^^^^^^^^^^^^^^^^
  File "C:\Users\subhi\AppData\Roaming\Python\Python312\site-packages\sqlparse\sql.py", line 386, in _get_first_name
    return token.get_name()
           ^^^^^^^^^^^^^^^^
  File "C:\Users\subhi\AppData\Roaming\Python\Python312\site-packages\sqlparse\sql.py", line 355, in get_name
    return self.get_alias() or self.get_real_name()
           ^^^^^^^^^^^^^^^^
  File "C:\Users\subhi\AppData\Roaming\Python\Python312\site-packages\sqlparse\sql.py", line 339, in get_alias
    kw_idx, kw = self.token_next_by(m=(T.Keyword, 'AS'))
                 ^^^^^^^^^^^^^^^^^^^^^^^^^^^^^^^^^^^^^^^
  File "C:\Users\subhi\AppData\Roaming\Python\Python312\site-packages\sqlparse\sql.py", line 244, in token_next_by
    return self._token_matching(funcs, idx, end)
           ^^^^^^^^^^^^^^^^^^^^^^^^^^^^^^^^^^^^^
  File "C:\Users\subhi\AppData\Roaming\Python\Python312\site-packages\sqlparse\sql.py", line 223, in _token_matching
    if func(token):
       ^^^^^^^^^^^
  File "C:\Users\subhi\AppData\Roaming\Python\Python312\site-packages\sqlparse\sql.py", line 242, in <lambda>
    funcs = lambda tk: imt(tk, i, m, t)
                       ^^^^^^^^^^^^^^^^
  File "C:\Users\subhi\AppData\Roaming\Python\Python312\site-packages\sqlparse\utils.py", line 98, in imt
    elif mpatterns and any(token.match(*pattern) for pattern in mpatterns):
                       ^^^^^^^^^^^^^^^^^^^^^^^^^^^^^^^^^^^^^^^^^^^^^^^^^^^
  File "C:\Users\subhi\AppData\Roaming\Python\Python312\site-packages\sqlparse\utils.py", line 98, in <genexpr>
    elif mpatterns and any(token.match(*pattern) for pattern in mpatterns):
                           ^^^^^^^^^^^^^^^^^^^^^
RecursionError: maximum recursion depth exceeded

The above exception was the direct cause of the following exception:

Traceback (most recent call last):
  File "C:\Users\subhi\AppData\Roaming\Python\Python312\site-packages\djongo\cursor.py", line 76, in fetchone
    return self.result.next()
           ^^^^^^^^^^^^^^^^^^
  File "C:\Users\subhi\AppData\Roaming\Python\Python312\site-packages\djongo\sql2mongo\query.py", line 797, in __next__
    result = next(self._result_generator)
             ^^^^^^^^^^^^^^^^^^^^^^^^^^^^
  File "C:\Users\subhi\AppData\Roaming\Python\Python312\site-packages\djongo\sql2mongo\query.py", line 830, in __iter__
    raise exe from e
djongo.exceptions.SQLDecodeError: 

	Keyword: FAILED SQL: SELECT %(0)s AS "a" FROM "newsapp_user" WHERE "newsapp_user"."email" = %(1)s LIMIT 1
Params: (1, 'subhitcha.s@gmail.com')
Version: 1.3.6
	Sub SQL: None
	FAILED SQL: None
	Params: None
	Version: None

The above exception was the direct cause of the following exception:

Traceback (most recent call last):
  File "C:\Users\subhi\AppData\Roaming\Python\Python312\site-packages\django\db\utils.py", line 98, in inner
    return func(*args, **kwargs)
           ^^^^^^^^^^^^^^^^^^^^^
  File "C:\Users\subhi\AppData\Roaming\Python\Python312\site-packages\djongo\cursor.py", line 81, in fetchone
    raise db_exe from e
djongo.database.DatabaseError

The above exception was the direct cause of the following exception:

Traceback (most recent call last):
  File "C:\Users\subhi\AppData\Roaming\Python\Python312\site-packages\django\core\handlers\exception.py", line 56, in inner
    response = get_response(request)
               ^^^^^^^^^^^^^^^^^^^^^
  File "C:\Users\subhi\AppData\Roaming\Python\Python312\site-packages\django\core\handlers\base.py", line 197, in _get_response
    response = wrapped_callback(request, *callback_args, **callback_kwargs)
               ^^^^^^^^^^^^^^^^^^^^^^^^^^^^^^^^^^^^^^^^^^^^^^^^^^^^^^^^^^^^
  File "C:\Users\subhi\AppData\Roaming\Python\Python312\site-packages\django\views\decorators\csrf.py", line 55, in wrapped_view
    return view_func(*args, **kwargs)
           ^^^^^^^^^^^^^^^^^^^^^^^^^^
  File "C:\Users\subhi\AppData\Roaming\Python\Python312\site-packages\django\views\generic\base.py", line 103, in view
    return self.dispatch(request, *args, **kwargs)
           ^^^^^^^^^^^^^^^^^^^^^^^^^^^^^^^^^^^^^^^
  File "C:\Users\subhi\AppData\Roaming\Python\Python312\site-packages\rest_framework\views.py", line 509, in dispatch
    response = self.handle_exception(exc)
               ^^^^^^^^^^^^^^^^^^^^^^^^^^
  File "C:\Users\subhi\AppData\Roaming\Python\Python312\site-packages\rest_framework\views.py", line 469, in handle_exception
    self.raise_uncaught_exception(exc)
  File "C:\Users\subhi\AppData\Roaming\Python\Python312\site-packages\rest_framework\views.py", line 480, in raise_uncaught_exception
    raise exc
  File "C:\Users\subhi\AppData\Roaming\Python\Python312\site-packages\rest_framework\views.py", line 506, in dispatch
    response = handler(request, *args, **kwargs)
               ^^^^^^^^^^^^^^^^^^^^^^^^^^^^^^^^^
  File "C:\Users\subhi\AppData\Roaming\Python\Python312\site-packages\rest_framework\decorators.py", line 50, in handler
    return func(*args, **kwargs)
           ^^^^^^^^^^^^^^^^^^^^^
  File "C:\cit\6th sem\cloudcat\news_backend\newsapp\views.py", line 91, in register_user
    if User.objects.filter(email=data.get('email')).exists():
       ^^^^^^^^^^^^^^^^^^^^^^^^^^^^^^^^^^^^^^^^^^^^^^^^^^^^^
  File "C:\Users\subhi\AppData\Roaming\Python\Python312\site-packages\django\db\models\query.py", line 1226, in exists
    return self.query.has_results(using=self.db)
           ^^^^^^^^^^^^^^^^^^^^^^^^^^^^^^^^^^^^^
  File "C:\Users\subhi\AppData\Roaming\Python\Python312\site-packages\django\db\models\sql\query.py", line 592, in has_results
    return compiler.has_results()
           ^^^^^^^^^^^^^^^^^^^^^^
  File "C:\Users\subhi\AppData\Roaming\Python\Python312\site-packages\django\db\models\sql\compiler.py", line 1366, in has_results
    return bool(self.execute_sql(SINGLE))
                ^^^^^^^^^^^^^^^^^^^^^^^^
  File "C:\Users\subhi\AppData\Roaming\Python\Python312\site-packages\django\db\models\sql\compiler.py", line 1409, in execute_sql
    val = cursor.fetchone()
          ^^^^^^^^^^^^^^^^^
  File "C:\Users\subhi\AppData\Roaming\Python\Python312\site-packages\django\db\utils.py", line 97, in inner
    with self:
  File "C:\Users\subhi\AppData\Roaming\Python\Python312\site-packages\django\db\utils.py", line 91, in __exit__
    raise dj_exc_value.with_traceback(traceback) from exc_value
  File "C:\Users\subhi\AppData\Roaming\Python\Python312\site-packages\django\db\utils.py", line 98, in inner
    return func(*args, **kwargs)
           ^^^^^^^^^^^^^^^^^^^^^
  File "C:\Users\subhi\AppData\Roaming\Python\Python312\site-packages\djongo\cursor.py", line 81, in fetchone
    raise db_exe from e
django.db.utils.DatabaseError
"POST /api/news/signup/ HTTP/1.1" 500 3816902
Internal Server Error: /api/news/signup/
Traceback (most recent call last):
  File "C:\Users\subhi\AppData\Roaming\Python\Python312\site-packages\djongo\sql2mongo\query.py", line 808, in __iter__
    yield from iter(self._query)
  File "C:\Users\subhi\AppData\Roaming\Python\Python312\site-packages\djongo\sql2mongo\query.py", line 167, in __iter__
    yield self._align_results(doc)
          ^^^^^^^^^^^^^^^^^^^^^^^^
  File "C:\Users\subhi\AppData\Roaming\Python\Python312\site-packages\djongo\sql2mongo\query.py", line 269, in _align_results
    if selected.table == self.left_table:
       ^^^^^^^^^^^^^^
  File "C:\Users\subhi\AppData\Roaming\Python\Python312\site-packages\djongo\sql2mongo\sql_tokens.py", line 133, in table
    return alias2token[name].table
           ^^^^^^^^^^^^^^^^^^^^^^^
  File "C:\Users\subhi\AppData\Roaming\Python\Python312\site-packages\djongo\sql2mongo\sql_tokens.py", line 133, in table
    return alias2token[name].table
           ^^^^^^^^^^^^^^^^^^^^^^^
  File "C:\Users\subhi\AppData\Roaming\Python\Python312\site-packages\djongo\sql2mongo\sql_tokens.py", line 133, in table
    return alias2token[name].table
           ^^^^^^^^^^^^^^^^^^^^^^^
  [Previous line repeated 941 more times]
  File "C:\Users\subhi\AppData\Roaming\Python\Python312\site-packages\djongo\sql2mongo\sql_tokens.py", line 130, in table
    name = self.given_table
           ^^^^^^^^^^^^^^^^
  File "C:\Users\subhi\AppData\Roaming\Python\Python312\site-packages\djongo\sql2mongo\sql_tokens.py", line 141, in given_table
    name = self._token.get_real_name()
           ^^^^^^^^^^^^^^^^^^^^^^^^^^^
  File "C:\Users\subhi\AppData\Roaming\Python\Python312\site-packages\sqlparse\sql.py", line 361, in get_real_name
    return self._get_first_name(dot_idx)
           ^^^^^^^^^^^^^^^^^^^^^^^^^^^^^
  File "C:\Users\subhi\AppData\Roaming\Python\Python312\site-packages\sqlparse\sql.py", line 386, in _get_first_name
    return token.get_name()
           ^^^^^^^^^^^^^^^^
  File "C:\Users\subhi\AppData\Roaming\Python\Python312\site-packages\sqlparse\sql.py", line 355, in get_name
    return self.get_alias() or self.get_real_name()
           ^^^^^^^^^^^^^^^^
  File "C:\Users\subhi\AppData\Roaming\Python\Python312\site-packages\sqlparse\sql.py", line 339, in get_alias
    kw_idx, kw = self.token_next_by(m=(T.Keyword, 'AS'))
                 ^^^^^^^^^^^^^^^^^^^^^^^^^^^^^^^^^^^^^^^
  File "C:\Users\subhi\AppData\Roaming\Python\Python312\site-packages\sqlparse\sql.py", line 244, in token_next_by
    return self._token_matching(funcs, idx, end)
           ^^^^^^^^^^^^^^^^^^^^^^^^^^^^^^^^^^^^^
  File "C:\Users\subhi\AppData\Roaming\Python\Python312\site-packages\sqlparse\sql.py", line 223, in _token_matching
    if func(token):
       ^^^^^^^^^^^
  File "C:\Users\subhi\AppData\Roaming\Python\Python312\site-packages\sqlparse\sql.py", line 242, in <lambda>
    funcs = lambda tk: imt(tk, i, m, t)
                       ^^^^^^^^^^^^^^^^
  File "C:\Users\subhi\AppData\Roaming\Python\Python312\site-packages\sqlparse\utils.py", line 98, in imt
    elif mpatterns and any(token.match(*pattern) for pattern in mpatterns):
                       ^^^^^^^^^^^^^^^^^^^^^^^^^^^^^^^^^^^^^^^^^^^^^^^^^^^
  File "C:\Users\subhi\AppData\Roaming\Python\Python312\site-packages\sqlparse\utils.py", line 98, in <genexpr>
    elif mpatterns and any(token.match(*pattern) for pattern in mpatterns):
                           ^^^^^^^^^^^^^^^^^^^^^
RecursionError: maximum recursion depth exceeded

The above exception was the direct cause of the following exception:

Traceback (most recent call last):
  File "C:\Users\subhi\AppData\Roaming\Python\Python312\site-packages\djongo\cursor.py", line 76, in fetchone
    return self.result.next()
           ^^^^^^^^^^^^^^^^^^
  File "C:\Users\subhi\AppData\Roaming\Python\Python312\site-packages\djongo\sql2mongo\query.py", line 797, in __next__
    result = next(self._result_generator)
             ^^^^^^^^^^^^^^^^^^^^^^^^^^^^
  File "C:\Users\subhi\AppData\Roaming\Python\Python312\site-packages\djongo\sql2mongo\query.py", line 830, in __iter__
    raise exe from e
djongo.exceptions.SQLDecodeError: 

	Keyword: FAILED SQL: SELECT %(0)s AS "a" FROM "newsapp_user" WHERE "newsapp_user"."email" = %(1)s LIMIT 1
Params: (1, 'subhitcha.s@gmail.com')
Version: 1.3.6
	Sub SQL: None
	FAILED SQL: None
	Params: None
	Version: None

The above exception was the direct cause of the following exception:

Traceback (most recent call last):
  File "C:\Users\subhi\AppData\Roaming\Python\Python312\site-packages\django\db\utils.py", line 98, in inner
    return func(*args, **kwargs)
           ^^^^^^^^^^^^^^^^^^^^^
  File "C:\Users\subhi\AppData\Roaming\Python\Python312\site-packages\djongo\cursor.py", line 81, in fetchone
    raise db_exe from e
djongo.database.DatabaseError

The above exception was the direct cause of the following exception:

Traceback (most recent call last):
  File "C:\Users\subhi\AppData\Roaming\Python\Python312\site-packages\django\core\handlers\exception.py", line 56, in inner
    response = get_response(request)
               ^^^^^^^^^^^^^^^^^^^^^
  File "C:\Users\subhi\AppData\Roaming\Python\Python312\site-packages\django\core\handlers\base.py", line 197, in _get_response
    response = wrapped_callback(request, *callback_args, **callback_kwargs)
               ^^^^^^^^^^^^^^^^^^^^^^^^^^^^^^^^^^^^^^^^^^^^^^^^^^^^^^^^^^^^
  File "C:\Users\subhi\AppData\Roaming\Python\Python312\site-packages\django\views\decorators\csrf.py", line 55, in wrapped_view
    return view_func(*args, **kwargs)
           ^^^^^^^^^^^^^^^^^^^^^^^^^^
  File "C:\Users\subhi\AppData\Roaming\Python\Python312\site-packages\django\views\generic\base.py", line 103, in view
    return self.dispatch(request, *args, **kwargs)
           ^^^^^^^^^^^^^^^^^^^^^^^^^^^^^^^^^^^^^^^
  File "C:\Users\subhi\AppData\Roaming\Python\Python312\site-packages\rest_framework\views.py", line 509, in dispatch
    response = self.handle_exception(exc)
               ^^^^^^^^^^^^^^^^^^^^^^^^^^
  File "C:\Users\subhi\AppData\Roaming\Python\Python312\site-packages\rest_framework\views.py", line 469, in handle_exception
    self.raise_uncaught_exception(exc)
  File "C:\Users\subhi\AppData\Roaming\Python\Python312\site-packages\rest_framework\views.py", line 480, in raise_uncaught_exception
    raise exc
  File "C:\Users\subhi\AppData\Roaming\Python\Python312\site-packages\rest_framework\views.py", line 506, in dispatch
    response = handler(request, *args, **kwargs)
               ^^^^^^^^^^^^^^^^^^^^^^^^^^^^^^^^^
  File "C:\Users\subhi\AppData\Roaming\Python\Python312\site-packages\rest_framework\decorators.py", line 50, in handler
    return func(*args, **kwargs)
           ^^^^^^^^^^^^^^^^^^^^^
  File "C:\cit\6th sem\cloudcat\news_backend\newsapp\views.py", line 91, in register_user
    if User.objects.filter(email=data.get('email')).exists():
       ^^^^^^^^^^^^^^^^^^^^^^^^^^^^^^^^^^^^^^^^^^^^^^^^^^^^^
  File "C:\Users\subhi\AppData\Roaming\Python\Python312\site-packages\django\db\models\query.py", line 1226, in exists
    return self.query.has_results(using=self.db)
           ^^^^^^^^^^^^^^^^^^^^^^^^^^^^^^^^^^^^^
  File "C:\Users\subhi\AppData\Roaming\Python\Python312\site-packages\django\db\models\sql\query.py", line 592, in has_results
    return compiler.has_results()
           ^^^^^^^^^^^^^^^^^^^^^^
  File "C:\Users\subhi\AppData\Roaming\Python\Python312\site-packages\django\db\models\sql\compiler.py", line 1366, in has_results
    return bool(self.execute_sql(SINGLE))
                ^^^^^^^^^^^^^^^^^^^^^^^^
  File "C:\Users\subhi\AppData\Roaming\Python\Python312\site-packages\django\db\models\sql\compiler.py", line 1409, in execute_sql
    val = cursor.fetchone()
          ^^^^^^^^^^^^^^^^^
  File "C:\Users\subhi\AppData\Roaming\Python\Python312\site-packages\django\db\utils.py", line 97, in inner
    with self:
  File "C:\Users\subhi\AppData\Roaming\Python\Python312\site-packages\django\db\utils.py", line 91, in __exit__
    raise dj_exc_value.with_traceback(traceback) from exc_value
  File "C:\Users\subhi\AppData\Roaming\Python\Python312\site-packages\django\db\utils.py", line 98, in inner
    return func(*args, **kwargs)
           ^^^^^^^^^^^^^^^^^^^^^
  File "C:\Users\subhi\AppData\Roaming\Python\Python312\site-packages\djongo\cursor.py", line 81, in fetchone
    raise db_exe from e
django.db.utils.DatabaseError
"POST /api/news/signup/ HTTP/1.1" 500 3816902
Internal Server Error: /api/news/signup/
Traceback (most recent call last):
  File "C:\Users\subhi\AppData\Roaming\Python\Python312\site-packages\djongo\sql2mongo\query.py", line 808, in __iter__
    yield from iter(self._query)
  File "C:\Users\subhi\AppData\Roaming\Python\Python312\site-packages\djongo\sql2mongo\query.py", line 167, in __iter__
    yield self._align_results(doc)
          ^^^^^^^^^^^^^^^^^^^^^^^^
  File "C:\Users\subhi\AppData\Roaming\Python\Python312\site-packages\djongo\sql2mongo\query.py", line 269, in _align_results
    if selected.table == self.left_table:
       ^^^^^^^^^^^^^^
  File "C:\Users\subhi\AppData\Roaming\Python\Python312\site-packages\djongo\sql2mongo\sql_tokens.py", line 133, in table
    return alias2token[name].table
           ^^^^^^^^^^^^^^^^^^^^^^^
  File "C:\Users\subhi\AppData\Roaming\Python\Python312\site-packages\djongo\sql2mongo\sql_tokens.py", line 133, in table
    return alias2token[name].table
           ^^^^^^^^^^^^^^^^^^^^^^^
  File "C:\Users\subhi\AppData\Roaming\Python\Python312\site-packages\djongo\sql2mongo\sql_tokens.py", line 133, in table
    return alias2token[name].table
           ^^^^^^^^^^^^^^^^^^^^^^^
  [Previous line repeated 941 more times]
  File "C:\Users\subhi\AppData\Roaming\Python\Python312\site-packages\djongo\sql2mongo\sql_tokens.py", line 130, in table
    name = self.given_table
           ^^^^^^^^^^^^^^^^
  File "C:\Users\subhi\AppData\Roaming\Python\Python312\site-packages\djongo\sql2mongo\sql_tokens.py", line 141, in given_table
    name = self._token.get_real_name()
           ^^^^^^^^^^^^^^^^^^^^^^^^^^^
  File "C:\Users\subhi\AppData\Roaming\Python\Python312\site-packages\sqlparse\sql.py", line 361, in get_real_name
    return self._get_first_name(dot_idx)
           ^^^^^^^^^^^^^^^^^^^^^^^^^^^^^
  File "C:\Users\subhi\AppData\Roaming\Python\Python312\site-packages\sqlparse\sql.py", line 386, in _get_first_name
    return token.get_name()
           ^^^^^^^^^^^^^^^^
  File "C:\Users\subhi\AppData\Roaming\Python\Python312\site-packages\sqlparse\sql.py", line 355, in get_name
    return self.get_alias() or self.get_real_name()
           ^^^^^^^^^^^^^^^^
  File "C:\Users\subhi\AppData\Roaming\Python\Python312\site-packages\sqlparse\sql.py", line 339, in get_alias
    kw_idx, kw = self.token_next_by(m=(T.Keyword, 'AS'))
                 ^^^^^^^^^^^^^^^^^^^^^^^^^^^^^^^^^^^^^^^
  File "C:\Users\subhi\AppData\Roaming\Python\Python312\site-packages\sqlparse\sql.py", line 244, in token_next_by
    return self._token_matching(funcs, idx, end)
           ^^^^^^^^^^^^^^^^^^^^^^^^^^^^^^^^^^^^^
  File "C:\Users\subhi\AppData\Roaming\Python\Python312\site-packages\sqlparse\sql.py", line 223, in _token_matching
    if func(token):
       ^^^^^^^^^^^
  File "C:\Users\subhi\AppData\Roaming\Python\Python312\site-packages\sqlparse\sql.py", line 242, in <lambda>
    funcs = lambda tk: imt(tk, i, m, t)
                       ^^^^^^^^^^^^^^^^
  File "C:\Users\subhi\AppData\Roaming\Python\Python312\site-packages\sqlparse\utils.py", line 98, in imt
    elif mpatterns and any(token.match(*pattern) for pattern in mpatterns):
                       ^^^^^^^^^^^^^^^^^^^^^^^^^^^^^^^^^^^^^^^^^^^^^^^^^^^
  File "C:\Users\subhi\AppData\Roaming\Python\Python312\site-packages\sqlparse\utils.py", line 98, in <genexpr>
    elif mpatterns and any(token.match(*pattern) for pattern in mpatterns):
                           ^^^^^^^^^^^^^^^^^^^^^
RecursionError: maximum recursion depth exceeded

The above exception was the direct cause of the following exception:

Traceback (most recent call last):
  File "C:\Users\subhi\AppData\Roaming\Python\Python312\site-packages\djongo\cursor.py", line 76, in fetchone
    return self.result.next()
           ^^^^^^^^^^^^^^^^^^
  File "C:\Users\subhi\AppData\Roaming\Python\Python312\site-packages\djongo\sql2mongo\query.py", line 797, in __next__
    result = next(self._result_generator)
             ^^^^^^^^^^^^^^^^^^^^^^^^^^^^
  File "C:\Users\subhi\AppData\Roaming\Python\Python312\site-packages\djongo\sql2mongo\query.py", line 830, in __iter__
    raise exe from e
djongo.exceptions.SQLDecodeError: 

	Keyword: FAILED SQL: SELECT %(0)s AS "a" FROM "newsapp_user" WHERE "newsapp_user"."email" = %(1)s LIMIT 1
Params: (1, 'subhitcha.s@gmail.com')
Version: 1.3.6
	Sub SQL: None
	FAILED SQL: None
	Params: None
	Version: None

The above exception was the direct cause of the following exception:

Traceback (most recent call last):
  File "C:\Users\subhi\AppData\Roaming\Python\Python312\site-packages\django\db\utils.py", line 98, in inner
    return func(*args, **kwargs)
           ^^^^^^^^^^^^^^^^^^^^^
  File "C:\Users\subhi\AppData\Roaming\Python\Python312\site-packages\djongo\cursor.py", line 81, in fetchone
    raise db_exe from e
djongo.database.DatabaseError

The above exception was the direct cause of the following exception:

Traceback (most recent call last):
  File "C:\Users\subhi\AppData\Roaming\Python\Python312\site-packages\django\core\handlers\exception.py", line 56, in inner
    response = get_response(request)
               ^^^^^^^^^^^^^^^^^^^^^
  File "C:\Users\subhi\AppData\Roaming\Python\Python312\site-packages\django\core\handlers\base.py", line 197, in _get_response
    response = wrapped_callback(request, *callback_args, **callback_kwargs)
               ^^^^^^^^^^^^^^^^^^^^^^^^^^^^^^^^^^^^^^^^^^^^^^^^^^^^^^^^^^^^
  File "C:\Users\subhi\AppData\Roaming\Python\Python312\site-packages\django\views\decorators\csrf.py", line 55, in wrapped_view
    return view_func(*args, **kwargs)
           ^^^^^^^^^^^^^^^^^^^^^^^^^^
  File "C:\Users\subhi\AppData\Roaming\Python\Python312\site-packages\django\views\generic\base.py", line 103, in view
    return self.dispatch(request, *args, **kwargs)
           ^^^^^^^^^^^^^^^^^^^^^^^^^^^^^^^^^^^^^^^
  File "C:\Users\subhi\AppData\Roaming\Python\Python312\site-packages\rest_framework\views.py", line 509, in dispatch
    response = self.handle_exception(exc)
               ^^^^^^^^^^^^^^^^^^^^^^^^^^
  File "C:\Users\subhi\AppData\Roaming\Python\Python312\site-packages\rest_framework\views.py", line 469, in handle_exception
    self.raise_uncaught_exception(exc)
  File "C:\Users\subhi\AppData\Roaming\Python\Python312\site-packages\rest_framework\views.py", line 480, in raise_uncaught_exception
    raise exc
  File "C:\Users\subhi\AppData\Roaming\Python\Python312\site-packages\rest_framework\views.py", line 506, in dispatch
    response = handler(request, *args, **kwargs)
               ^^^^^^^^^^^^^^^^^^^^^^^^^^^^^^^^^
  File "C:\Users\subhi\AppData\Roaming\Python\Python312\site-packages\rest_framework\decorators.py", line 50, in handler
    return func(*args, **kwargs)
           ^^^^^^^^^^^^^^^^^^^^^
  File "C:\cit\6th sem\cloudcat\news_backend\newsapp\views.py", line 91, in register_user
    if User.objects.filter(email=data.get('email')).exists():
       ^^^^^^^^^^^^^^^^^^^^^^^^^^^^^^^^^^^^^^^^^^^^^^^^^^^^^
  File "C:\Users\subhi\AppData\Roaming\Python\Python312\site-packages\django\db\models\query.py", line 1226, in exists
    return self.query.has_results(using=self.db)
           ^^^^^^^^^^^^^^^^^^^^^^^^^^^^^^^^^^^^^
  File "C:\Users\subhi\AppData\Roaming\Python\Python312\site-packages\django\db\models\sql\query.py", line 592, in has_results
    return compiler.has_results()
           ^^^^^^^^^^^^^^^^^^^^^^
  File "C:\Users\subhi\AppData\Roaming\Python\Python312\site-packages\django\db\models\sql\compiler.py", line 1366, in has_results
    return bool(self.execute_sql(SINGLE))
                ^^^^^^^^^^^^^^^^^^^^^^^^
  File "C:\Users\subhi\AppData\Roaming\Python\Python312\site-packages\django\db\models\sql\compiler.py", line 1409, in execute_sql
    val = cursor.fetchone()
          ^^^^^^^^^^^^^^^^^
  File "C:\Users\subhi\AppData\Roaming\Python\Python312\site-packages\django\db\utils.py", line 97, in inner
    with self:
  File "C:\Users\subhi\AppData\Roaming\Python\Python312\site-packages\django\db\utils.py", line 91, in __exit__
    raise dj_exc_value.with_traceback(traceback) from exc_value
  File "C:\Users\subhi\AppData\Roaming\Python\Python312\site-packages\django\db\utils.py", line 98, in inner
    return func(*args, **kwargs)
           ^^^^^^^^^^^^^^^^^^^^^
  File "C:\Users\subhi\AppData\Roaming\Python\Python312\site-packages\djongo\cursor.py", line 81, in fetchone
    raise db_exe from e
django.db.utils.DatabaseError
"POST /api/news/signup/ HTTP/1.1" 500 3816902
Internal Server Error: /api/news/signup/
Traceback (most recent call last):
  File "C:\Users\subhi\AppData\Roaming\Python\Python312\site-packages\djongo\sql2mongo\query.py", line 808, in __iter__
    yield from iter(self._query)
  File "C:\Users\subhi\AppData\Roaming\Python\Python312\site-packages\djongo\sql2mongo\query.py", line 167, in __iter__
    yield self._align_results(doc)
          ^^^^^^^^^^^^^^^^^^^^^^^^
  File "C:\Users\subhi\AppData\Roaming\Python\Python312\site-packages\djongo\sql2mongo\query.py", line 269, in _align_results
    if selected.table == self.left_table:
       ^^^^^^^^^^^^^^
  File "C:\Users\subhi\AppData\Roaming\Python\Python312\site-packages\djongo\sql2mongo\sql_tokens.py", line 133, in table
    return alias2token[name].table
           ^^^^^^^^^^^^^^^^^^^^^^^
  File "C:\Users\subhi\AppData\Roaming\Python\Python312\site-packages\djongo\sql2mongo\sql_tokens.py", line 133, in table
    return alias2token[name].table
           ^^^^^^^^^^^^^^^^^^^^^^^
  File "C:\Users\subhi\AppData\Roaming\Python\Python312\site-packages\djongo\sql2mongo\sql_tokens.py", line 133, in table
    return alias2token[name].table
           ^^^^^^^^^^^^^^^^^^^^^^^
  [Previous line repeated 941 more times]
  File "C:\Users\subhi\AppData\Roaming\Python\Python312\site-packages\djongo\sql2mongo\sql_tokens.py", line 130, in table
    name = self.given_table
           ^^^^^^^^^^^^^^^^
  File "C:\Users\subhi\AppData\Roaming\Python\Python312\site-packages\djongo\sql2mongo\sql_tokens.py", line 141, in given_table
    name = self._token.get_real_name()
           ^^^^^^^^^^^^^^^^^^^^^^^^^^^
  File "C:\Users\subhi\AppData\Roaming\Python\Python312\site-packages\sqlparse\sql.py", line 361, in get_real_name
    return self._get_first_name(dot_idx)
           ^^^^^^^^^^^^^^^^^^^^^^^^^^^^^
  File "C:\Users\subhi\AppData\Roaming\Python\Python312\site-packages\sqlparse\sql.py", line 386, in _get_first_name
    return token.get_name()
           ^^^^^^^^^^^^^^^^
  File "C:\Users\subhi\AppData\Roaming\Python\Python312\site-packages\sqlparse\sql.py", line 355, in get_name
    return self.get_alias() or self.get_real_name()
           ^^^^^^^^^^^^^^^^
  File "C:\Users\subhi\AppData\Roaming\Python\Python312\site-packages\sqlparse\sql.py", line 339, in get_alias
    kw_idx, kw = self.token_next_by(m=(T.Keyword, 'AS'))
                 ^^^^^^^^^^^^^^^^^^^^^^^^^^^^^^^^^^^^^^^
  File "C:\Users\subhi\AppData\Roaming\Python\Python312\site-packages\sqlparse\sql.py", line 244, in token_next_by
    return self._token_matching(funcs, idx, end)
           ^^^^^^^^^^^^^^^^^^^^^^^^^^^^^^^^^^^^^
  File "C:\Users\subhi\AppData\Roaming\Python\Python312\site-packages\sqlparse\sql.py", line 223, in _token_matching
    if func(token):
       ^^^^^^^^^^^
  File "C:\Users\subhi\AppData\Roaming\Python\Python312\site-packages\sqlparse\sql.py", line 242, in <lambda>
    funcs = lambda tk: imt(tk, i, m, t)
                       ^^^^^^^^^^^^^^^^
  File "C:\Users\subhi\AppData\Roaming\Python\Python312\site-packages\sqlparse\utils.py", line 98, in imt
    elif mpatterns and any(token.match(*pattern) for pattern in mpatterns):
                       ^^^^^^^^^^^^^^^^^^^^^^^^^^^^^^^^^^^^^^^^^^^^^^^^^^^
  File "C:\Users\subhi\AppData\Roaming\Python\Python312\site-packages\sqlparse\utils.py", line 98, in <genexpr>
    elif mpatterns and any(token.match(*pattern) for pattern in mpatterns):
                           ^^^^^^^^^^^^^^^^^^^^^
RecursionError: maximum recursion depth exceeded

The above exception was the direct cause of the following exception:

Traceback (most recent call last):
  File "C:\Users\subhi\AppData\Roaming\Python\Python312\site-packages\djongo\cursor.py", line 76, in fetchone
    return self.result.next()
           ^^^^^^^^^^^^^^^^^^
  File "C:\Users\subhi\AppData\Roaming\Python\Python312\site-packages\djongo\sql2mongo\query.py", line 797, in __next__
    result = next(self._result_generator)
             ^^^^^^^^^^^^^^^^^^^^^^^^^^^^
  File "C:\Users\subhi\AppData\Roaming\Python\Python312\site-packages\djongo\sql2mongo\query.py", line 830, in __iter__
    raise exe from e
djongo.exceptions.SQLDecodeError: 

	Keyword: FAILED SQL: SELECT %(0)s AS "a" FROM "newsapp_user" WHERE "newsapp_user"."email" = %(1)s LIMIT 1
Params: (1, 'subhitcha.s@gmail.com')
Version: 1.3.6
	Sub SQL: None
	FAILED SQL: None
	Params: None
	Version: None

The above exception was the direct cause of the following exception:

Traceback (most recent call last):
  File "C:\Users\subhi\AppData\Roaming\Python\Python312\site-packages\django\db\utils.py", line 98, in inner
    return func(*args, **kwargs)
           ^^^^^^^^^^^^^^^^^^^^^
  File "C:\Users\subhi\AppData\Roaming\Python\Python312\site-packages\djongo\cursor.py", line 81, in fetchone
    raise db_exe from e
djongo.database.DatabaseError

The above exception was the direct cause of the following exception:

Traceback (most recent call last):
  File "C:\Users\subhi\AppData\Roaming\Python\Python312\site-packages\django\core\handlers\exception.py", line 56, in inner
    response = get_response(request)
               ^^^^^^^^^^^^^^^^^^^^^
  File "C:\Users\subhi\AppData\Roaming\Python\Python312\site-packages\django\core\handlers\base.py", line 197, in _get_response
    response = wrapped_callback(request, *callback_args, **callback_kwargs)
               ^^^^^^^^^^^^^^^^^^^^^^^^^^^^^^^^^^^^^^^^^^^^^^^^^^^^^^^^^^^^
  File "C:\Users\subhi\AppData\Roaming\Python\Python312\site-packages\django\views\decorators\csrf.py", line 55, in wrapped_view
    return view_func(*args, **kwargs)
           ^^^^^^^^^^^^^^^^^^^^^^^^^^
  File "C:\Users\subhi\AppData\Roaming\Python\Python312\site-packages\django\views\generic\base.py", line 103, in view
    return self.dispatch(request, *args, **kwargs)
           ^^^^^^^^^^^^^^^^^^^^^^^^^^^^^^^^^^^^^^^
  File "C:\Users\subhi\AppData\Roaming\Python\Python312\site-packages\rest_framework\views.py", line 509, in dispatch
    response = self.handle_exception(exc)
               ^^^^^^^^^^^^^^^^^^^^^^^^^^
  File "C:\Users\subhi\AppData\Roaming\Python\Python312\site-packages\rest_framework\views.py", line 469, in handle_exception
    self.raise_uncaught_exception(exc)
  File "C:\Users\subhi\AppData\Roaming\Python\Python312\site-packages\rest_framework\views.py", line 480, in raise_uncaught_exception
    raise exc
  File "C:\Users\subhi\AppData\Roaming\Python\Python312\site-packages\rest_framework\views.py", line 506, in dispatch
    response = handler(request, *args, **kwargs)
               ^^^^^^^^^^^^^^^^^^^^^^^^^^^^^^^^^
  File "C:\Users\subhi\AppData\Roaming\Python\Python312\site-packages\rest_framework\decorators.py", line 50, in handler
    return func(*args, **kwargs)
           ^^^^^^^^^^^^^^^^^^^^^
  File "C:\cit\6th sem\cloudcat\news_backend\newsapp\views.py", line 91, in register_user
    if User.objects.filter(email=data.get('email')).exists():
       ^^^^^^^^^^^^^^^^^^^^^^^^^^^^^^^^^^^^^^^^^^^^^^^^^^^^^
  File "C:\Users\subhi\AppData\Roaming\Python\Python312\site-packages\django\db\models\query.py", line 1226, in exists
    return self.query.has_results(using=self.db)
           ^^^^^^^^^^^^^^^^^^^^^^^^^^^^^^^^^^^^^
  File "C:\Users\subhi\AppData\Roaming\Python\Python312\site-packages\django\db\models\sql\query.py", line 592, in has_results
    return compiler.has_results()
           ^^^^^^^^^^^^^^^^^^^^^^
  File "C:\Users\subhi\AppData\Roaming\Python\Python312\site-packages\django\db\models\sql\compiler.py", line 1366, in has_results
    return bool(self.execute_sql(SINGLE))
                ^^^^^^^^^^^^^^^^^^^^^^^^
  File "C:\Users\subhi\AppData\Roaming\Python\Python312\site-packages\django\db\models\sql\compiler.py", line 1409, in execute_sql
    val = cursor.fetchone()
          ^^^^^^^^^^^^^^^^^
  File "C:\Users\subhi\AppData\Roaming\Python\Python312\site-packages\django\db\utils.py", line 97, in inner
    with self:
  File "C:\Users\subhi\AppData\Roaming\Python\Python312\site-packages\django\db\utils.py", line 91, in __exit__
    raise dj_exc_value.with_traceback(traceback) from exc_value
  File "C:\Users\subhi\AppData\Roaming\Python\Python312\site-packages\django\db\utils.py", line 98, in inner
    return func(*args, **kwargs)
           ^^^^^^^^^^^^^^^^^^^^^
  File "C:\Users\subhi\AppData\Roaming\Python\Python312\site-packages\djongo\cursor.py", line 81, in fetchone
    raise db_exe from e
django.db.utils.DatabaseError
"POST /api/news/signup/ HTTP/1.1" 500 3816902
Internal Server Error: /api/news/signup/
Traceback (most recent call last):
  File "C:\Users\subhi\AppData\Roaming\Python\Python312\site-packages\djongo\sql2mongo\query.py", line 808, in __iter__
    yield from iter(self._query)
  File "C:\Users\subhi\AppData\Roaming\Python\Python312\site-packages\djongo\sql2mongo\query.py", line 167, in __iter__
    yield self._align_results(doc)
          ^^^^^^^^^^^^^^^^^^^^^^^^
  File "C:\Users\subhi\AppData\Roaming\Python\Python312\site-packages\djongo\sql2mongo\query.py", line 269, in _align_results
    if selected.table == self.left_table:
       ^^^^^^^^^^^^^^
  File "C:\Users\subhi\AppData\Roaming\Python\Python312\site-packages\djongo\sql2mongo\sql_tokens.py", line 133, in table
    return alias2token[name].table
           ^^^^^^^^^^^^^^^^^^^^^^^
  File "C:\Users\subhi\AppData\Roaming\Python\Python312\site-packages\djongo\sql2mongo\sql_tokens.py", line 133, in table
    return alias2token[name].table
           ^^^^^^^^^^^^^^^^^^^^^^^
  File "C:\Users\subhi\AppData\Roaming\Python\Python312\site-packages\djongo\sql2mongo\sql_tokens.py", line 133, in table
    return alias2token[name].table
           ^^^^^^^^^^^^^^^^^^^^^^^
  [Previous line repeated 941 more times]
  File "C:\Users\subhi\AppData\Roaming\Python\Python312\site-packages\djongo\sql2mongo\sql_tokens.py", line 130, in table
    name = self.given_table
           ^^^^^^^^^^^^^^^^
  File "C:\Users\subhi\AppData\Roaming\Python\Python312\site-packages\djongo\sql2mongo\sql_tokens.py", line 141, in given_table
    name = self._token.get_real_name()
           ^^^^^^^^^^^^^^^^^^^^^^^^^^^
  File "C:\Users\subhi\AppData\Roaming\Python\Python312\site-packages\sqlparse\sql.py", line 361, in get_real_name
    return self._get_first_name(dot_idx)
           ^^^^^^^^^^^^^^^^^^^^^^^^^^^^^
  File "C:\Users\subhi\AppData\Roaming\Python\Python312\site-packages\sqlparse\sql.py", line 386, in _get_first_name
    return token.get_name()
           ^^^^^^^^^^^^^^^^
  File "C:\Users\subhi\AppData\Roaming\Python\Python312\site-packages\sqlparse\sql.py", line 355, in get_name
    return self.get_alias() or self.get_real_name()
           ^^^^^^^^^^^^^^^^
  File "C:\Users\subhi\AppData\Roaming\Python\Python312\site-packages\sqlparse\sql.py", line 339, in get_alias
    kw_idx, kw = self.token_next_by(m=(T.Keyword, 'AS'))
                 ^^^^^^^^^^^^^^^^^^^^^^^^^^^^^^^^^^^^^^^
  File "C:\Users\subhi\AppData\Roaming\Python\Python312\site-packages\sqlparse\sql.py", line 244, in token_next_by
    return self._token_matching(funcs, idx, end)
           ^^^^^^^^^^^^^^^^^^^^^^^^^^^^^^^^^^^^^
  File "C:\Users\subhi\AppData\Roaming\Python\Python312\site-packages\sqlparse\sql.py", line 223, in _token_matching
    if func(token):
       ^^^^^^^^^^^
  File "C:\Users\subhi\AppData\Roaming\Python\Python312\site-packages\sqlparse\sql.py", line 242, in <lambda>
    funcs = lambda tk: imt(tk, i, m, t)
                       ^^^^^^^^^^^^^^^^
  File "C:\Users\subhi\AppData\Roaming\Python\Python312\site-packages\sqlparse\utils.py", line 98, in imt
    elif mpatterns and any(token.match(*pattern) for pattern in mpatterns):
                       ^^^^^^^^^^^^^^^^^^^^^^^^^^^^^^^^^^^^^^^^^^^^^^^^^^^
  File "C:\Users\subhi\AppData\Roaming\Python\Python312\site-packages\sqlparse\utils.py", line 98, in <genexpr>
    elif mpatterns and any(token.match(*pattern) for pattern in mpatterns):
                           ^^^^^^^^^^^^^^^^^^^^^
RecursionError: maximum recursion depth exceeded

The above exception was the direct cause of the following exception:

Traceback (most recent call last):
  File "C:\Users\subhi\AppData\Roaming\Python\Python312\site-packages\djongo\cursor.py", line 76, in fetchone
    return self.result.next()
           ^^^^^^^^^^^^^^^^^^
  File "C:\Users\subhi\AppData\Roaming\Python\Python312\site-packages\djongo\sql2mongo\query.py", line 797, in __next__
    result = next(self._result_generator)
             ^^^^^^^^^^^^^^^^^^^^^^^^^^^^
  File "C:\Users\subhi\AppData\Roaming\Python\Python312\site-packages\djongo\sql2mongo\query.py", line 830, in __iter__
    raise exe from e
djongo.exceptions.SQLDecodeError: 

	Keyword: FAILED SQL: SELECT %(0)s AS "a" FROM "newsapp_user" WHERE "newsapp_user"."email" = %(1)s LIMIT 1
Params: (1, 'subhitcha.s@gmail.com')
Version: 1.3.6
	Sub SQL: None
	FAILED SQL: None
	Params: None
	Version: None

The above exception was the direct cause of the following exception:

Traceback (most recent call last):
  File "C:\Users\subhi\AppData\Roaming\Python\Python312\site-packages\django\db\utils.py", line 98, in inner
    return func(*args, **kwargs)
           ^^^^^^^^^^^^^^^^^^^^^
  File "C:\Users\subhi\AppData\Roaming\Python\Python312\site-packages\djongo\cursor.py", line 81, in fetchone
    raise db_exe from e
djongo.database.DatabaseError

The above exception was the direct cause of the following exception:

Traceback (most recent call last):
  File "C:\Users\subhi\AppData\Roaming\Python\Python312\site-packages\django\core\handlers\exception.py", line 56, in inner
    response = get_response(request)
               ^^^^^^^^^^^^^^^^^^^^^
  File "C:\Users\subhi\AppData\Roaming\Python\Python312\site-packages\django\core\handlers\base.py", line 197, in _get_response
    response = wrapped_callback(request, *callback_args, **callback_kwargs)
               ^^^^^^^^^^^^^^^^^^^^^^^^^^^^^^^^^^^^^^^^^^^^^^^^^^^^^^^^^^^^
  File "C:\Users\subhi\AppData\Roaming\Python\Python312\site-packages\django\views\decorators\csrf.py", line 55, in wrapped_view
    return view_func(*args, **kwargs)
           ^^^^^^^^^^^^^^^^^^^^^^^^^^
  File "C:\Users\subhi\AppData\Roaming\Python\Python312\site-packages\django\views\generic\base.py", line 103, in view
    return self.dispatch(request, *args, **kwargs)
           ^^^^^^^^^^^^^^^^^^^^^^^^^^^^^^^^^^^^^^^
  File "C:\Users\subhi\AppData\Roaming\Python\Python312\site-packages\rest_framework\views.py", line 509, in dispatch
    response = self.handle_exception(exc)
               ^^^^^^^^^^^^^^^^^^^^^^^^^^
  File "C:\Users\subhi\AppData\Roaming\Python\Python312\site-packages\rest_framework\views.py", line 469, in handle_exception
    self.raise_uncaught_exception(exc)
  File "C:\Users\subhi\AppData\Roaming\Python\Python312\site-packages\rest_framework\views.py", line 480, in raise_uncaught_exception
    raise exc
  File "C:\Users\subhi\AppData\Roaming\Python\Python312\site-packages\rest_framework\views.py", line 506, in dispatch
    response = handler(request, *args, **kwargs)
               ^^^^^^^^^^^^^^^^^^^^^^^^^^^^^^^^^
  File "C:\Users\subhi\AppData\Roaming\Python\Python312\site-packages\rest_framework\decorators.py", line 50, in handler
    return func(*args, **kwargs)
           ^^^^^^^^^^^^^^^^^^^^^
  File "C:\cit\6th sem\cloudcat\news_backend\newsapp\views.py", line 91, in register_user
    if User.objects.filter(email=data.get('email')).exists():
       ^^^^^^^^^^^^^^^^^^^^^^^^^^^^^^^^^^^^^^^^^^^^^^^^^^^^^
  File "C:\Users\subhi\AppData\Roaming\Python\Python312\site-packages\django\db\models\query.py", line 1226, in exists
    return self.query.has_results(using=self.db)
           ^^^^^^^^^^^^^^^^^^^^^^^^^^^^^^^^^^^^^
  File "C:\Users\subhi\AppData\Roaming\Python\Python312\site-packages\django\db\models\sql\query.py", line 592, in has_results
    return compiler.has_results()
           ^^^^^^^^^^^^^^^^^^^^^^
  File "C:\Users\subhi\AppData\Roaming\Python\Python312\site-packages\django\db\models\sql\compiler.py", line 1366, in has_results
    return bool(self.execute_sql(SINGLE))
                ^^^^^^^^^^^^^^^^^^^^^^^^
  File "C:\Users\subhi\AppData\Roaming\Python\Python312\site-packages\django\db\models\sql\compiler.py", line 1409, in execute_sql
    val = cursor.fetchone()
          ^^^^^^^^^^^^^^^^^
  File "C:\Users\subhi\AppData\Roaming\Python\Python312\site-packages\django\db\utils.py", line 97, in inner
    with self:
  File "C:\Users\subhi\AppData\Roaming\Python\Python312\site-packages\django\db\utils.py", line 91, in __exit__
    raise dj_exc_value.with_traceback(traceback) from exc_value
  File "C:\Users\subhi\AppData\Roaming\Python\Python312\site-packages\django\db\utils.py", line 98, in inner
    return func(*args, **kwargs)
           ^^^^^^^^^^^^^^^^^^^^^
  File "C:\Users\subhi\AppData\Roaming\Python\Python312\site-packages\djongo\cursor.py", line 81, in fetchone
    raise db_exe from e
django.db.utils.DatabaseError
"POST /api/news/signup/ HTTP/1.1" 500 3816902
Internal Server Error: /api/news/signup/
Traceback (most recent call last):
  File "C:\Users\subhi\AppData\Roaming\Python\Python312\site-packages\djongo\sql2mongo\query.py", line 808, in __iter__
    yield from iter(self._query)
  File "C:\Users\subhi\AppData\Roaming\Python\Python312\site-packages\djongo\sql2mongo\query.py", line 167, in __iter__
    yield self._align_results(doc)
          ^^^^^^^^^^^^^^^^^^^^^^^^
  File "C:\Users\subhi\AppData\Roaming\Python\Python312\site-packages\djongo\sql2mongo\query.py", line 269, in _align_results
    if selected.table == self.left_table:
       ^^^^^^^^^^^^^^
  File "C:\Users\subhi\AppData\Roaming\Python\Python312\site-packages\djongo\sql2mongo\sql_tokens.py", line 133, in table
    return alias2token[name].table
           ^^^^^^^^^^^^^^^^^^^^^^^
  File "C:\Users\subhi\AppData\Roaming\Python\Python312\site-packages\djongo\sql2mongo\sql_tokens.py", line 133, in table
    return alias2token[name].table
           ^^^^^^^^^^^^^^^^^^^^^^^
  File "C:\Users\subhi\AppData\Roaming\Python\Python312\site-packages\djongo\sql2mongo\sql_tokens.py", line 133, in table
    return alias2token[name].table
           ^^^^^^^^^^^^^^^^^^^^^^^
  [Previous line repeated 941 more times]
  File "C:\Users\subhi\AppData\Roaming\Python\Python312\site-packages\djongo\sql2mongo\sql_tokens.py", line 130, in table
    name = self.given_table
           ^^^^^^^^^^^^^^^^
  File "C:\Users\subhi\AppData\Roaming\Python\Python312\site-packages\djongo\sql2mongo\sql_tokens.py", line 141, in given_table
    name = self._token.get_real_name()
           ^^^^^^^^^^^^^^^^^^^^^^^^^^^
  File "C:\Users\subhi\AppData\Roaming\Python\Python312\site-packages\sqlparse\sql.py", line 361, in get_real_name
    return self._get_first_name(dot_idx)
           ^^^^^^^^^^^^^^^^^^^^^^^^^^^^^
  File "C:\Users\subhi\AppData\Roaming\Python\Python312\site-packages\sqlparse\sql.py", line 386, in _get_first_name
    return token.get_name()
           ^^^^^^^^^^^^^^^^
  File "C:\Users\subhi\AppData\Roaming\Python\Python312\site-packages\sqlparse\sql.py", line 355, in get_name
    return self.get_alias() or self.get_real_name()
           ^^^^^^^^^^^^^^^^
  File "C:\Users\subhi\AppData\Roaming\Python\Python312\site-packages\sqlparse\sql.py", line 339, in get_alias
    kw_idx, kw = self.token_next_by(m=(T.Keyword, 'AS'))
                 ^^^^^^^^^^^^^^^^^^^^^^^^^^^^^^^^^^^^^^^
  File "C:\Users\subhi\AppData\Roaming\Python\Python312\site-packages\sqlparse\sql.py", line 244, in token_next_by
    return self._token_matching(funcs, idx, end)
           ^^^^^^^^^^^^^^^^^^^^^^^^^^^^^^^^^^^^^
  File "C:\Users\subhi\AppData\Roaming\Python\Python312\site-packages\sqlparse\sql.py", line 223, in _token_matching
    if func(token):
       ^^^^^^^^^^^
  File "C:\Users\subhi\AppData\Roaming\Python\Python312\site-packages\sqlparse\sql.py", line 242, in <lambda>
    funcs = lambda tk: imt(tk, i, m, t)
                       ^^^^^^^^^^^^^^^^
  File "C:\Users\subhi\AppData\Roaming\Python\Python312\site-packages\sqlparse\utils.py", line 98, in imt
    elif mpatterns and any(token.match(*pattern) for pattern in mpatterns):
                       ^^^^^^^^^^^^^^^^^^^^^^^^^^^^^^^^^^^^^^^^^^^^^^^^^^^
  File "C:\Users\subhi\AppData\Roaming\Python\Python312\site-packages\sqlparse\utils.py", line 98, in <genexpr>
    elif mpatterns and any(token.match(*pattern) for pattern in mpatterns):
                           ^^^^^^^^^^^^^^^^^^^^^
RecursionError: maximum recursion depth exceeded

The above exception was the direct cause of the following exception:

Traceback (most recent call last):
  File "C:\Users\subhi\AppData\Roaming\Python\Python312\site-packages\djongo\cursor.py", line 76, in fetchone
    return self.result.next()
           ^^^^^^^^^^^^^^^^^^
  File "C:\Users\subhi\AppData\Roaming\Python\Python312\site-packages\djongo\sql2mongo\query.py", line 797, in __next__
    result = next(self._result_generator)
             ^^^^^^^^^^^^^^^^^^^^^^^^^^^^
  File "C:\Users\subhi\AppData\Roaming\Python\Python312\site-packages\djongo\sql2mongo\query.py", line 830, in __iter__
    raise exe from e
djongo.exceptions.SQLDecodeError: 

	Keyword: FAILED SQL: SELECT %(0)s AS "a" FROM "newsapp_user" WHERE "newsapp_user"."email" = %(1)s LIMIT 1
Params: (1, 'subhitcha.s@gmail.com')
Version: 1.3.6
	Sub SQL: None
	FAILED SQL: None
	Params: None
	Version: None

The above exception was the direct cause of the following exception:

Traceback (most recent call last):
  File "C:\Users\subhi\AppData\Roaming\Python\Python312\site-packages\django\db\utils.py", line 98, in inner
    return func(*args, **kwargs)
           ^^^^^^^^^^^^^^^^^^^^^
  File "C:\Users\subhi\AppData\Roaming\Python\Python312\site-packages\djongo\cursor.py", line 81, in fetchone
    raise db_exe from e
djongo.database.DatabaseError

The above exception was the direct cause of the following exception:

Traceback (most recent call last):
  File "C:\Users\subhi\AppData\Roaming\Python\Python312\site-packages\django\core\handlers\exception.py", line 56, in inner
    response = get_response(request)
               ^^^^^^^^^^^^^^^^^^^^^
  File "C:\Users\subhi\AppData\Roaming\Python\Python312\site-packages\django\core\handlers\base.py", line 197, in _get_response
    response = wrapped_callback(request, *callback_args, **callback_kwargs)
               ^^^^^^^^^^^^^^^^^^^^^^^^^^^^^^^^^^^^^^^^^^^^^^^^^^^^^^^^^^^^
  File "C:\Users\subhi\AppData\Roaming\Python\Python312\site-packages\django\views\decorators\csrf.py", line 55, in wrapped_view
    return view_func(*args, **kwargs)
           ^^^^^^^^^^^^^^^^^^^^^^^^^^
  File "C:\Users\subhi\AppData\Roaming\Python\Python312\site-packages\django\views\generic\base.py", line 103, in view
    return self.dispatch(request, *args, **kwargs)
           ^^^^^^^^^^^^^^^^^^^^^^^^^^^^^^^^^^^^^^^
  File "C:\Users\subhi\AppData\Roaming\Python\Python312\site-packages\rest_framework\views.py", line 509, in dispatch
    response = self.handle_exception(exc)
               ^^^^^^^^^^^^^^^^^^^^^^^^^^
  File "C:\Users\subhi\AppData\Roaming\Python\Python312\site-packages\rest_framework\views.py", line 469, in handle_exception
    self.raise_uncaught_exception(exc)
  File "C:\Users\subhi\AppData\Roaming\Python\Python312\site-packages\rest_framework\views.py", line 480, in raise_uncaught_exception
    raise exc
  File "C:\Users\subhi\AppData\Roaming\Python\Python312\site-packages\rest_framework\views.py", line 506, in dispatch
    response = handler(request, *args, **kwargs)
               ^^^^^^^^^^^^^^^^^^^^^^^^^^^^^^^^^
  File "C:\Users\subhi\AppData\Roaming\Python\Python312\site-packages\rest_framework\decorators.py", line 50, in handler
    return func(*args, **kwargs)
           ^^^^^^^^^^^^^^^^^^^^^
  File "C:\cit\6th sem\cloudcat\news_backend\newsapp\views.py", line 91, in register_user
    if User.objects.filter(email=data.get('email')).exists():
       ^^^^^^^^^^^^^^^^^^^^^^^^^^^^^^^^^^^^^^^^^^^^^^^^^^^^^
  File "C:\Users\subhi\AppData\Roaming\Python\Python312\site-packages\django\db\models\query.py", line 1226, in exists
    return self.query.has_results(using=self.db)
           ^^^^^^^^^^^^^^^^^^^^^^^^^^^^^^^^^^^^^
  File "C:\Users\subhi\AppData\Roaming\Python\Python312\site-packages\django\db\models\sql\query.py", line 592, in has_results
    return compiler.has_results()
           ^^^^^^^^^^^^^^^^^^^^^^
  File "C:\Users\subhi\AppData\Roaming\Python\Python312\site-packages\django\db\models\sql\compiler.py", line 1366, in has_results
    return bool(self.execute_sql(SINGLE))
                ^^^^^^^^^^^^^^^^^^^^^^^^
  File "C:\Users\subhi\AppData\Roaming\Python\Python312\site-packages\django\db\models\sql\compiler.py", line 1409, in execute_sql
    val = cursor.fetchone()
          ^^^^^^^^^^^^^^^^^
  File "C:\Users\subhi\AppData\Roaming\Python\Python312\site-packages\django\db\utils.py", line 97, in inner
    with self:
  File "C:\Users\subhi\AppData\Roaming\Python\Python312\site-packages\django\db\utils.py", line 91, in __exit__
    raise dj_exc_value.with_traceback(traceback) from exc_value
  File "C:\Users\subhi\AppData\Roaming\Python\Python312\site-packages\django\db\utils.py", line 98, in inner
    return func(*args, **kwargs)
           ^^^^^^^^^^^^^^^^^^^^^
  File "C:\Users\subhi\AppData\Roaming\Python\Python312\site-packages\djongo\cursor.py", line 81, in fetchone
    raise db_exe from e
django.db.utils.DatabaseError
"POST /api/news/signup/ HTTP/1.1" 500 3816902
Internal Server Error: /api/news/signup/
Traceback (most recent call last):
  File "C:\Users\subhi\AppData\Roaming\Python\Python312\site-packages\djongo\sql2mongo\query.py", line 808, in __iter__
    yield from iter(self._query)
  File "C:\Users\subhi\AppData\Roaming\Python\Python312\site-packages\djongo\sql2mongo\query.py", line 167, in __iter__
    yield self._align_results(doc)
          ^^^^^^^^^^^^^^^^^^^^^^^^
  File "C:\Users\subhi\AppData\Roaming\Python\Python312\site-packages\djongo\sql2mongo\query.py", line 269, in _align_results
    if selected.table == self.left_table:
       ^^^^^^^^^^^^^^
  File "C:\Users\subhi\AppData\Roaming\Python\Python312\site-packages\djongo\sql2mongo\sql_tokens.py", line 133, in table
    return alias2token[name].table
           ^^^^^^^^^^^^^^^^^^^^^^^
  File "C:\Users\subhi\AppData\Roaming\Python\Python312\site-packages\djongo\sql2mongo\sql_tokens.py", line 133, in table
    return alias2token[name].table
           ^^^^^^^^^^^^^^^^^^^^^^^
  File "C:\Users\subhi\AppData\Roaming\Python\Python312\site-packages\djongo\sql2mongo\sql_tokens.py", line 133, in table
    return alias2token[name].table
           ^^^^^^^^^^^^^^^^^^^^^^^
  [Previous line repeated 941 more times]
  File "C:\Users\subhi\AppData\Roaming\Python\Python312\site-packages\djongo\sql2mongo\sql_tokens.py", line 130, in table
    name = self.given_table
           ^^^^^^^^^^^^^^^^
  File "C:\Users\subhi\AppData\Roaming\Python\Python312\site-packages\djongo\sql2mongo\sql_tokens.py", line 141, in given_table
    name = self._token.get_real_name()
           ^^^^^^^^^^^^^^^^^^^^^^^^^^^
  File "C:\Users\subhi\AppData\Roaming\Python\Python312\site-packages\sqlparse\sql.py", line 361, in get_real_name
    return self._get_first_name(dot_idx)
           ^^^^^^^^^^^^^^^^^^^^^^^^^^^^^
  File "C:\Users\subhi\AppData\Roaming\Python\Python312\site-packages\sqlparse\sql.py", line 386, in _get_first_name
    return token.get_name()
           ^^^^^^^^^^^^^^^^
  File "C:\Users\subhi\AppData\Roaming\Python\Python312\site-packages\sqlparse\sql.py", line 355, in get_name
    return self.get_alias() or self.get_real_name()
           ^^^^^^^^^^^^^^^^
  File "C:\Users\subhi\AppData\Roaming\Python\Python312\site-packages\sqlparse\sql.py", line 339, in get_alias
    kw_idx, kw = self.token_next_by(m=(T.Keyword, 'AS'))
                 ^^^^^^^^^^^^^^^^^^^^^^^^^^^^^^^^^^^^^^^
  File "C:\Users\subhi\AppData\Roaming\Python\Python312\site-packages\sqlparse\sql.py", line 244, in token_next_by
    return self._token_matching(funcs, idx, end)
           ^^^^^^^^^^^^^^^^^^^^^^^^^^^^^^^^^^^^^
  File "C:\Users\subhi\AppData\Roaming\Python\Python312\site-packages\sqlparse\sql.py", line 223, in _token_matching
    if func(token):
       ^^^^^^^^^^^
  File "C:\Users\subhi\AppData\Roaming\Python\Python312\site-packages\sqlparse\sql.py", line 242, in <lambda>
    funcs = lambda tk: imt(tk, i, m, t)
                       ^^^^^^^^^^^^^^^^
  File "C:\Users\subhi\AppData\Roaming\Python\Python312\site-packages\sqlparse\utils.py", line 98, in imt
    elif mpatterns and any(token.match(*pattern) for pattern in mpatterns):
                       ^^^^^^^^^^^^^^^^^^^^^^^^^^^^^^^^^^^^^^^^^^^^^^^^^^^
  File "C:\Users\subhi\AppData\Roaming\Python\Python312\site-packages\sqlparse\utils.py", line 98, in <genexpr>
    elif mpatterns and any(token.match(*pattern) for pattern in mpatterns):
                           ^^^^^^^^^^^^^^^^^^^^^
RecursionError: maximum recursion depth exceeded

The above exception was the direct cause of the following exception:

Traceback (most recent call last):
  File "C:\Users\subhi\AppData\Roaming\Python\Python312\site-packages\djongo\cursor.py", line 76, in fetchone
    return self.result.next()
           ^^^^^^^^^^^^^^^^^^
  File "C:\Users\subhi\AppData\Roaming\Python\Python312\site-packages\djongo\sql2mongo\query.py", line 797, in __next__
    result = next(self._result_generator)
             ^^^^^^^^^^^^^^^^^^^^^^^^^^^^
  File "C:\Users\subhi\AppData\Roaming\Python\Python312\site-packages\djongo\sql2mongo\query.py", line 830, in __iter__
    raise exe from e
djongo.exceptions.SQLDecodeError: 

	Keyword: FAILED SQL: SELECT %(0)s AS "a" FROM "newsapp_user" WHERE "newsapp_user"."email" = %(1)s LIMIT 1
Params: (1, 'subhitcha.s@gmail.com')
Version: 1.3.6
	Sub SQL: None
	FAILED SQL: None
	Params: None
	Version: None

The above exception was the direct cause of the following exception:

Traceback (most recent call last):
  File "C:\Users\subhi\AppData\Roaming\Python\Python312\site-packages\django\db\utils.py", line 98, in inner
    return func(*args, **kwargs)
           ^^^^^^^^^^^^^^^^^^^^^
  File "C:\Users\subhi\AppData\Roaming\Python\Python312\site-packages\djongo\cursor.py", line 81, in fetchone
    raise db_exe from e
djongo.database.DatabaseError

The above exception was the direct cause of the following exception:

Traceback (most recent call last):
  File "C:\Users\subhi\AppData\Roaming\Python\Python312\site-packages\django\core\handlers\exception.py", line 56, in inner
    response = get_response(request)
               ^^^^^^^^^^^^^^^^^^^^^
  File "C:\Users\subhi\AppData\Roaming\Python\Python312\site-packages\django\core\handlers\base.py", line 197, in _get_response
    response = wrapped_callback(request, *callback_args, **callback_kwargs)
               ^^^^^^^^^^^^^^^^^^^^^^^^^^^^^^^^^^^^^^^^^^^^^^^^^^^^^^^^^^^^
  File "C:\Users\subhi\AppData\Roaming\Python\Python312\site-packages\django\views\decorators\csrf.py", line 55, in wrapped_view
    return view_func(*args, **kwargs)
           ^^^^^^^^^^^^^^^^^^^^^^^^^^
  File "C:\Users\subhi\AppData\Roaming\Python\Python312\site-packages\django\views\generic\base.py", line 103, in view
    return self.dispatch(request, *args, **kwargs)
           ^^^^^^^^^^^^^^^^^^^^^^^^^^^^^^^^^^^^^^^
  File "C:\Users\subhi\AppData\Roaming\Python\Python312\site-packages\rest_framework\views.py", line 509, in dispatch
    response = self.handle_exception(exc)
               ^^^^^^^^^^^^^^^^^^^^^^^^^^
  File "C:\Users\subhi\AppData\Roaming\Python\Python312\site-packages\rest_framework\views.py", line 469, in handle_exception
    self.raise_uncaught_exception(exc)
  File "C:\Users\subhi\AppData\Roaming\Python\Python312\site-packages\rest_framework\views.py", line 480, in raise_uncaught_exception
    raise exc
  File "C:\Users\subhi\AppData\Roaming\Python\Python312\site-packages\rest_framework\views.py", line 506, in dispatch
    response = handler(request, *args, **kwargs)
               ^^^^^^^^^^^^^^^^^^^^^^^^^^^^^^^^^
  File "C:\Users\subhi\AppData\Roaming\Python\Python312\site-packages\rest_framework\decorators.py", line 50, in handler
    return func(*args, **kwargs)
           ^^^^^^^^^^^^^^^^^^^^^
  File "C:\cit\6th sem\cloudcat\news_backend\newsapp\views.py", line 91, in register_user
    if User.objects.filter(email=data.get('email')).exists():
       ^^^^^^^^^^^^^^^^^^^^^^^^^^^^^^^^^^^^^^^^^^^^^^^^^^^^^
  File "C:\Users\subhi\AppData\Roaming\Python\Python312\site-packages\django\db\models\query.py", line 1226, in exists
    return self.query.has_results(using=self.db)
           ^^^^^^^^^^^^^^^^^^^^^^^^^^^^^^^^^^^^^
  File "C:\Users\subhi\AppData\Roaming\Python\Python312\site-packages\django\db\models\sql\query.py", line 592, in has_results
    return compiler.has_results()
           ^^^^^^^^^^^^^^^^^^^^^^
  File "C:\Users\subhi\AppData\Roaming\Python\Python312\site-packages\django\db\models\sql\compiler.py", line 1366, in has_results
    return bool(self.execute_sql(SINGLE))
                ^^^^^^^^^^^^^^^^^^^^^^^^
  File "C:\Users\subhi\AppData\Roaming\Python\Python312\site-packages\django\db\models\sql\compiler.py", line 1409, in execute_sql
    val = cursor.fetchone()
          ^^^^^^^^^^^^^^^^^
  File "C:\Users\subhi\AppData\Roaming\Python\Python312\site-packages\django\db\utils.py", line 97, in inner
    with self:
  File "C:\Users\subhi\AppData\Roaming\Python\Python312\site-packages\django\db\utils.py", line 91, in __exit__
    raise dj_exc_value.with_traceback(traceback) from exc_value
  File "C:\Users\subhi\AppData\Roaming\Python\Python312\site-packages\django\db\utils.py", line 98, in inner
    return func(*args, **kwargs)
           ^^^^^^^^^^^^^^^^^^^^^
  File "C:\Users\subhi\AppData\Roaming\Python\Python312\site-packages\djongo\cursor.py", line 81, in fetchone
    raise db_exe from e
django.db.utils.DatabaseError
"POST /api/news/signup/ HTTP/1.1" 500 3816902
Internal Server Error: /api/news/signup/
Traceback (most recent call last):
  File "C:\Users\subhi\AppData\Roaming\Python\Python312\site-packages\djongo\sql2mongo\query.py", line 808, in __iter__
    yield from iter(self._query)
  File "C:\Users\subhi\AppData\Roaming\Python\Python312\site-packages\djongo\sql2mongo\query.py", line 167, in __iter__
    yield self._align_results(doc)
          ^^^^^^^^^^^^^^^^^^^^^^^^
  File "C:\Users\subhi\AppData\Roaming\Python\Python312\site-packages\djongo\sql2mongo\query.py", line 269, in _align_results
    if selected.table == self.left_table:
       ^^^^^^^^^^^^^^
  File "C:\Users\subhi\AppData\Roaming\Python\Python312\site-packages\djongo\sql2mongo\sql_tokens.py", line 133, in table
    return alias2token[name].table
           ^^^^^^^^^^^^^^^^^^^^^^^
  File "C:\Users\subhi\AppData\Roaming\Python\Python312\site-packages\djongo\sql2mongo\sql_tokens.py", line 133, in table
    return alias2token[name].table
           ^^^^^^^^^^^^^^^^^^^^^^^
  File "C:\Users\subhi\AppData\Roaming\Python\Python312\site-packages\djongo\sql2mongo\sql_tokens.py", line 133, in table
    return alias2token[name].table
           ^^^^^^^^^^^^^^^^^^^^^^^
  [Previous line repeated 941 more times]
  File "C:\Users\subhi\AppData\Roaming\Python\Python312\site-packages\djongo\sql2mongo\sql_tokens.py", line 130, in table
    name = self.given_table
           ^^^^^^^^^^^^^^^^
  File "C:\Users\subhi\AppData\Roaming\Python\Python312\site-packages\djongo\sql2mongo\sql_tokens.py", line 141, in given_table
    name = self._token.get_real_name()
           ^^^^^^^^^^^^^^^^^^^^^^^^^^^
  File "C:\Users\subhi\AppData\Roaming\Python\Python312\site-packages\sqlparse\sql.py", line 361, in get_real_name
    return self._get_first_name(dot_idx)
           ^^^^^^^^^^^^^^^^^^^^^^^^^^^^^
  File "C:\Users\subhi\AppData\Roaming\Python\Python312\site-packages\sqlparse\sql.py", line 386, in _get_first_name
    return token.get_name()
           ^^^^^^^^^^^^^^^^
  File "C:\Users\subhi\AppData\Roaming\Python\Python312\site-packages\sqlparse\sql.py", line 355, in get_name
    return self.get_alias() or self.get_real_name()
           ^^^^^^^^^^^^^^^^
  File "C:\Users\subhi\AppData\Roaming\Python\Python312\site-packages\sqlparse\sql.py", line 339, in get_alias
    kw_idx, kw = self.token_next_by(m=(T.Keyword, 'AS'))
                 ^^^^^^^^^^^^^^^^^^^^^^^^^^^^^^^^^^^^^^^
  File "C:\Users\subhi\AppData\Roaming\Python\Python312\site-packages\sqlparse\sql.py", line 244, in token_next_by
    return self._token_matching(funcs, idx, end)
           ^^^^^^^^^^^^^^^^^^^^^^^^^^^^^^^^^^^^^
  File "C:\Users\subhi\AppData\Roaming\Python\Python312\site-packages\sqlparse\sql.py", line 223, in _token_matching
    if func(token):
       ^^^^^^^^^^^
  File "C:\Users\subhi\AppData\Roaming\Python\Python312\site-packages\sqlparse\sql.py", line 242, in <lambda>
    funcs = lambda tk: imt(tk, i, m, t)
                       ^^^^^^^^^^^^^^^^
  File "C:\Users\subhi\AppData\Roaming\Python\Python312\site-packages\sqlparse\utils.py", line 98, in imt
    elif mpatterns and any(token.match(*pattern) for pattern in mpatterns):
                       ^^^^^^^^^^^^^^^^^^^^^^^^^^^^^^^^^^^^^^^^^^^^^^^^^^^
  File "C:\Users\subhi\AppData\Roaming\Python\Python312\site-packages\sqlparse\utils.py", line 98, in <genexpr>
    elif mpatterns and any(token.match(*pattern) for pattern in mpatterns):
                           ^^^^^^^^^^^^^^^^^^^^^
RecursionError: maximum recursion depth exceeded

The above exception was the direct cause of the following exception:

Traceback (most recent call last):
  File "C:\Users\subhi\AppData\Roaming\Python\Python312\site-packages\djongo\cursor.py", line 76, in fetchone
    return self.result.next()
           ^^^^^^^^^^^^^^^^^^
  File "C:\Users\subhi\AppData\Roaming\Python\Python312\site-packages\djongo\sql2mongo\query.py", line 797, in __next__
    result = next(self._result_generator)
             ^^^^^^^^^^^^^^^^^^^^^^^^^^^^
  File "C:\Users\subhi\AppData\Roaming\Python\Python312\site-packages\djongo\sql2mongo\query.py", line 830, in __iter__
    raise exe from e
djongo.exceptions.SQLDecodeError: 

	Keyword: FAILED SQL: SELECT %(0)s AS "a" FROM "newsapp_user" WHERE "newsapp_user"."email" = %(1)s LIMIT 1
Params: (1, 'kavya@gmail.com')
Version: 1.3.6
	Sub SQL: None
	FAILED SQL: None
	Params: None
	Version: None

The above exception was the direct cause of the following exception:

Traceback (most recent call last):
  File "C:\Users\subhi\AppData\Roaming\Python\Python312\site-packages\django\db\utils.py", line 98, in inner
    return func(*args, **kwargs)
           ^^^^^^^^^^^^^^^^^^^^^
  File "C:\Users\subhi\AppData\Roaming\Python\Python312\site-packages\djongo\cursor.py", line 81, in fetchone
    raise db_exe from e
djongo.database.DatabaseError

The above exception was the direct cause of the following exception:

Traceback (most recent call last):
  File "C:\Users\subhi\AppData\Roaming\Python\Python312\site-packages\django\core\handlers\exception.py", line 56, in inner
    response = get_response(request)
               ^^^^^^^^^^^^^^^^^^^^^
  File "C:\Users\subhi\AppData\Roaming\Python\Python312\site-packages\django\core\handlers\base.py", line 197, in _get_response
    response = wrapped_callback(request, *callback_args, **callback_kwargs)
               ^^^^^^^^^^^^^^^^^^^^^^^^^^^^^^^^^^^^^^^^^^^^^^^^^^^^^^^^^^^^
  File "C:\Users\subhi\AppData\Roaming\Python\Python312\site-packages\django\views\decorators\csrf.py", line 55, in wrapped_view
    return view_func(*args, **kwargs)
           ^^^^^^^^^^^^^^^^^^^^^^^^^^
  File "C:\Users\subhi\AppData\Roaming\Python\Python312\site-packages\django\views\generic\base.py", line 103, in view
    return self.dispatch(request, *args, **kwargs)
           ^^^^^^^^^^^^^^^^^^^^^^^^^^^^^^^^^^^^^^^
  File "C:\Users\subhi\AppData\Roaming\Python\Python312\site-packages\rest_framework\views.py", line 509, in dispatch
    response = self.handle_exception(exc)
               ^^^^^^^^^^^^^^^^^^^^^^^^^^
  File "C:\Users\subhi\AppData\Roaming\Python\Python312\site-packages\rest_framework\views.py", line 469, in handle_exception
    self.raise_uncaught_exception(exc)
  File "C:\Users\subhi\AppData\Roaming\Python\Python312\site-packages\rest_framework\views.py", line 480, in raise_uncaught_exception
    raise exc
  File "C:\Users\subhi\AppData\Roaming\Python\Python312\site-packages\rest_framework\views.py", line 506, in dispatch
    response = handler(request, *args, **kwargs)
               ^^^^^^^^^^^^^^^^^^^^^^^^^^^^^^^^^
  File "C:\Users\subhi\AppData\Roaming\Python\Python312\site-packages\rest_framework\decorators.py", line 50, in handler
    return func(*args, **kwargs)
           ^^^^^^^^^^^^^^^^^^^^^
  File "C:\cit\6th sem\cloudcat\news_backend\newsapp\views.py", line 91, in register_user
    if User.objects.filter(email=data.get('email')).exists():
       ^^^^^^^^^^^^^^^^^^^^^^^^^^^^^^^^^^^^^^^^^^^^^^^^^^^^^
  File "C:\Users\subhi\AppData\Roaming\Python\Python312\site-packages\django\db\models\query.py", line 1226, in exists
    return self.query.has_results(using=self.db)
           ^^^^^^^^^^^^^^^^^^^^^^^^^^^^^^^^^^^^^
  File "C:\Users\subhi\AppData\Roaming\Python\Python312\site-packages\django\db\models\sql\query.py", line 592, in has_results
    return compiler.has_results()
           ^^^^^^^^^^^^^^^^^^^^^^
  File "C:\Users\subhi\AppData\Roaming\Python\Python312\site-packages\django\db\models\sql\compiler.py", line 1366, in has_results
    return bool(self.execute_sql(SINGLE))
                ^^^^^^^^^^^^^^^^^^^^^^^^
  File "C:\Users\subhi\AppData\Roaming\Python\Python312\site-packages\django\db\models\sql\compiler.py", line 1409, in execute_sql
    val = cursor.fetchone()
          ^^^^^^^^^^^^^^^^^
  File "C:\Users\subhi\AppData\Roaming\Python\Python312\site-packages\django\db\utils.py", line 97, in inner
    with self:
  File "C:\Users\subhi\AppData\Roaming\Python\Python312\site-packages\django\db\utils.py", line 91, in __exit__
    raise dj_exc_value.with_traceback(traceback) from exc_value
  File "C:\Users\subhi\AppData\Roaming\Python\Python312\site-packages\django\db\utils.py", line 98, in inner
    return func(*args, **kwargs)
           ^^^^^^^^^^^^^^^^^^^^^
  File "C:\Users\subhi\AppData\Roaming\Python\Python312\site-packages\djongo\cursor.py", line 81, in fetchone
    raise db_exe from e
django.db.utils.DatabaseError
"POST /api/news/signup/ HTTP/1.1" 500 3816857
Internal Server Error: /admin/
Traceback (most recent call last):
  File "C:\Users\subhi\AppData\Local\Programs\Python\Python310\lib\site-packages\djongo\cursor.py", line 51, in execute
    self.result = Query(
  File "C:\Users\subhi\AppData\Local\Programs\Python\Python310\lib\site-packages\djongo\sql2mongo\query.py", line 781, in __init__
    self._query = self.parse()
  File "C:\Users\subhi\AppData\Local\Programs\Python\Python310\lib\site-packages\djongo\sql2mongo\query.py", line 873, in parse
    raise e
  File "C:\Users\subhi\AppData\Local\Programs\Python\Python310\lib\site-packages\djongo\sql2mongo\query.py", line 854, in parse
    return handler(self, statement)
  File "C:\Users\subhi\AppData\Local\Programs\Python\Python310\lib\site-packages\djongo\sql2mongo\query.py", line 930, in _select
    return SelectQuery(self.db, self.connection_properties, sm, self._params)
  File "C:\Users\subhi\AppData\Local\Programs\Python\Python310\lib\site-packages\djongo\sql2mongo\query.py", line 116, in __init__
    super().__init__(*args)
  File "C:\Users\subhi\AppData\Local\Programs\Python\Python310\lib\site-packages\djongo\sql2mongo\query.py", line 62, in __init__
    self.parse()
  File "C:\Users\subhi\AppData\Local\Programs\Python\Python310\lib\site-packages\djongo\sql2mongo\query.py", line 155, in parse
    raise SQLDecodeError(f'Unknown keyword: {tok}')
djongo.exceptions.SQLDecodeError: 

	Keyword: Unknown keyword: ORDER BY
	Sub SQL: None
	FAILED SQL: ('SELECT "django_admin_log"."id", "django_admin_log"."action_time", "django_admin_log"."user_id", "django_admin_log"."content_type_id", "django_admin_log"."object_id", "django_admin_log"."object_repr", "django_admin_log"."action_flag", "django_admin_log"."change_message", "auth_user"."id", "auth_user"."password", "auth_user"."last_login", "auth_user"."is_superuser", "auth_user"."username", "auth_user"."first_name", "auth_user"."last_name", "auth_user"."email", "auth_user"."is_staff", "auth_user"."is_active", "auth_user"."date_joined", "django_content_type"."id", "django_content_type"."app_label", "django_content_type"."model" FROM "django_admin_log" INNER JOIN "auth_user" ON ("django_admin_log"."user_id" = "auth_user"."id") LEFT OUTER JOIN "django_content_type" ON ("django_admin_log"."content_type_id" = "django_content_type"."id") WHERE "django_admin_log"."user_id" = %(0)s ORDER BY "django_admin_log"."action_time" DESC LIMIT 10',)
	Params: ((1,),)
	Version: 1.3.7

The above exception was the direct cause of the following exception:

Traceback (most recent call last):
  File "C:\Users\subhi\AppData\Local\Programs\Python\Python310\lib\site-packages\django\db\backends\utils.py", line 89, in _execute
    return self.cursor.execute(sql, params)
  File "C:\Users\subhi\AppData\Local\Programs\Python\Python310\lib\site-packages\djongo\cursor.py", line 59, in execute
    raise db_exe from e
djongo.database.DatabaseError

The above exception was the direct cause of the following exception:

Traceback (most recent call last):
  File "C:\Users\subhi\AppData\Local\Programs\Python\Python310\lib\site-packages\django\core\handlers\exception.py", line 55, in inner
    response = get_response(request)
  File "C:\Users\subhi\AppData\Local\Programs\Python\Python310\lib\site-packages\django\core\handlers\base.py", line 220, in _get_response
    response = response.render()
  File "C:\Users\subhi\AppData\Local\Programs\Python\Python310\lib\site-packages\django\template\response.py", line 111, in render
    self.content = self.rendered_content
  File "C:\Users\subhi\AppData\Local\Programs\Python\Python310\lib\site-packages\django\template\response.py", line 89, in rendered_content
    return template.render(context, self._request)
  File "C:\Users\subhi\AppData\Local\Programs\Python\Python310\lib\site-packages\django\template\backends\django.py", line 61, in render
    return self.template.render(context)
  File "C:\Users\subhi\AppData\Local\Programs\Python\Python310\lib\site-packages\django\template\base.py", line 175, in render
    return self._render(context)
  File "C:\Users\subhi\AppData\Local\Programs\Python\Python310\lib\site-packages\django\template\base.py", line 167, in _render
    return self.nodelist.render(context)
  File "C:\Users\subhi\AppData\Local\Programs\Python\Python310\lib\site-packages\django\template\base.py", line 1005, in render
    return SafeString("".join([node.render_annotated(context) for node in self]))
  File "C:\Users\subhi\AppData\Local\Programs\Python\Python310\lib\site-packages\django\template\base.py", line 1005, in <listcomp>
    return SafeString("".join([node.render_annotated(context) for node in self]))
  File "C:\Users\subhi\AppData\Local\Programs\Python\Python310\lib\site-packages\django\template\base.py", line 966, in render_annotated
    return self.render(context)
  File "C:\Users\subhi\AppData\Local\Programs\Python\Python310\lib\site-packages\django\template\loader_tags.py", line 157, in render
    return compiled_parent._render(context)
  File "C:\Users\subhi\AppData\Local\Programs\Python\Python310\lib\site-packages\django\template\base.py", line 167, in _render
    return self.nodelist.render(context)
  File "C:\Users\subhi\AppData\Local\Programs\Python\Python310\lib\site-packages\django\template\base.py", line 1005, in render
    return SafeString("".join([node.render_annotated(context) for node in self]))
  File "C:\Users\subhi\AppData\Local\Programs\Python\Python310\lib\site-packages\django\template\base.py", line 1005, in <listcomp>
    return SafeString("".join([node.render_annotated(context) for node in self]))
  File "C:\Users\subhi\AppData\Local\Programs\Python\Python310\lib\site-packages\django\template\base.py", line 966, in render_annotated
    return self.render(context)
  File "C:\Users\subhi\AppData\Local\Programs\Python\Python310\lib\site-packages\django\template\loader_tags.py", line 157, in render
    return compiled_parent._render(context)
  File "C:\Users\subhi\AppData\Local\Programs\Python\Python310\lib\site-packages\django\template\base.py", line 167, in _render
    return self.nodelist.render(context)
  File "C:\Users\subhi\AppData\Local\Programs\Python\Python310\lib\site-packages\django\template\base.py", line 1005, in render
    return SafeString("".join([node.render_annotated(context) for node in self]))
  File "C:\Users\subhi\AppData\Local\Programs\Python\Python310\lib\site-packages\django\template\base.py", line 1005, in <listcomp>
    return SafeString("".join([node.render_annotated(context) for node in self]))
  File "C:\Users\subhi\AppData\Local\Programs\Python\Python310\lib\site-packages\django\template\base.py", line 966, in render_annotated
    return self.render(context)
  File "C:\Users\subhi\AppData\Local\Programs\Python\Python310\lib\site-packages\django\template\loader_tags.py", line 63, in render
    result = block.nodelist.render(context)
  File "C:\Users\subhi\AppData\Local\Programs\Python\Python310\lib\site-packages\django\template\base.py", line 1005, in render
    return SafeString("".join([node.render_annotated(context) for node in self]))
  File "C:\Users\subhi\AppData\Local\Programs\Python\Python310\lib\site-packages\django\template\base.py", line 1005, in <listcomp>
    return SafeString("".join([node.render_annotated(context) for node in self]))
  File "C:\Users\subhi\AppData\Local\Programs\Python\Python310\lib\site-packages\django\template\base.py", line 966, in render_annotated
    return self.render(context)
  File "C:\Users\subhi\AppData\Local\Programs\Python\Python310\lib\site-packages\django\template\defaulttags.py", line 321, in render
    return nodelist.render(context)
  File "C:\Users\subhi\AppData\Local\Programs\Python\Python310\lib\site-packages\django\template\base.py", line 1005, in render
    return SafeString("".join([node.render_annotated(context) for node in self]))
  File "C:\Users\subhi\AppData\Local\Programs\Python\Python310\lib\site-packages\django\template\base.py", line 1005, in <listcomp>
    return SafeString("".join([node.render_annotated(context) for node in self]))
  File "C:\Users\subhi\AppData\Local\Programs\Python\Python310\lib\site-packages\django\template\base.py", line 966, in render_annotated
    return self.render(context)
  File "C:\Users\subhi\AppData\Local\Programs\Python\Python310\lib\site-packages\django\template\defaulttags.py", line 194, in render
    len_values = len(values)
  File "C:\Users\subhi\AppData\Local\Programs\Python\Python310\lib\site-packages\django\db\models\query.py", line 380, in __len__
    self._fetch_all()
  File "C:\Users\subhi\AppData\Local\Programs\Python\Python310\lib\site-packages\django\db\models\query.py", line 1881, in _fetch_all
    self._result_cache = list(self._iterable_class(self))
  File "C:\Users\subhi\AppData\Local\Programs\Python\Python310\lib\site-packages\django\db\models\query.py", line 91, in __iter__
    results = compiler.execute_sql(
  File "C:\Users\subhi\AppData\Local\Programs\Python\Python310\lib\site-packages\django\db\models\sql\compiler.py", line 1560, in execute_sql
    cursor.execute(sql, params)
  File "C:\Users\subhi\AppData\Local\Programs\Python\Python310\lib\site-packages\django\db\backends\utils.py", line 102, in execute
    return super().execute(sql, params)
  File "C:\Users\subhi\AppData\Local\Programs\Python\Python310\lib\site-packages\django\db\backends\utils.py", line 67, in execute
    return self._execute_with_wrappers(
  File "C:\Users\subhi\AppData\Local\Programs\Python\Python310\lib\site-packages\django\db\backends\utils.py", line 80, in _execute_with_wrappers
    return executor(sql, params, many, context)
  File "C:\Users\subhi\AppData\Local\Programs\Python\Python310\lib\site-packages\django\db\backends\utils.py", line 84, in _execute
    with self.db.wrap_database_errors:
  File "C:\Users\subhi\AppData\Local\Programs\Python\Python310\lib\site-packages\django\db\utils.py", line 91, in __exit__
    raise dj_exc_value.with_traceback(traceback) from exc_value
  File "C:\Users\subhi\AppData\Local\Programs\Python\Python310\lib\site-packages\django\db\backends\utils.py", line 89, in _execute
    return self.cursor.execute(sql, params)
  File "C:\Users\subhi\AppData\Local\Programs\Python\Python310\lib\site-packages\djongo\cursor.py", line 59, in execute
    raise db_exe from e
django.db.utils.DatabaseError
"GET /admin/ HTTP/1.1" 500 491788
Internal Server Error: /admin/
Traceback (most recent call last):
  File "C:\Users\subhi\AppData\Local\Programs\Python\Python310\lib\site-packages\djongo\cursor.py", line 51, in execute
    self.result = Query(
  File "C:\Users\subhi\AppData\Local\Programs\Python\Python310\lib\site-packages\djongo\sql2mongo\query.py", line 781, in __init__
    self._query = self.parse()
  File "C:\Users\subhi\AppData\Local\Programs\Python\Python310\lib\site-packages\djongo\sql2mongo\query.py", line 873, in parse
    raise e
  File "C:\Users\subhi\AppData\Local\Programs\Python\Python310\lib\site-packages\djongo\sql2mongo\query.py", line 854, in parse
    return handler(self, statement)
  File "C:\Users\subhi\AppData\Local\Programs\Python\Python310\lib\site-packages\djongo\sql2mongo\query.py", line 930, in _select
    return SelectQuery(self.db, self.connection_properties, sm, self._params)
  File "C:\Users\subhi\AppData\Local\Programs\Python\Python310\lib\site-packages\djongo\sql2mongo\query.py", line 116, in __init__
    super().__init__(*args)
  File "C:\Users\subhi\AppData\Local\Programs\Python\Python310\lib\site-packages\djongo\sql2mongo\query.py", line 62, in __init__
    self.parse()
  File "C:\Users\subhi\AppData\Local\Programs\Python\Python310\lib\site-packages\djongo\sql2mongo\query.py", line 155, in parse
    raise SQLDecodeError(f'Unknown keyword: {tok}')
djongo.exceptions.SQLDecodeError: 

	Keyword: Unknown keyword: ORDER BY
	Sub SQL: None
	FAILED SQL: ('SELECT "django_admin_log"."id", "django_admin_log"."action_time", "django_admin_log"."user_id", "django_admin_log"."content_type_id", "django_admin_log"."object_id", "django_admin_log"."object_repr", "django_admin_log"."action_flag", "django_admin_log"."change_message", "auth_user"."id", "auth_user"."password", "auth_user"."last_login", "auth_user"."is_superuser", "auth_user"."username", "auth_user"."first_name", "auth_user"."last_name", "auth_user"."email", "auth_user"."is_staff", "auth_user"."is_active", "auth_user"."date_joined", "django_content_type"."id", "django_content_type"."app_label", "django_content_type"."model" FROM "django_admin_log" INNER JOIN "auth_user" ON ("django_admin_log"."user_id" = "auth_user"."id") LEFT OUTER JOIN "django_content_type" ON ("django_admin_log"."content_type_id" = "django_content_type"."id") WHERE "django_admin_log"."user_id" = %(0)s ORDER BY "django_admin_log"."action_time" DESC LIMIT 10',)
	Params: ((1,),)
	Version: 1.3.7

The above exception was the direct cause of the following exception:

Traceback (most recent call last):
  File "C:\Users\subhi\AppData\Local\Programs\Python\Python310\lib\site-packages\django\db\backends\utils.py", line 89, in _execute
    return self.cursor.execute(sql, params)
  File "C:\Users\subhi\AppData\Local\Programs\Python\Python310\lib\site-packages\djongo\cursor.py", line 59, in execute
    raise db_exe from e
djongo.database.DatabaseError

The above exception was the direct cause of the following exception:

Traceback (most recent call last):
  File "C:\Users\subhi\AppData\Local\Programs\Python\Python310\lib\site-packages\django\core\handlers\exception.py", line 55, in inner
    response = get_response(request)
  File "C:\Users\subhi\AppData\Local\Programs\Python\Python310\lib\site-packages\django\core\handlers\base.py", line 220, in _get_response
    response = response.render()
  File "C:\Users\subhi\AppData\Local\Programs\Python\Python310\lib\site-packages\django\template\response.py", line 111, in render
    self.content = self.rendered_content
  File "C:\Users\subhi\AppData\Local\Programs\Python\Python310\lib\site-packages\django\template\response.py", line 89, in rendered_content
    return template.render(context, self._request)
  File "C:\Users\subhi\AppData\Local\Programs\Python\Python310\lib\site-packages\django\template\backends\django.py", line 61, in render
    return self.template.render(context)
  File "C:\Users\subhi\AppData\Local\Programs\Python\Python310\lib\site-packages\django\template\base.py", line 175, in render
    return self._render(context)
  File "C:\Users\subhi\AppData\Local\Programs\Python\Python310\lib\site-packages\django\template\base.py", line 167, in _render
    return self.nodelist.render(context)
  File "C:\Users\subhi\AppData\Local\Programs\Python\Python310\lib\site-packages\django\template\base.py", line 1005, in render
    return SafeString("".join([node.render_annotated(context) for node in self]))
  File "C:\Users\subhi\AppData\Local\Programs\Python\Python310\lib\site-packages\django\template\base.py", line 1005, in <listcomp>
    return SafeString("".join([node.render_annotated(context) for node in self]))
  File "C:\Users\subhi\AppData\Local\Programs\Python\Python310\lib\site-packages\django\template\base.py", line 966, in render_annotated
    return self.render(context)
  File "C:\Users\subhi\AppData\Local\Programs\Python\Python310\lib\site-packages\django\template\loader_tags.py", line 157, in render
    return compiled_parent._render(context)
  File "C:\Users\subhi\AppData\Local\Programs\Python\Python310\lib\site-packages\django\template\base.py", line 167, in _render
    return self.nodelist.render(context)
  File "C:\Users\subhi\AppData\Local\Programs\Python\Python310\lib\site-packages\django\template\base.py", line 1005, in render
    return SafeString("".join([node.render_annotated(context) for node in self]))
  File "C:\Users\subhi\AppData\Local\Programs\Python\Python310\lib\site-packages\django\template\base.py", line 1005, in <listcomp>
    return SafeString("".join([node.render_annotated(context) for node in self]))
  File "C:\Users\subhi\AppData\Local\Programs\Python\Python310\lib\site-packages\django\template\base.py", line 966, in render_annotated
    return self.render(context)
  File "C:\Users\subhi\AppData\Local\Programs\Python\Python310\lib\site-packages\django\template\loader_tags.py", line 157, in render
    return compiled_parent._render(context)
  File "C:\Users\subhi\AppData\Local\Programs\Python\Python310\lib\site-packages\django\template\base.py", line 167, in _render
    return self.nodelist.render(context)
  File "C:\Users\subhi\AppData\Local\Programs\Python\Python310\lib\site-packages\django\template\base.py", line 1005, in render
    return SafeString("".join([node.render_annotated(context) for node in self]))
  File "C:\Users\subhi\AppData\Local\Programs\Python\Python310\lib\site-packages\django\template\base.py", line 1005, in <listcomp>
    return SafeString("".join([node.render_annotated(context) for node in self]))
  File "C:\Users\subhi\AppData\Local\Programs\Python\Python310\lib\site-packages\django\template\base.py", line 966, in render_annotated
    return self.render(context)
  File "C:\Users\subhi\AppData\Local\Programs\Python\Python310\lib\site-packages\django\template\loader_tags.py", line 63, in render
    result = block.nodelist.render(context)
  File "C:\Users\subhi\AppData\Local\Programs\Python\Python310\lib\site-packages\django\template\base.py", line 1005, in render
    return SafeString("".join([node.render_annotated(context) for node in self]))
  File "C:\Users\subhi\AppData\Local\Programs\Python\Python310\lib\site-packages\django\template\base.py", line 1005, in <listcomp>
    return SafeString("".join([node.render_annotated(context) for node in self]))
  File "C:\Users\subhi\AppData\Local\Programs\Python\Python310\lib\site-packages\django\template\base.py", line 966, in render_annotated
    return self.render(context)
  File "C:\Users\subhi\AppData\Local\Programs\Python\Python310\lib\site-packages\django\template\defaulttags.py", line 321, in render
    return nodelist.render(context)
  File "C:\Users\subhi\AppData\Local\Programs\Python\Python310\lib\site-packages\django\template\base.py", line 1005, in render
    return SafeString("".join([node.render_annotated(context) for node in self]))
  File "C:\Users\subhi\AppData\Local\Programs\Python\Python310\lib\site-packages\django\template\base.py", line 1005, in <listcomp>
    return SafeString("".join([node.render_annotated(context) for node in self]))
  File "C:\Users\subhi\AppData\Local\Programs\Python\Python310\lib\site-packages\django\template\base.py", line 966, in render_annotated
    return self.render(context)
  File "C:\Users\subhi\AppData\Local\Programs\Python\Python310\lib\site-packages\django\template\defaulttags.py", line 194, in render
    len_values = len(values)
  File "C:\Users\subhi\AppData\Local\Programs\Python\Python310\lib\site-packages\django\db\models\query.py", line 380, in __len__
    self._fetch_all()
  File "C:\Users\subhi\AppData\Local\Programs\Python\Python310\lib\site-packages\django\db\models\query.py", line 1881, in _fetch_all
    self._result_cache = list(self._iterable_class(self))
  File "C:\Users\subhi\AppData\Local\Programs\Python\Python310\lib\site-packages\django\db\models\query.py", line 91, in __iter__
    results = compiler.execute_sql(
  File "C:\Users\subhi\AppData\Local\Programs\Python\Python310\lib\site-packages\django\db\models\sql\compiler.py", line 1560, in execute_sql
    cursor.execute(sql, params)
  File "C:\Users\subhi\AppData\Local\Programs\Python\Python310\lib\site-packages\django\db\backends\utils.py", line 102, in execute
    return super().execute(sql, params)
  File "C:\Users\subhi\AppData\Local\Programs\Python\Python310\lib\site-packages\django\db\backends\utils.py", line 67, in execute
    return self._execute_with_wrappers(
  File "C:\Users\subhi\AppData\Local\Programs\Python\Python310\lib\site-packages\django\db\backends\utils.py", line 80, in _execute_with_wrappers
    return executor(sql, params, many, context)
  File "C:\Users\subhi\AppData\Local\Programs\Python\Python310\lib\site-packages\django\db\backends\utils.py", line 84, in _execute
    with self.db.wrap_database_errors:
  File "C:\Users\subhi\AppData\Local\Programs\Python\Python310\lib\site-packages\django\db\utils.py", line 91, in __exit__
    raise dj_exc_value.with_traceback(traceback) from exc_value
  File "C:\Users\subhi\AppData\Local\Programs\Python\Python310\lib\site-packages\django\db\backends\utils.py", line 89, in _execute
    return self.cursor.execute(sql, params)
  File "C:\Users\subhi\AppData\Local\Programs\Python\Python310\lib\site-packages\djongo\cursor.py", line 59, in execute
    raise db_exe from e
django.db.utils.DatabaseError
"GET /admin/ HTTP/1.1" 500 491514
Internal Server Error: /admin/newsapp/newsarticle/
Traceback (most recent call last):
  File "C:\Users\subhi\AppData\Local\Programs\Python\Python310\lib\site-packages\djongo\cursor.py", line 51, in execute
    self.result = Query(
  File "C:\Users\subhi\AppData\Local\Programs\Python\Python310\lib\site-packages\djongo\sql2mongo\query.py", line 781, in __init__
    self._query = self.parse()
  File "C:\Users\subhi\AppData\Local\Programs\Python\Python310\lib\site-packages\djongo\sql2mongo\query.py", line 873, in parse
    raise e
  File "C:\Users\subhi\AppData\Local\Programs\Python\Python310\lib\site-packages\djongo\sql2mongo\query.py", line 854, in parse
    return handler(self, statement)
  File "C:\Users\subhi\AppData\Local\Programs\Python\Python310\lib\site-packages\djongo\sql2mongo\query.py", line 930, in _select
    return SelectQuery(self.db, self.connection_properties, sm, self._params)
  File "C:\Users\subhi\AppData\Local\Programs\Python\Python310\lib\site-packages\djongo\sql2mongo\query.py", line 116, in __init__
    super().__init__(*args)
  File "C:\Users\subhi\AppData\Local\Programs\Python\Python310\lib\site-packages\djongo\sql2mongo\query.py", line 62, in __init__
    self.parse()
  File "C:\Users\subhi\AppData\Local\Programs\Python\Python310\lib\site-packages\djongo\sql2mongo\query.py", line 155, in parse
    raise SQLDecodeError(f'Unknown keyword: {tok}')
djongo.exceptions.SQLDecodeError: 

	Keyword: Unknown keyword: ORDER BY
	Sub SQL: None
	FAILED SQL: ('SELECT "newsapp_newsarticle"."id", "newsapp_newsarticle"."article_id", "newsapp_newsarticle"."title", "newsapp_newsarticle"."link", "newsapp_newsarticle"."keywords", "newsapp_newsarticle"."creator", "newsapp_newsarticle"."video_url", "newsapp_newsarticle"."description", "newsapp_newsarticle"."pubDate", "newsapp_newsarticle"."image_url", "newsapp_newsarticle"."source_name", "newsapp_newsarticle"."category", "newsapp_newsarticle"."country" FROM "newsapp_newsarticle" ORDER BY "newsapp_newsarticle"."id" DESC',)
	Params: ((),)
	Version: 1.3.7

The above exception was the direct cause of the following exception:

Traceback (most recent call last):
  File "C:\Users\subhi\AppData\Local\Programs\Python\Python310\lib\site-packages\django\db\backends\utils.py", line 105, in _execute
    return self.cursor.execute(sql, params)
  File "C:\Users\subhi\AppData\Local\Programs\Python\Python310\lib\site-packages\djongo\cursor.py", line 59, in execute
    raise db_exe from e
djongo.database.DatabaseError

The above exception was the direct cause of the following exception:

Traceback (most recent call last):
  File "C:\Users\subhi\AppData\Local\Programs\Python\Python310\lib\site-packages\django\core\handlers\exception.py", line 55, in inner
    response = get_response(request)
  File "C:\Users\subhi\AppData\Local\Programs\Python\Python310\lib\site-packages\django\core\handlers\base.py", line 197, in _get_response
    response = wrapped_callback(request, *callback_args, **callback_kwargs)
  File "C:\Users\subhi\AppData\Local\Programs\Python\Python310\lib\site-packages\django\contrib\admin\options.py", line 718, in wrapper
    return self.admin_site.admin_view(view)(*args, **kwargs)
  File "C:\Users\subhi\AppData\Local\Programs\Python\Python310\lib\site-packages\django\utils\decorators.py", line 188, in _view_wrapper
    result = _process_exception(request, e)
  File "C:\Users\subhi\AppData\Local\Programs\Python\Python310\lib\site-packages\django\utils\decorators.py", line 186, in _view_wrapper
    response = view_func(request, *args, **kwargs)
  File "C:\Users\subhi\AppData\Local\Programs\Python\Python310\lib\site-packages\django\views\decorators\cache.py", line 80, in _view_wrapper
    response = view_func(request, *args, **kwargs)
  File "C:\Users\subhi\AppData\Local\Programs\Python\Python310\lib\site-packages\django\contrib\admin\sites.py", line 241, in inner
    return view(request, *args, **kwargs)
  File "C:\Users\subhi\AppData\Local\Programs\Python\Python310\lib\site-packages\django\utils\decorators.py", line 48, in _wrapper
    return bound_method(*args, **kwargs)
  File "C:\Users\subhi\AppData\Local\Programs\Python\Python310\lib\site-packages\django\utils\decorators.py", line 188, in _view_wrapper
    result = _process_exception(request, e)
  File "C:\Users\subhi\AppData\Local\Programs\Python\Python310\lib\site-packages\django\utils\decorators.py", line 186, in _view_wrapper
    response = view_func(request, *args, **kwargs)
  File "C:\Users\subhi\AppData\Local\Programs\Python\Python310\lib\site-packages\django\contrib\admin\options.py", line 2140, in changelist_view
    "selection_note": _("0 of %(cnt)s selected") % {"cnt": len(cl.result_list)},
  File "C:\Users\subhi\AppData\Local\Programs\Python\Python310\lib\site-packages\django\db\models\query.py", line 382, in __len__
    self._fetch_all()
  File "C:\Users\subhi\AppData\Local\Programs\Python\Python310\lib\site-packages\django\db\models\query.py", line 1928, in _fetch_all
    self._result_cache = list(self._iterable_class(self))
  File "C:\Users\subhi\AppData\Local\Programs\Python\Python310\lib\site-packages\django\db\models\query.py", line 91, in __iter__
    results = compiler.execute_sql(
  File "C:\Users\subhi\AppData\Local\Programs\Python\Python310\lib\site-packages\django\db\models\sql\compiler.py", line 1574, in execute_sql
    cursor.execute(sql, params)
  File "C:\Users\subhi\AppData\Local\Programs\Python\Python310\lib\site-packages\django\db\backends\utils.py", line 122, in execute
    return super().execute(sql, params)
  File "C:\Users\subhi\AppData\Local\Programs\Python\Python310\lib\site-packages\django\db\backends\utils.py", line 79, in execute
    return self._execute_with_wrappers(
  File "C:\Users\subhi\AppData\Local\Programs\Python\Python310\lib\site-packages\django\db\backends\utils.py", line 92, in _execute_with_wrappers
    return executor(sql, params, many, context)
  File "C:\Users\subhi\AppData\Local\Programs\Python\Python310\lib\site-packages\django\db\backends\utils.py", line 100, in _execute
    with self.db.wrap_database_errors:
  File "C:\Users\subhi\AppData\Local\Programs\Python\Python310\lib\site-packages\django\db\utils.py", line 91, in __exit__
    raise dj_exc_value.with_traceback(traceback) from exc_value
  File "C:\Users\subhi\AppData\Local\Programs\Python\Python310\lib\site-packages\django\db\backends\utils.py", line 105, in _execute
    return self.cursor.execute(sql, params)
  File "C:\Users\subhi\AppData\Local\Programs\Python\Python310\lib\site-packages\djongo\cursor.py", line 59, in execute
    raise db_exe from e
django.db.utils.DatabaseError
"GET /admin/newsapp/newsarticle/ HTTP/1.1" 500 216489
Internal Server Error: /admin/newsapp/newsarticle/
Traceback (most recent call last):
  File "C:\Users\subhi\AppData\Local\Programs\Python\Python310\lib\site-packages\django\core\handlers\exception.py", line 47, in inner
    response = get_response(request)
  File "C:\Users\subhi\AppData\Local\Programs\Python\Python310\lib\site-packages\django\core\handlers\base.py", line 167, in _get_response
    callback, callback_args, callback_kwargs = self.resolve_request(request)
  File "C:\Users\subhi\AppData\Local\Programs\Python\Python310\lib\site-packages\django\core\handlers\base.py", line 290, in resolve_request
    resolver_match = resolver.resolve(request.path_info)
  File "C:\Users\subhi\AppData\Local\Programs\Python\Python310\lib\site-packages\django\urls\resolvers.py", line 545, in resolve
    for pattern in self.url_patterns:
  File "C:\Users\subhi\AppData\Local\Programs\Python\Python310\lib\site-packages\django\utils\functional.py", line 48, in __get__
    res = instance.__dict__[self.name] = self.func(instance)
  File "C:\Users\subhi\AppData\Local\Programs\Python\Python310\lib\site-packages\django\urls\resolvers.py", line 589, in url_patterns
    patterns = getattr(self.urlconf_module, "urlpatterns", self.urlconf_module)
  File "C:\Users\subhi\AppData\Local\Programs\Python\Python310\lib\site-packages\django\utils\functional.py", line 48, in __get__
    res = instance.__dict__[self.name] = self.func(instance)
  File "C:\Users\subhi\AppData\Local\Programs\Python\Python310\lib\site-packages\django\urls\resolvers.py", line 582, in urlconf_module
    return import_module(self.urlconf_name)
  File "C:\Users\subhi\AppData\Local\Programs\Python\Python310\lib\importlib\__init__.py", line 126, in import_module
    return _bootstrap._gcd_import(name[level:], package, level)
  File "<frozen importlib._bootstrap>", line 1050, in _gcd_import
  File "<frozen importlib._bootstrap>", line 1027, in _find_and_load
  File "<frozen importlib._bootstrap>", line 1006, in _find_and_load_unlocked
  File "<frozen importlib._bootstrap>", line 688, in _load_unlocked
  File "<frozen importlib._bootstrap_external>", line 883, in exec_module
  File "<frozen importlib._bootstrap>", line 241, in _call_with_frames_removed
  File "C:\cit\6th sem\cloudcat\news_backend\news_backend\urls.py", line 6, in <module>
    path('api/news/', include('newsapp.urls')),  # Now includes authentication
  File "C:\Users\subhi\AppData\Local\Programs\Python\Python310\lib\site-packages\django\urls\conf.py", line 34, in include
    urlconf_module = import_module(urlconf_module)
  File "C:\Users\subhi\AppData\Local\Programs\Python\Python310\lib\importlib\__init__.py", line 126, in import_module
    return _bootstrap._gcd_import(name[level:], package, level)
  File "<frozen importlib._bootstrap>", line 1050, in _gcd_import
  File "<frozen importlib._bootstrap>", line 1027, in _find_and_load
  File "<frozen importlib._bootstrap>", line 1006, in _find_and_load_unlocked
  File "<frozen importlib._bootstrap>", line 688, in _load_unlocked
  File "<frozen importlib._bootstrap_external>", line 883, in exec_module
  File "<frozen importlib._bootstrap>", line 241, in _call_with_frames_removed
  File "C:\cit\6th sem\cloudcat\news_backend\newsapp\urls.py", line 2, in <module>
    from .views import fetch_news, get_news, index, register_user, login_user  # Import auth views
  File "C:\cit\6th sem\cloudcat\news_backend\newsapp\views.py", line 3, in <module>
    from rest_framework.decorators import api_view, permission_classes
  File "C:\Users\subhi\AppData\Local\Programs\Python\Python310\lib\site-packages\rest_framework\decorators.py", line 13, in <module>
    from rest_framework.views import APIView
  File "C:\Users\subhi\AppData\Local\Programs\Python\Python310\lib\site-packages\rest_framework\views.py", line 15, in <module>
    from rest_framework.request import Request
  File "C:\Users\subhi\AppData\Local\Programs\Python\Python310\lib\site-packages\rest_framework\request.py", line 19, in <module>
    from django.utils.http import parse_header_parameters
ImportError: cannot import name 'parse_header_parameters' from 'django.utils.http' (C:\Users\subhi\AppData\Local\Programs\Python\Python310\lib\site-packages\django\utils\http.py)
Internal Server Error: /admin/newsapp/newsarticle/
Traceback (most recent call last):
  File "C:\Users\subhi\AppData\Local\Programs\Python\Python310\lib\site-packages\django\core\handlers\exception.py", line 47, in inner
    response = get_response(request)
  File "C:\Users\subhi\AppData\Local\Programs\Python\Python310\lib\site-packages\django\core\handlers\base.py", line 167, in _get_response
    callback, callback_args, callback_kwargs = self.resolve_request(request)
  File "C:\Users\subhi\AppData\Local\Programs\Python\Python310\lib\site-packages\django\core\handlers\base.py", line 290, in resolve_request
    resolver_match = resolver.resolve(request.path_info)
  File "C:\Users\subhi\AppData\Local\Programs\Python\Python310\lib\site-packages\django\urls\resolvers.py", line 545, in resolve
    for pattern in self.url_patterns:
  File "C:\Users\subhi\AppData\Local\Programs\Python\Python310\lib\site-packages\django\utils\functional.py", line 48, in __get__
    res = instance.__dict__[self.name] = self.func(instance)
  File "C:\Users\subhi\AppData\Local\Programs\Python\Python310\lib\site-packages\django\urls\resolvers.py", line 589, in url_patterns
    patterns = getattr(self.urlconf_module, "urlpatterns", self.urlconf_module)
  File "C:\Users\subhi\AppData\Local\Programs\Python\Python310\lib\site-packages\django\utils\functional.py", line 48, in __get__
    res = instance.__dict__[self.name] = self.func(instance)
  File "C:\Users\subhi\AppData\Local\Programs\Python\Python310\lib\site-packages\django\urls\resolvers.py", line 582, in urlconf_module
    return import_module(self.urlconf_name)
  File "C:\Users\subhi\AppData\Local\Programs\Python\Python310\lib\importlib\__init__.py", line 126, in import_module
    return _bootstrap._gcd_import(name[level:], package, level)
  File "<frozen importlib._bootstrap>", line 1050, in _gcd_import
  File "<frozen importlib._bootstrap>", line 1027, in _find_and_load
  File "<frozen importlib._bootstrap>", line 1006, in _find_and_load_unlocked
  File "<frozen importlib._bootstrap>", line 688, in _load_unlocked
  File "<frozen importlib._bootstrap_external>", line 883, in exec_module
  File "<frozen importlib._bootstrap>", line 241, in _call_with_frames_removed
  File "C:\cit\6th sem\cloudcat\news_backend\news_backend\urls.py", line 6, in <module>
    path('api/news/', include('newsapp.urls')),  # Now includes authentication
  File "C:\Users\subhi\AppData\Local\Programs\Python\Python310\lib\site-packages\django\urls\conf.py", line 34, in include
    urlconf_module = import_module(urlconf_module)
  File "C:\Users\subhi\AppData\Local\Programs\Python\Python310\lib\importlib\__init__.py", line 126, in import_module
    return _bootstrap._gcd_import(name[level:], package, level)
  File "<frozen importlib._bootstrap>", line 1050, in _gcd_import
  File "<frozen importlib._bootstrap>", line 1027, in _find_and_load
  File "<frozen importlib._bootstrap>", line 1006, in _find_and_load_unlocked
  File "<frozen importlib._bootstrap>", line 688, in _load_unlocked
  File "<frozen importlib._bootstrap_external>", line 883, in exec_module
  File "<frozen importlib._bootstrap>", line 241, in _call_with_frames_removed
  File "C:\cit\6th sem\cloudcat\news_backend\newsapp\urls.py", line 2, in <module>
    from .views import fetch_news, get_news, index, register_user, login_user  # Import auth views
  File "C:\cit\6th sem\cloudcat\news_backend\newsapp\views.py", line 3, in <module>
    from rest_framework.decorators import api_view, permission_classes
  File "C:\Users\subhi\AppData\Local\Programs\Python\Python310\lib\site-packages\rest_framework\decorators.py", line 13, in <module>
    from rest_framework.views import APIView
  File "C:\Users\subhi\AppData\Local\Programs\Python\Python310\lib\site-packages\rest_framework\views.py", line 15, in <module>
    from rest_framework.request import Request
  File "C:\Users\subhi\AppData\Local\Programs\Python\Python310\lib\site-packages\rest_framework\request.py", line 19, in <module>
    from django.utils.http import parse_header_parameters
ImportError: cannot import name 'parse_header_parameters' from 'django.utils.http' (C:\Users\subhi\AppData\Local\Programs\Python\Python310\lib\site-packages\django\utils\http.py)
Internal Server Error: /admin/newsapp/newsarticle/
Traceback (most recent call last):
  File "C:\Users\subhi\AppData\Local\Programs\Python\Python310\lib\site-packages\django\core\handlers\exception.py", line 47, in inner
    response = get_response(request)
  File "C:\Users\subhi\AppData\Local\Programs\Python\Python310\lib\site-packages\django\core\handlers\base.py", line 167, in _get_response
    callback, callback_args, callback_kwargs = self.resolve_request(request)
  File "C:\Users\subhi\AppData\Local\Programs\Python\Python310\lib\site-packages\django\core\handlers\base.py", line 290, in resolve_request
    resolver_match = resolver.resolve(request.path_info)
  File "C:\Users\subhi\AppData\Local\Programs\Python\Python310\lib\site-packages\django\urls\resolvers.py", line 545, in resolve
    for pattern in self.url_patterns:
  File "C:\Users\subhi\AppData\Local\Programs\Python\Python310\lib\site-packages\django\utils\functional.py", line 48, in __get__
    res = instance.__dict__[self.name] = self.func(instance)
  File "C:\Users\subhi\AppData\Local\Programs\Python\Python310\lib\site-packages\django\urls\resolvers.py", line 589, in url_patterns
    patterns = getattr(self.urlconf_module, "urlpatterns", self.urlconf_module)
  File "C:\Users\subhi\AppData\Local\Programs\Python\Python310\lib\site-packages\django\utils\functional.py", line 48, in __get__
    res = instance.__dict__[self.name] = self.func(instance)
  File "C:\Users\subhi\AppData\Local\Programs\Python\Python310\lib\site-packages\django\urls\resolvers.py", line 582, in urlconf_module
    return import_module(self.urlconf_name)
  File "C:\Users\subhi\AppData\Local\Programs\Python\Python310\lib\importlib\__init__.py", line 126, in import_module
    return _bootstrap._gcd_import(name[level:], package, level)
  File "<frozen importlib._bootstrap>", line 1050, in _gcd_import
  File "<frozen importlib._bootstrap>", line 1027, in _find_and_load
  File "<frozen importlib._bootstrap>", line 1006, in _find_and_load_unlocked
  File "<frozen importlib._bootstrap>", line 688, in _load_unlocked
  File "<frozen importlib._bootstrap_external>", line 883, in exec_module
  File "<frozen importlib._bootstrap>", line 241, in _call_with_frames_removed
  File "C:\cit\6th sem\cloudcat\news_backend\news_backend\urls.py", line 6, in <module>
    path('api/news/', include('newsapp.urls')),  # Now includes authentication
  File "C:\Users\subhi\AppData\Local\Programs\Python\Python310\lib\site-packages\django\urls\conf.py", line 34, in include
    urlconf_module = import_module(urlconf_module)
  File "C:\Users\subhi\AppData\Local\Programs\Python\Python310\lib\importlib\__init__.py", line 126, in import_module
    return _bootstrap._gcd_import(name[level:], package, level)
  File "<frozen importlib._bootstrap>", line 1050, in _gcd_import
  File "<frozen importlib._bootstrap>", line 1027, in _find_and_load
  File "<frozen importlib._bootstrap>", line 1006, in _find_and_load_unlocked
  File "<frozen importlib._bootstrap>", line 688, in _load_unlocked
  File "<frozen importlib._bootstrap_external>", line 883, in exec_module
  File "<frozen importlib._bootstrap>", line 241, in _call_with_frames_removed
  File "C:\cit\6th sem\cloudcat\news_backend\newsapp\urls.py", line 2, in <module>
    from .views import fetch_news, get_news, index, register_user, login_user  # Import auth views
  File "C:\cit\6th sem\cloudcat\news_backend\newsapp\views.py", line 3, in <module>
    from rest_framework.decorators import api_view, permission_classes
  File "C:\Users\subhi\AppData\Local\Programs\Python\Python310\lib\site-packages\rest_framework\decorators.py", line 13, in <module>
    from rest_framework.views import APIView
  File "C:\Users\subhi\AppData\Local\Programs\Python\Python310\lib\site-packages\rest_framework\views.py", line 15, in <module>
    from rest_framework.request import Request
  File "C:\Users\subhi\AppData\Local\Programs\Python\Python310\lib\site-packages\rest_framework\request.py", line 19, in <module>
    from django.utils.http import parse_header_parameters
ImportError: cannot import name 'parse_header_parameters' from 'django.utils.http' (C:\Users\subhi\AppData\Local\Programs\Python\Python310\lib\site-packages\django\utils\http.py)
Internal Server Error: /admin/login/
Traceback (most recent call last):
  File "C:\Users\subhi\AppData\Local\Programs\Python\Python310\lib\site-packages\djongo\cursor.py", line 51, in execute
    self.result = Query(
  File "C:\Users\subhi\AppData\Local\Programs\Python\Python310\lib\site-packages\djongo\sql2mongo\query.py", line 781, in __init__
    self._query = self.parse()
  File "C:\Users\subhi\AppData\Local\Programs\Python\Python310\lib\site-packages\djongo\sql2mongo\query.py", line 873, in parse
    raise e
  File "C:\Users\subhi\AppData\Local\Programs\Python\Python310\lib\site-packages\djongo\sql2mongo\query.py", line 854, in parse
    return handler(self, statement)
  File "C:\Users\subhi\AppData\Local\Programs\Python\Python310\lib\site-packages\djongo\sql2mongo\query.py", line 925, in _insert
    query = InsertQuery(self, self.db, self.connection_properties, sm, self._params)
  File "C:\Users\subhi\AppData\Local\Programs\Python\Python310\lib\site-packages\djongo\sql2mongo\query.py", line 340, in __init__
    super().__init__(*args)
  File "C:\Users\subhi\AppData\Local\Programs\Python\Python310\lib\site-packages\djongo\sql2mongo\query.py", line 62, in __init__
    self.parse()
  File "C:\Users\subhi\AppData\Local\Programs\Python\Python310\lib\site-packages\djongo\sql2mongo\query.py", line 410, in parse
    self._fill_values(statement)
  File "C:\Users\subhi\AppData\Local\Programs\Python\Python310\lib\site-packages\djongo\sql2mongo\query.py", line 368, in _fill_values
    raise SQLDecodeError
djongo.exceptions.SQLDecodeError: 

	Keyword: None
	Sub SQL: None
	FAILED SQL: ('INSERT INTO "django_session" ("session_key", "session_data", "expire_date") VALUES (%(0)s, %(1)s, %(2)s)',)
	Params: (('wlsdo6m4egb7sdz5f3y7rkis26lk7qgv', 'e30:1tjYPe:OBT7FBvITgEQOzf697aqErWqWWeLmtIRSDWkQEMZggU', datetime.datetime(2025, 3, 2, 12, 15, 58, 574708)),)
	Version: 1.3.7

The above exception was the direct cause of the following exception:

Traceback (most recent call last):
  File "C:\Users\subhi\AppData\Local\Programs\Python\Python310\lib\site-packages\django\db\backends\utils.py", line 105, in _execute
    return self.cursor.execute(sql, params)
  File "C:\Users\subhi\AppData\Local\Programs\Python\Python310\lib\site-packages\djongo\cursor.py", line 59, in execute
    raise db_exe from e
djongo.database.DatabaseError

The above exception was the direct cause of the following exception:

Traceback (most recent call last):
  File "C:\Users\subhi\AppData\Local\Programs\Python\Python310\lib\site-packages\django\core\handlers\exception.py", line 55, in inner
    response = get_response(request)
  File "C:\Users\subhi\AppData\Local\Programs\Python\Python310\lib\site-packages\django\core\handlers\base.py", line 197, in _get_response
    response = wrapped_callback(request, *callback_args, **callback_kwargs)
  File "C:\Users\subhi\AppData\Local\Programs\Python\Python310\lib\site-packages\django\utils\decorators.py", line 48, in _wrapper
    return bound_method(*args, **kwargs)
  File "C:\Users\subhi\AppData\Local\Programs\Python\Python310\lib\site-packages\django\views\decorators\cache.py", line 80, in _view_wrapper
    response = view_func(request, *args, **kwargs)
  File "C:\Users\subhi\AppData\Local\Programs\Python\Python310\lib\site-packages\django\contrib\admin\sites.py", line 444, in login
    return LoginView.as_view(**defaults)(request)
  File "C:\Users\subhi\AppData\Local\Programs\Python\Python310\lib\site-packages\django\views\generic\base.py", line 104, in view
    return self.dispatch(request, *args, **kwargs)
  File "C:\Users\subhi\AppData\Local\Programs\Python\Python310\lib\site-packages\django\utils\decorators.py", line 48, in _wrapper
    return bound_method(*args, **kwargs)
  File "C:\Users\subhi\AppData\Local\Programs\Python\Python310\lib\site-packages\django\utils\decorators.py", line 48, in _wrapper
    return bound_method(*args, **kwargs)
  File "C:\Users\subhi\AppData\Local\Programs\Python\Python310\lib\site-packages\django\views\decorators\debug.py", line 143, in sensitive_post_parameters_wrapper
    return view(request, *args, **kwargs)
  File "C:\Users\subhi\AppData\Local\Programs\Python\Python310\lib\site-packages\django\utils\decorators.py", line 48, in _wrapper
    return bound_method(*args, **kwargs)
  File "C:\Users\subhi\AppData\Local\Programs\Python\Python310\lib\site-packages\django\utils\decorators.py", line 188, in _view_wrapper
    result = _process_exception(request, e)
  File "C:\Users\subhi\AppData\Local\Programs\Python\Python310\lib\site-packages\django\utils\decorators.py", line 186, in _view_wrapper
    response = view_func(request, *args, **kwargs)
  File "C:\Users\subhi\AppData\Local\Programs\Python\Python310\lib\site-packages\django\utils\decorators.py", line 48, in _wrapper
    return bound_method(*args, **kwargs)
  File "C:\Users\subhi\AppData\Local\Programs\Python\Python310\lib\site-packages\django\views\decorators\cache.py", line 80, in _view_wrapper
    response = view_func(request, *args, **kwargs)
  File "C:\Users\subhi\AppData\Local\Programs\Python\Python310\lib\site-packages\django\contrib\auth\views.py", line 89, in dispatch
    return super().dispatch(request, *args, **kwargs)
  File "C:\Users\subhi\AppData\Local\Programs\Python\Python310\lib\site-packages\django\views\generic\base.py", line 143, in dispatch
    return handler(request, *args, **kwargs)
  File "C:\Users\subhi\AppData\Local\Programs\Python\Python310\lib\site-packages\django\views\generic\edit.py", line 151, in post
    return self.form_valid(form)
  File "C:\Users\subhi\AppData\Local\Programs\Python\Python310\lib\site-packages\django\contrib\auth\views.py", line 108, in form_valid
    auth_login(self.request, form.get_user())
  File "C:\Users\subhi\AppData\Local\Programs\Python\Python310\lib\site-packages\django\contrib\auth\__init__.py", line 126, in login
    request.session.cycle_key()
  File "C:\Users\subhi\AppData\Local\Programs\Python\Python310\lib\site-packages\django\contrib\sessions\backends\base.py", line 432, in cycle_key
    self.create()
  File "C:\Users\subhi\AppData\Local\Programs\Python\Python310\lib\site-packages\django\contrib\sessions\backends\db.py", line 74, in create
    self.save(must_create=True)
  File "C:\Users\subhi\AppData\Local\Programs\Python\Python310\lib\site-packages\django\contrib\sessions\backends\db.py", line 127, in save
    obj.save(
  File "C:\Users\subhi\AppData\Local\Programs\Python\Python310\lib\site-packages\django\db\models\base.py", line 892, in save
    self.save_base(
  File "C:\Users\subhi\AppData\Local\Programs\Python\Python310\lib\site-packages\django\db\models\base.py", line 998, in save_base
    updated = self._save_table(
  File "C:\Users\subhi\AppData\Local\Programs\Python\Python310\lib\site-packages\django\db\models\base.py", line 1161, in _save_table
    results = self._do_insert(
  File "C:\Users\subhi\AppData\Local\Programs\Python\Python310\lib\site-packages\django\db\models\base.py", line 1202, in _do_insert
    return manager._insert(
  File "C:\Users\subhi\AppData\Local\Programs\Python\Python310\lib\site-packages\django\db\models\manager.py", line 87, in manager_method
    return getattr(self.get_queryset(), name)(*args, **kwargs)
  File "C:\Users\subhi\AppData\Local\Programs\Python\Python310\lib\site-packages\django\db\models\query.py", line 1847, in _insert
    return query.get_compiler(using=using).execute_sql(returning_fields)
  File "C:\Users\subhi\AppData\Local\Programs\Python\Python310\lib\site-packages\django\db\models\sql\compiler.py", line 1836, in execute_sql
    cursor.execute(sql, params)
  File "C:\Users\subhi\AppData\Local\Programs\Python\Python310\lib\site-packages\django\db\backends\utils.py", line 122, in execute
    return super().execute(sql, params)
  File "C:\Users\subhi\AppData\Local\Programs\Python\Python310\lib\site-packages\django\db\backends\utils.py", line 79, in execute
    return self._execute_with_wrappers(
  File "C:\Users\subhi\AppData\Local\Programs\Python\Python310\lib\site-packages\django\db\backends\utils.py", line 92, in _execute_with_wrappers
    return executor(sql, params, many, context)
  File "C:\Users\subhi\AppData\Local\Programs\Python\Python310\lib\site-packages\django\db\backends\utils.py", line 100, in _execute
    with self.db.wrap_database_errors:
  File "C:\Users\subhi\AppData\Local\Programs\Python\Python310\lib\site-packages\django\db\utils.py", line 91, in __exit__
    raise dj_exc_value.with_traceback(traceback) from exc_value
  File "C:\Users\subhi\AppData\Local\Programs\Python\Python310\lib\site-packages\django\db\backends\utils.py", line 105, in _execute
    return self.cursor.execute(sql, params)
  File "C:\Users\subhi\AppData\Local\Programs\Python\Python310\lib\site-packages\djongo\cursor.py", line 59, in execute
    raise db_exe from e
django.db.utils.DatabaseError
"POST /admin/login/?next=/admin/ HTTP/1.1" 500 278477
"GET /admin/ HTTP/1.1" 500 59
"POST /admin/login/?next=/admin/ HTTP/1.1" 500 59
"POST /admin/login/?next=/admin/ HTTP/1.1" 500 59
"GET /admin/ HTTP/1.1" 500 59
"GET /admin/newsapp/newsarticle/ HTTP/1.1" 500 59
"GET /admin/jsi18n/ HTTP/1.1" 500 59
"GET /admin/newsapp/reaction/ HTTP/1.1" 500 59
"GET /admin/jsi18n/ HTTP/1.1" 500 59
